2023-06-21 20:43:46,270 - apscheduler.scheduler - INFO - Scheduler started
2023-06-21 20:44:11,223 - apscheduler.scheduler - INFO - Scheduler started
2023-06-21 21:04:21,082 - root - INFO - /in called, chat_id=1250739576 user_id=1250739576
2023-06-21 21:11:14,941 - root - INFO - /all called, chat_id=-1001719730820 user_count=2
2023-06-21 21:32:46,431 - apscheduler.scheduler - INFO - Scheduler started
2023-06-21 21:32:47,592 - root - INFO - /all called, chat_id=-1001719730820 user_count=2
2023-06-21 21:32:55,005 - root - INFO - /all called, chat_id=-1001719730820 user_count=2
2023-06-21 22:18:23,788 - apscheduler.scheduler - INFO - Scheduler started
2023-06-21 22:20:14,693 - apscheduler.scheduler - INFO - Scheduler started
2023-06-21 22:29:35,163 - apscheduler.scheduler - INFO - Scheduler started
2023-06-21 22:36:34,315 - apscheduler.scheduler - INFO - Scheduler started
2023-06-21 23:35:04,861 - apscheduler.scheduler - INFO - Scheduler started
2023-06-21 23:35:06,599 - werkzeug - INFO - [31m[1mWARNING: This is a development server. Do not use it in a production deployment. Use a production WSGI server instead.[0m
 * Running on all addresses (0.0.0.0)
 * Running on http://127.0.0.1:5000
 * Running on http://192.168.0.231:5000
2023-06-21 23:35:06,599 - werkzeug - INFO - [33mPress CTRL+C to quit[0m
2023-06-21 23:35:06,608 - werkzeug - INFO -  * Restarting with stat
2023-06-21 23:35:08,197 - apscheduler.scheduler - INFO - Scheduler started
2023-06-21 23:35:08,626 - werkzeug - WARNING -  * Debugger is active!
2023-06-21 23:35:08,636 - werkzeug - INFO -  * Debugger PIN: 106-333-038
2023-06-21 23:35:08,716 - telegram.ext.updater - ERROR - Error while getting Updates: Conflict: terminated by other getUpdates request; make sure that only one bot instance is running
2023-06-21 23:35:08,716 - telegram.ext.dispatcher - ERROR - No error handlers are registered, logging exception.
Traceback (most recent call last):
  File "C:\Users\USERNAME\AppData\Local\Programs\Python\Python310\lib\site-packages\telegram\ext\updater.py", line 646, in _network_loop_retry
    if not action_cb():
  File "C:\Users\USERNAME\AppData\Local\Programs\Python\Python310\lib\site-packages\telegram\ext\updater.py", line 597, in polling_action_cb
    updates = self.bot.get_updates(
  File "C:\Users\USERNAME\AppData\Local\Programs\Python\Python310\lib\site-packages\telegram\ext\extbot.py", line 222, in get_updates
    updates = super().get_updates(
  File "C:\Users\USERNAME\AppData\Local\Programs\Python\Python310\lib\site-packages\telegram\bot.py", line 130, in decorator
    result = func(*args, **kwargs)
  File "C:\Users\USERNAME\AppData\Local\Programs\Python\Python310\lib\site-packages\telegram\bot.py", line 2861, in get_updates
    self._post(
  File "C:\Users\USERNAME\AppData\Local\Programs\Python\Python310\lib\site-packages\telegram\bot.py", line 295, in _post
    return self.request.post(
  File "C:\Users\USERNAME\AppData\Local\Programs\Python\Python310\lib\site-packages\telegram\utils\request.py", line 356, in post
    result = self._request_wrapper(
  File "C:\Users\USERNAME\AppData\Local\Programs\Python\Python310\lib\site-packages\telegram\utils\request.py", line 283, in _request_wrapper
    raise Conflict(message)
telegram.error.Conflict: Conflict: terminated by other getUpdates request; make sure that only one bot instance is running
2023-06-21 23:35:12,825 - telegram.ext.updater - ERROR - Error while getting Updates: Conflict: terminated by other getUpdates request; make sure that only one bot instance is running
2023-06-21 23:35:12,825 - telegram.ext.dispatcher - ERROR - No error handlers are registered, logging exception.
Traceback (most recent call last):
  File "C:\Users\USERNAME\AppData\Local\Programs\Python\Python310\lib\site-packages\telegram\ext\updater.py", line 646, in _network_loop_retry
    if not action_cb():
  File "C:\Users\USERNAME\AppData\Local\Programs\Python\Python310\lib\site-packages\telegram\ext\updater.py", line 597, in polling_action_cb
    updates = self.bot.get_updates(
  File "C:\Users\USERNAME\AppData\Local\Programs\Python\Python310\lib\site-packages\telegram\ext\extbot.py", line 222, in get_updates
    updates = super().get_updates(
  File "C:\Users\USERNAME\AppData\Local\Programs\Python\Python310\lib\site-packages\telegram\bot.py", line 130, in decorator
    result = func(*args, **kwargs)
  File "C:\Users\USERNAME\AppData\Local\Programs\Python\Python310\lib\site-packages\telegram\bot.py", line 2861, in get_updates
    self._post(
  File "C:\Users\USERNAME\AppData\Local\Programs\Python\Python310\lib\site-packages\telegram\bot.py", line 295, in _post
    return self.request.post(
  File "C:\Users\USERNAME\AppData\Local\Programs\Python\Python310\lib\site-packages\telegram\utils\request.py", line 356, in post
    result = self._request_wrapper(
  File "C:\Users\USERNAME\AppData\Local\Programs\Python\Python310\lib\site-packages\telegram\utils\request.py", line 283, in _request_wrapper
    raise Conflict(message)
telegram.error.Conflict: Conflict: terminated by other getUpdates request; make sure that only one bot instance is running
2023-06-21 23:35:13,927 - telegram.ext.updater - ERROR - Error while getting Updates: Conflict: terminated by other getUpdates request; make sure that only one bot instance is running
2023-06-21 23:35:13,927 - telegram.ext.dispatcher - ERROR - No error handlers are registered, logging exception.
Traceback (most recent call last):
  File "C:\Users\USERNAME\AppData\Local\Programs\Python\Python310\lib\site-packages\telegram\ext\updater.py", line 646, in _network_loop_retry
    if not action_cb():
  File "C:\Users\USERNAME\AppData\Local\Programs\Python\Python310\lib\site-packages\telegram\ext\updater.py", line 597, in polling_action_cb
    updates = self.bot.get_updates(
  File "C:\Users\USERNAME\AppData\Local\Programs\Python\Python310\lib\site-packages\telegram\ext\extbot.py", line 222, in get_updates
    updates = super().get_updates(
  File "C:\Users\USERNAME\AppData\Local\Programs\Python\Python310\lib\site-packages\telegram\bot.py", line 130, in decorator
    result = func(*args, **kwargs)
  File "C:\Users\USERNAME\AppData\Local\Programs\Python\Python310\lib\site-packages\telegram\bot.py", line 2861, in get_updates
    self._post(
  File "C:\Users\USERNAME\AppData\Local\Programs\Python\Python310\lib\site-packages\telegram\bot.py", line 295, in _post
    return self.request.post(
  File "C:\Users\USERNAME\AppData\Local\Programs\Python\Python310\lib\site-packages\telegram\utils\request.py", line 356, in post
    result = self._request_wrapper(
  File "C:\Users\USERNAME\AppData\Local\Programs\Python\Python310\lib\site-packages\telegram\utils\request.py", line 283, in _request_wrapper
    raise Conflict(message)
telegram.error.Conflict: Conflict: terminated by other getUpdates request; make sure that only one bot instance is running
2023-06-21 23:35:18,525 - telegram.ext.updater - ERROR - Error while getting Updates: Conflict: terminated by other getUpdates request; make sure that only one bot instance is running
2023-06-21 23:35:18,525 - telegram.ext.dispatcher - ERROR - No error handlers are registered, logging exception.
Traceback (most recent call last):
  File "C:\Users\USERNAME\AppData\Local\Programs\Python\Python310\lib\site-packages\telegram\ext\updater.py", line 646, in _network_loop_retry
    if not action_cb():
  File "C:\Users\USERNAME\AppData\Local\Programs\Python\Python310\lib\site-packages\telegram\ext\updater.py", line 597, in polling_action_cb
    updates = self.bot.get_updates(
  File "C:\Users\USERNAME\AppData\Local\Programs\Python\Python310\lib\site-packages\telegram\ext\extbot.py", line 222, in get_updates
    updates = super().get_updates(
  File "C:\Users\USERNAME\AppData\Local\Programs\Python\Python310\lib\site-packages\telegram\bot.py", line 130, in decorator
    result = func(*args, **kwargs)
  File "C:\Users\USERNAME\AppData\Local\Programs\Python\Python310\lib\site-packages\telegram\bot.py", line 2861, in get_updates
    self._post(
  File "C:\Users\USERNAME\AppData\Local\Programs\Python\Python310\lib\site-packages\telegram\bot.py", line 295, in _post
    return self.request.post(
  File "C:\Users\USERNAME\AppData\Local\Programs\Python\Python310\lib\site-packages\telegram\utils\request.py", line 356, in post
    result = self._request_wrapper(
  File "C:\Users\USERNAME\AppData\Local\Programs\Python\Python310\lib\site-packages\telegram\utils\request.py", line 283, in _request_wrapper
    raise Conflict(message)
telegram.error.Conflict: Conflict: terminated by other getUpdates request; make sure that only one bot instance is running
2023-06-21 23:35:19,636 - telegram.ext.updater - ERROR - Error while getting Updates: Conflict: terminated by other getUpdates request; make sure that only one bot instance is running
2023-06-21 23:35:19,636 - telegram.ext.dispatcher - ERROR - No error handlers are registered, logging exception.
Traceback (most recent call last):
  File "C:\Users\USERNAME\AppData\Local\Programs\Python\Python310\lib\site-packages\telegram\ext\updater.py", line 646, in _network_loop_retry
    if not action_cb():
  File "C:\Users\USERNAME\AppData\Local\Programs\Python\Python310\lib\site-packages\telegram\ext\updater.py", line 597, in polling_action_cb
    updates = self.bot.get_updates(
  File "C:\Users\USERNAME\AppData\Local\Programs\Python\Python310\lib\site-packages\telegram\ext\extbot.py", line 222, in get_updates
    updates = super().get_updates(
  File "C:\Users\USERNAME\AppData\Local\Programs\Python\Python310\lib\site-packages\telegram\bot.py", line 130, in decorator
    result = func(*args, **kwargs)
  File "C:\Users\USERNAME\AppData\Local\Programs\Python\Python310\lib\site-packages\telegram\bot.py", line 2861, in get_updates
    self._post(
  File "C:\Users\USERNAME\AppData\Local\Programs\Python\Python310\lib\site-packages\telegram\bot.py", line 295, in _post
    return self.request.post(
  File "C:\Users\USERNAME\AppData\Local\Programs\Python\Python310\lib\site-packages\telegram\utils\request.py", line 356, in post
    result = self._request_wrapper(
  File "C:\Users\USERNAME\AppData\Local\Programs\Python\Python310\lib\site-packages\telegram\utils\request.py", line 283, in _request_wrapper
    raise Conflict(message)
telegram.error.Conflict: Conflict: terminated by other getUpdates request; make sure that only one bot instance is running
2023-06-21 23:35:24,994 - telegram.ext.updater - ERROR - Error while getting Updates: Conflict: terminated by other getUpdates request; make sure that only one bot instance is running
2023-06-21 23:35:24,995 - telegram.ext.dispatcher - ERROR - No error handlers are registered, logging exception.
Traceback (most recent call last):
  File "C:\Users\USERNAME\AppData\Local\Programs\Python\Python310\lib\site-packages\telegram\ext\updater.py", line 646, in _network_loop_retry
    if not action_cb():
  File "C:\Users\USERNAME\AppData\Local\Programs\Python\Python310\lib\site-packages\telegram\ext\updater.py", line 597, in polling_action_cb
    updates = self.bot.get_updates(
  File "C:\Users\USERNAME\AppData\Local\Programs\Python\Python310\lib\site-packages\telegram\ext\extbot.py", line 222, in get_updates
    updates = super().get_updates(
  File "C:\Users\USERNAME\AppData\Local\Programs\Python\Python310\lib\site-packages\telegram\bot.py", line 130, in decorator
    result = func(*args, **kwargs)
  File "C:\Users\USERNAME\AppData\Local\Programs\Python\Python310\lib\site-packages\telegram\bot.py", line 2861, in get_updates
    self._post(
  File "C:\Users\USERNAME\AppData\Local\Programs\Python\Python310\lib\site-packages\telegram\bot.py", line 295, in _post
    return self.request.post(
  File "C:\Users\USERNAME\AppData\Local\Programs\Python\Python310\lib\site-packages\telegram\utils\request.py", line 356, in post
    result = self._request_wrapper(
  File "C:\Users\USERNAME\AppData\Local\Programs\Python\Python310\lib\site-packages\telegram\utils\request.py", line 283, in _request_wrapper
    raise Conflict(message)
telegram.error.Conflict: Conflict: terminated by other getUpdates request; make sure that only one bot instance is running
2023-06-21 23:35:26,095 - telegram.ext.updater - ERROR - Error while getting Updates: Conflict: terminated by other getUpdates request; make sure that only one bot instance is running
2023-06-21 23:35:26,096 - telegram.ext.dispatcher - ERROR - No error handlers are registered, logging exception.
Traceback (most recent call last):
  File "C:\Users\USERNAME\AppData\Local\Programs\Python\Python310\lib\site-packages\telegram\ext\updater.py", line 646, in _network_loop_retry
    if not action_cb():
  File "C:\Users\USERNAME\AppData\Local\Programs\Python\Python310\lib\site-packages\telegram\ext\updater.py", line 597, in polling_action_cb
    updates = self.bot.get_updates(
  File "C:\Users\USERNAME\AppData\Local\Programs\Python\Python310\lib\site-packages\telegram\ext\extbot.py", line 222, in get_updates
    updates = super().get_updates(
  File "C:\Users\USERNAME\AppData\Local\Programs\Python\Python310\lib\site-packages\telegram\bot.py", line 130, in decorator
    result = func(*args, **kwargs)
  File "C:\Users\USERNAME\AppData\Local\Programs\Python\Python310\lib\site-packages\telegram\bot.py", line 2861, in get_updates
    self._post(
  File "C:\Users\USERNAME\AppData\Local\Programs\Python\Python310\lib\site-packages\telegram\bot.py", line 295, in _post
    return self.request.post(
  File "C:\Users\USERNAME\AppData\Local\Programs\Python\Python310\lib\site-packages\telegram\utils\request.py", line 356, in post
    result = self._request_wrapper(
  File "C:\Users\USERNAME\AppData\Local\Programs\Python\Python310\lib\site-packages\telegram\utils\request.py", line 283, in _request_wrapper
    raise Conflict(message)
telegram.error.Conflict: Conflict: terminated by other getUpdates request; make sure that only one bot instance is running
2023-06-21 23:35:26,780 - telegram.ext.dispatcher - ERROR - No error handlers are registered, logging exception.
Traceback (most recent call last):
  File "C:\Users\USERNAME\AppData\Local\Programs\Python\Python310\lib\site-packages\telegram\ext\dispatcher.py", line 555, in process_update
    handler.handle_update(update, self, check, context)
  File "C:\Users\USERNAME\AppData\Local\Programs\Python\Python310\lib\site-packages\telegram\ext\handler.py", line 198, in handle_update
    return self.callback(update, context)
  File "C:\Users\USERNAME\Desktop\AIESEC_CRUSH_BOT\main2.py", line 64, in random_gif
    gif_files = os.listdir(GIFS_DIR)
FileNotFoundError: [WinError 3] Системе не удается найти указанный путь: 'gifs'
2023-06-21 23:35:29,574 - telegram.ext.updater - ERROR - Error while getting Updates: Conflict: terminated by other getUpdates request; make sure that only one bot instance is running
2023-06-21 23:35:29,574 - telegram.ext.dispatcher - ERROR - No error handlers are registered, logging exception.
Traceback (most recent call last):
  File "C:\Users\USERNAME\AppData\Local\Programs\Python\Python310\lib\site-packages\telegram\ext\updater.py", line 646, in _network_loop_retry
    if not action_cb():
  File "C:\Users\USERNAME\AppData\Local\Programs\Python\Python310\lib\site-packages\telegram\ext\updater.py", line 597, in polling_action_cb
    updates = self.bot.get_updates(
  File "C:\Users\USERNAME\AppData\Local\Programs\Python\Python310\lib\site-packages\telegram\ext\extbot.py", line 222, in get_updates
    updates = super().get_updates(
  File "C:\Users\USERNAME\AppData\Local\Programs\Python\Python310\lib\site-packages\telegram\bot.py", line 130, in decorator
    result = func(*args, **kwargs)
  File "C:\Users\USERNAME\AppData\Local\Programs\Python\Python310\lib\site-packages\telegram\bot.py", line 2861, in get_updates
    self._post(
  File "C:\Users\USERNAME\AppData\Local\Programs\Python\Python310\lib\site-packages\telegram\bot.py", line 295, in _post
    return self.request.post(
  File "C:\Users\USERNAME\AppData\Local\Programs\Python\Python310\lib\site-packages\telegram\utils\request.py", line 356, in post
    result = self._request_wrapper(
  File "C:\Users\USERNAME\AppData\Local\Programs\Python\Python310\lib\site-packages\telegram\utils\request.py", line 283, in _request_wrapper
    raise Conflict(message)
telegram.error.Conflict: Conflict: terminated by other getUpdates request; make sure that only one bot instance is running
2023-06-21 23:35:33,687 - telegram.ext.updater - ERROR - Error while getting Updates: Conflict: terminated by other getUpdates request; make sure that only one bot instance is running
2023-06-21 23:35:33,688 - telegram.ext.dispatcher - ERROR - No error handlers are registered, logging exception.
Traceback (most recent call last):
  File "C:\Users\USERNAME\AppData\Local\Programs\Python\Python310\lib\site-packages\telegram\ext\updater.py", line 646, in _network_loop_retry
    if not action_cb():
  File "C:\Users\USERNAME\AppData\Local\Programs\Python\Python310\lib\site-packages\telegram\ext\updater.py", line 597, in polling_action_cb
    updates = self.bot.get_updates(
  File "C:\Users\USERNAME\AppData\Local\Programs\Python\Python310\lib\site-packages\telegram\ext\extbot.py", line 222, in get_updates
    updates = super().get_updates(
  File "C:\Users\USERNAME\AppData\Local\Programs\Python\Python310\lib\site-packages\telegram\bot.py", line 130, in decorator
    result = func(*args, **kwargs)
  File "C:\Users\USERNAME\AppData\Local\Programs\Python\Python310\lib\site-packages\telegram\bot.py", line 2861, in get_updates
    self._post(
  File "C:\Users\USERNAME\AppData\Local\Programs\Python\Python310\lib\site-packages\telegram\bot.py", line 295, in _post
    return self.request.post(
  File "C:\Users\USERNAME\AppData\Local\Programs\Python\Python310\lib\site-packages\telegram\utils\request.py", line 356, in post
    result = self._request_wrapper(
  File "C:\Users\USERNAME\AppData\Local\Programs\Python\Python310\lib\site-packages\telegram\utils\request.py", line 283, in _request_wrapper
    raise Conflict(message)
telegram.error.Conflict: Conflict: terminated by other getUpdates request; make sure that only one bot instance is running
2023-06-21 23:35:38,848 - telegram.ext.updater - ERROR - Error while getting Updates: Conflict: terminated by other getUpdates request; make sure that only one bot instance is running
2023-06-21 23:35:38,848 - telegram.ext.dispatcher - ERROR - No error handlers are registered, logging exception.
Traceback (most recent call last):
  File "C:\Users\USERNAME\AppData\Local\Programs\Python\Python310\lib\site-packages\telegram\ext\updater.py", line 646, in _network_loop_retry
    if not action_cb():
  File "C:\Users\USERNAME\AppData\Local\Programs\Python\Python310\lib\site-packages\telegram\ext\updater.py", line 597, in polling_action_cb
    updates = self.bot.get_updates(
  File "C:\Users\USERNAME\AppData\Local\Programs\Python\Python310\lib\site-packages\telegram\ext\extbot.py", line 222, in get_updates
    updates = super().get_updates(
  File "C:\Users\USERNAME\AppData\Local\Programs\Python\Python310\lib\site-packages\telegram\bot.py", line 130, in decorator
    result = func(*args, **kwargs)
  File "C:\Users\USERNAME\AppData\Local\Programs\Python\Python310\lib\site-packages\telegram\bot.py", line 2861, in get_updates
    self._post(
  File "C:\Users\USERNAME\AppData\Local\Programs\Python\Python310\lib\site-packages\telegram\bot.py", line 295, in _post
    return self.request.post(
  File "C:\Users\USERNAME\AppData\Local\Programs\Python\Python310\lib\site-packages\telegram\utils\request.py", line 356, in post
    result = self._request_wrapper(
  File "C:\Users\USERNAME\AppData\Local\Programs\Python\Python310\lib\site-packages\telegram\utils\request.py", line 283, in _request_wrapper
    raise Conflict(message)
telegram.error.Conflict: Conflict: terminated by other getUpdates request; make sure that only one bot instance is running
2023-06-21 23:35:43,460 - telegram.ext.updater - ERROR - Error while getting Updates: Conflict: terminated by other getUpdates request; make sure that only one bot instance is running
2023-06-21 23:35:43,460 - telegram.ext.dispatcher - ERROR - No error handlers are registered, logging exception.
Traceback (most recent call last):
  File "C:\Users\USERNAME\AppData\Local\Programs\Python\Python310\lib\site-packages\telegram\ext\updater.py", line 646, in _network_loop_retry
    if not action_cb():
  File "C:\Users\USERNAME\AppData\Local\Programs\Python\Python310\lib\site-packages\telegram\ext\updater.py", line 597, in polling_action_cb
    updates = self.bot.get_updates(
  File "C:\Users\USERNAME\AppData\Local\Programs\Python\Python310\lib\site-packages\telegram\ext\extbot.py", line 222, in get_updates
    updates = super().get_updates(
  File "C:\Users\USERNAME\AppData\Local\Programs\Python\Python310\lib\site-packages\telegram\bot.py", line 130, in decorator
    result = func(*args, **kwargs)
  File "C:\Users\USERNAME\AppData\Local\Programs\Python\Python310\lib\site-packages\telegram\bot.py", line 2861, in get_updates
    self._post(
  File "C:\Users\USERNAME\AppData\Local\Programs\Python\Python310\lib\site-packages\telegram\bot.py", line 295, in _post
    return self.request.post(
  File "C:\Users\USERNAME\AppData\Local\Programs\Python\Python310\lib\site-packages\telegram\utils\request.py", line 356, in post
    result = self._request_wrapper(
  File "C:\Users\USERNAME\AppData\Local\Programs\Python\Python310\lib\site-packages\telegram\utils\request.py", line 283, in _request_wrapper
    raise Conflict(message)
telegram.error.Conflict: Conflict: terminated by other getUpdates request; make sure that only one bot instance is running
2023-06-21 23:35:51,156 - telegram.ext.updater - ERROR - Error while getting Updates: Conflict: terminated by other getUpdates request; make sure that only one bot instance is running
2023-06-21 23:35:51,156 - telegram.ext.dispatcher - ERROR - No error handlers are registered, logging exception.
Traceback (most recent call last):
  File "C:\Users\USERNAME\AppData\Local\Programs\Python\Python310\lib\site-packages\telegram\ext\updater.py", line 646, in _network_loop_retry
    if not action_cb():
  File "C:\Users\USERNAME\AppData\Local\Programs\Python\Python310\lib\site-packages\telegram\ext\updater.py", line 597, in polling_action_cb
    updates = self.bot.get_updates(
  File "C:\Users\USERNAME\AppData\Local\Programs\Python\Python310\lib\site-packages\telegram\ext\extbot.py", line 222, in get_updates
    updates = super().get_updates(
  File "C:\Users\USERNAME\AppData\Local\Programs\Python\Python310\lib\site-packages\telegram\bot.py", line 130, in decorator
    result = func(*args, **kwargs)
  File "C:\Users\USERNAME\AppData\Local\Programs\Python\Python310\lib\site-packages\telegram\bot.py", line 2861, in get_updates
    self._post(
  File "C:\Users\USERNAME\AppData\Local\Programs\Python\Python310\lib\site-packages\telegram\bot.py", line 295, in _post
    return self.request.post(
  File "C:\Users\USERNAME\AppData\Local\Programs\Python\Python310\lib\site-packages\telegram\utils\request.py", line 356, in post
    result = self._request_wrapper(
  File "C:\Users\USERNAME\AppData\Local\Programs\Python\Python310\lib\site-packages\telegram\utils\request.py", line 283, in _request_wrapper
    raise Conflict(message)
telegram.error.Conflict: Conflict: terminated by other getUpdates request; make sure that only one bot instance is running
2023-06-21 23:35:55,252 - telegram.ext.updater - ERROR - Error while getting Updates: Conflict: terminated by other getUpdates request; make sure that only one bot instance is running
2023-06-21 23:35:55,252 - telegram.ext.dispatcher - ERROR - No error handlers are registered, logging exception.
Traceback (most recent call last):
  File "C:\Users\USERNAME\AppData\Local\Programs\Python\Python310\lib\site-packages\telegram\ext\updater.py", line 646, in _network_loop_retry
    if not action_cb():
  File "C:\Users\USERNAME\AppData\Local\Programs\Python\Python310\lib\site-packages\telegram\ext\updater.py", line 597, in polling_action_cb
    updates = self.bot.get_updates(
  File "C:\Users\USERNAME\AppData\Local\Programs\Python\Python310\lib\site-packages\telegram\ext\extbot.py", line 222, in get_updates
    updates = super().get_updates(
  File "C:\Users\USERNAME\AppData\Local\Programs\Python\Python310\lib\site-packages\telegram\bot.py", line 130, in decorator
    result = func(*args, **kwargs)
  File "C:\Users\USERNAME\AppData\Local\Programs\Python\Python310\lib\site-packages\telegram\bot.py", line 2861, in get_updates
    self._post(
  File "C:\Users\USERNAME\AppData\Local\Programs\Python\Python310\lib\site-packages\telegram\bot.py", line 295, in _post
    return self.request.post(
  File "C:\Users\USERNAME\AppData\Local\Programs\Python\Python310\lib\site-packages\telegram\utils\request.py", line 356, in post
    result = self._request_wrapper(
  File "C:\Users\USERNAME\AppData\Local\Programs\Python\Python310\lib\site-packages\telegram\utils\request.py", line 283, in _request_wrapper
    raise Conflict(message)
telegram.error.Conflict: Conflict: terminated by other getUpdates request; make sure that only one bot instance is running
2023-06-21 23:36:06,743 - telegram.ext.updater - ERROR - Error while getting Updates: Conflict: terminated by other getUpdates request; make sure that only one bot instance is running
2023-06-21 23:36:06,743 - telegram.ext.dispatcher - ERROR - No error handlers are registered, logging exception.
Traceback (most recent call last):
  File "C:\Users\USERNAME\AppData\Local\Programs\Python\Python310\lib\site-packages\telegram\ext\updater.py", line 646, in _network_loop_retry
    if not action_cb():
  File "C:\Users\USERNAME\AppData\Local\Programs\Python\Python310\lib\site-packages\telegram\ext\updater.py", line 597, in polling_action_cb
    updates = self.bot.get_updates(
  File "C:\Users\USERNAME\AppData\Local\Programs\Python\Python310\lib\site-packages\telegram\ext\extbot.py", line 222, in get_updates
    updates = super().get_updates(
  File "C:\Users\USERNAME\AppData\Local\Programs\Python\Python310\lib\site-packages\telegram\bot.py", line 130, in decorator
    result = func(*args, **kwargs)
  File "C:\Users\USERNAME\AppData\Local\Programs\Python\Python310\lib\site-packages\telegram\bot.py", line 2861, in get_updates
    self._post(
  File "C:\Users\USERNAME\AppData\Local\Programs\Python\Python310\lib\site-packages\telegram\bot.py", line 295, in _post
    return self.request.post(
  File "C:\Users\USERNAME\AppData\Local\Programs\Python\Python310\lib\site-packages\telegram\utils\request.py", line 356, in post
    result = self._request_wrapper(
  File "C:\Users\USERNAME\AppData\Local\Programs\Python\Python310\lib\site-packages\telegram\utils\request.py", line 283, in _request_wrapper
    raise Conflict(message)
telegram.error.Conflict: Conflict: terminated by other getUpdates request; make sure that only one bot instance is running
2023-06-21 23:36:10,854 - telegram.ext.updater - ERROR - Error while getting Updates: Conflict: terminated by other getUpdates request; make sure that only one bot instance is running
2023-06-21 23:36:10,854 - telegram.ext.dispatcher - ERROR - No error handlers are registered, logging exception.
Traceback (most recent call last):
  File "C:\Users\USERNAME\AppData\Local\Programs\Python\Python310\lib\site-packages\telegram\ext\updater.py", line 646, in _network_loop_retry
    if not action_cb():
  File "C:\Users\USERNAME\AppData\Local\Programs\Python\Python310\lib\site-packages\telegram\ext\updater.py", line 597, in polling_action_cb
    updates = self.bot.get_updates(
  File "C:\Users\USERNAME\AppData\Local\Programs\Python\Python310\lib\site-packages\telegram\ext\extbot.py", line 222, in get_updates
    updates = super().get_updates(
  File "C:\Users\USERNAME\AppData\Local\Programs\Python\Python310\lib\site-packages\telegram\bot.py", line 130, in decorator
    result = func(*args, **kwargs)
  File "C:\Users\USERNAME\AppData\Local\Programs\Python\Python310\lib\site-packages\telegram\bot.py", line 2861, in get_updates
    self._post(
  File "C:\Users\USERNAME\AppData\Local\Programs\Python\Python310\lib\site-packages\telegram\bot.py", line 295, in _post
    return self.request.post(
  File "C:\Users\USERNAME\AppData\Local\Programs\Python\Python310\lib\site-packages\telegram\utils\request.py", line 356, in post
    result = self._request_wrapper(
  File "C:\Users\USERNAME\AppData\Local\Programs\Python\Python310\lib\site-packages\telegram\utils\request.py", line 283, in _request_wrapper
    raise Conflict(message)
telegram.error.Conflict: Conflict: terminated by other getUpdates request; make sure that only one bot instance is running
2023-06-21 23:36:28,046 - telegram.ext.updater - ERROR - Error while getting Updates: Conflict: terminated by other getUpdates request; make sure that only one bot instance is running
2023-06-21 23:36:28,046 - telegram.ext.dispatcher - ERROR - No error handlers are registered, logging exception.
Traceback (most recent call last):
  File "C:\Users\USERNAME\AppData\Local\Programs\Python\Python310\lib\site-packages\telegram\ext\updater.py", line 646, in _network_loop_retry
    if not action_cb():
  File "C:\Users\USERNAME\AppData\Local\Programs\Python\Python310\lib\site-packages\telegram\ext\updater.py", line 597, in polling_action_cb
    updates = self.bot.get_updates(
  File "C:\Users\USERNAME\AppData\Local\Programs\Python\Python310\lib\site-packages\telegram\ext\extbot.py", line 222, in get_updates
    updates = super().get_updates(
  File "C:\Users\USERNAME\AppData\Local\Programs\Python\Python310\lib\site-packages\telegram\bot.py", line 130, in decorator
    result = func(*args, **kwargs)
  File "C:\Users\USERNAME\AppData\Local\Programs\Python\Python310\lib\site-packages\telegram\bot.py", line 2861, in get_updates
    self._post(
  File "C:\Users\USERNAME\AppData\Local\Programs\Python\Python310\lib\site-packages\telegram\bot.py", line 295, in _post
    return self.request.post(
  File "C:\Users\USERNAME\AppData\Local\Programs\Python\Python310\lib\site-packages\telegram\utils\request.py", line 356, in post
    result = self._request_wrapper(
  File "C:\Users\USERNAME\AppData\Local\Programs\Python\Python310\lib\site-packages\telegram\utils\request.py", line 283, in _request_wrapper
    raise Conflict(message)
telegram.error.Conflict: Conflict: terminated by other getUpdates request; make sure that only one bot instance is running
2023-06-21 23:36:32,144 - telegram.ext.updater - ERROR - Error while getting Updates: Conflict: terminated by other getUpdates request; make sure that only one bot instance is running
2023-06-21 23:36:32,145 - telegram.ext.dispatcher - ERROR - No error handlers are registered, logging exception.
Traceback (most recent call last):
  File "C:\Users\USERNAME\AppData\Local\Programs\Python\Python310\lib\site-packages\telegram\ext\updater.py", line 646, in _network_loop_retry
    if not action_cb():
  File "C:\Users\USERNAME\AppData\Local\Programs\Python\Python310\lib\site-packages\telegram\ext\updater.py", line 597, in polling_action_cb
    updates = self.bot.get_updates(
  File "C:\Users\USERNAME\AppData\Local\Programs\Python\Python310\lib\site-packages\telegram\ext\extbot.py", line 222, in get_updates
    updates = super().get_updates(
  File "C:\Users\USERNAME\AppData\Local\Programs\Python\Python310\lib\site-packages\telegram\bot.py", line 130, in decorator
    result = func(*args, **kwargs)
  File "C:\Users\USERNAME\AppData\Local\Programs\Python\Python310\lib\site-packages\telegram\bot.py", line 2861, in get_updates
    self._post(
  File "C:\Users\USERNAME\AppData\Local\Programs\Python\Python310\lib\site-packages\telegram\bot.py", line 295, in _post
    return self.request.post(
  File "C:\Users\USERNAME\AppData\Local\Programs\Python\Python310\lib\site-packages\telegram\utils\request.py", line 356, in post
    result = self._request_wrapper(
  File "C:\Users\USERNAME\AppData\Local\Programs\Python\Python310\lib\site-packages\telegram\utils\request.py", line 283, in _request_wrapper
    raise Conflict(message)
telegram.error.Conflict: Conflict: terminated by other getUpdates request; make sure that only one bot instance is running
2023-06-21 23:36:57,869 - telegram.ext.updater - ERROR - Error while getting Updates: Conflict: terminated by other getUpdates request; make sure that only one bot instance is running
2023-06-21 23:36:57,870 - telegram.ext.dispatcher - ERROR - No error handlers are registered, logging exception.
Traceback (most recent call last):
  File "C:\Users\USERNAME\AppData\Local\Programs\Python\Python310\lib\site-packages\telegram\ext\updater.py", line 646, in _network_loop_retry
    if not action_cb():
  File "C:\Users\USERNAME\AppData\Local\Programs\Python\Python310\lib\site-packages\telegram\ext\updater.py", line 597, in polling_action_cb
    updates = self.bot.get_updates(
  File "C:\Users\USERNAME\AppData\Local\Programs\Python\Python310\lib\site-packages\telegram\ext\extbot.py", line 222, in get_updates
    updates = super().get_updates(
  File "C:\Users\USERNAME\AppData\Local\Programs\Python\Python310\lib\site-packages\telegram\bot.py", line 130, in decorator
    result = func(*args, **kwargs)
  File "C:\Users\USERNAME\AppData\Local\Programs\Python\Python310\lib\site-packages\telegram\bot.py", line 2861, in get_updates
    self._post(
  File "C:\Users\USERNAME\AppData\Local\Programs\Python\Python310\lib\site-packages\telegram\bot.py", line 295, in _post
    return self.request.post(
  File "C:\Users\USERNAME\AppData\Local\Programs\Python\Python310\lib\site-packages\telegram\utils\request.py", line 356, in post
    result = self._request_wrapper(
  File "C:\Users\USERNAME\AppData\Local\Programs\Python\Python310\lib\site-packages\telegram\utils\request.py", line 283, in _request_wrapper
    raise Conflict(message)
telegram.error.Conflict: Conflict: terminated by other getUpdates request; make sure that only one bot instance is running
2023-06-21 23:37:01,986 - telegram.ext.updater - ERROR - Error while getting Updates: Conflict: terminated by other getUpdates request; make sure that only one bot instance is running
2023-06-21 23:37:01,987 - telegram.ext.dispatcher - ERROR - No error handlers are registered, logging exception.
Traceback (most recent call last):
  File "C:\Users\USERNAME\AppData\Local\Programs\Python\Python310\lib\site-packages\telegram\ext\updater.py", line 646, in _network_loop_retry
    if not action_cb():
  File "C:\Users\USERNAME\AppData\Local\Programs\Python\Python310\lib\site-packages\telegram\ext\updater.py", line 597, in polling_action_cb
    updates = self.bot.get_updates(
  File "C:\Users\USERNAME\AppData\Local\Programs\Python\Python310\lib\site-packages\telegram\ext\extbot.py", line 222, in get_updates
    updates = super().get_updates(
  File "C:\Users\USERNAME\AppData\Local\Programs\Python\Python310\lib\site-packages\telegram\bot.py", line 130, in decorator
    result = func(*args, **kwargs)
  File "C:\Users\USERNAME\AppData\Local\Programs\Python\Python310\lib\site-packages\telegram\bot.py", line 2861, in get_updates
    self._post(
  File "C:\Users\USERNAME\AppData\Local\Programs\Python\Python310\lib\site-packages\telegram\bot.py", line 295, in _post
    return self.request.post(
  File "C:\Users\USERNAME\AppData\Local\Programs\Python\Python310\lib\site-packages\telegram\utils\request.py", line 356, in post
    result = self._request_wrapper(
  File "C:\Users\USERNAME\AppData\Local\Programs\Python\Python310\lib\site-packages\telegram\utils\request.py", line 283, in _request_wrapper
    raise Conflict(message)
telegram.error.Conflict: Conflict: terminated by other getUpdates request; make sure that only one bot instance is running
2023-06-21 23:37:40,535 - telegram.ext.updater - ERROR - Error while getting Updates: Conflict: terminated by other getUpdates request; make sure that only one bot instance is running
2023-06-21 23:37:40,536 - telegram.ext.dispatcher - ERROR - No error handlers are registered, logging exception.
Traceback (most recent call last):
  File "C:\Users\USERNAME\AppData\Local\Programs\Python\Python310\lib\site-packages\telegram\ext\updater.py", line 646, in _network_loop_retry
    if not action_cb():
  File "C:\Users\USERNAME\AppData\Local\Programs\Python\Python310\lib\site-packages\telegram\ext\updater.py", line 597, in polling_action_cb
    updates = self.bot.get_updates(
  File "C:\Users\USERNAME\AppData\Local\Programs\Python\Python310\lib\site-packages\telegram\ext\extbot.py", line 222, in get_updates
    updates = super().get_updates(
  File "C:\Users\USERNAME\AppData\Local\Programs\Python\Python310\lib\site-packages\telegram\bot.py", line 130, in decorator
    result = func(*args, **kwargs)
  File "C:\Users\USERNAME\AppData\Local\Programs\Python\Python310\lib\site-packages\telegram\bot.py", line 2861, in get_updates
    self._post(
  File "C:\Users\USERNAME\AppData\Local\Programs\Python\Python310\lib\site-packages\telegram\bot.py", line 295, in _post
    return self.request.post(
  File "C:\Users\USERNAME\AppData\Local\Programs\Python\Python310\lib\site-packages\telegram\utils\request.py", line 356, in post
    result = self._request_wrapper(
  File "C:\Users\USERNAME\AppData\Local\Programs\Python\Python310\lib\site-packages\telegram\utils\request.py", line 283, in _request_wrapper
    raise Conflict(message)
telegram.error.Conflict: Conflict: terminated by other getUpdates request; make sure that only one bot instance is running
2023-06-21 23:37:44,648 - telegram.ext.updater - ERROR - Error while getting Updates: Conflict: terminated by other getUpdates request; make sure that only one bot instance is running
2023-06-21 23:37:44,648 - telegram.ext.dispatcher - ERROR - No error handlers are registered, logging exception.
Traceback (most recent call last):
  File "C:\Users\USERNAME\AppData\Local\Programs\Python\Python310\lib\site-packages\telegram\ext\updater.py", line 646, in _network_loop_retry
    if not action_cb():
  File "C:\Users\USERNAME\AppData\Local\Programs\Python\Python310\lib\site-packages\telegram\ext\updater.py", line 597, in polling_action_cb
    updates = self.bot.get_updates(
  File "C:\Users\USERNAME\AppData\Local\Programs\Python\Python310\lib\site-packages\telegram\ext\extbot.py", line 222, in get_updates
    updates = super().get_updates(
  File "C:\Users\USERNAME\AppData\Local\Programs\Python\Python310\lib\site-packages\telegram\bot.py", line 130, in decorator
    result = func(*args, **kwargs)
  File "C:\Users\USERNAME\AppData\Local\Programs\Python\Python310\lib\site-packages\telegram\bot.py", line 2861, in get_updates
    self._post(
  File "C:\Users\USERNAME\AppData\Local\Programs\Python\Python310\lib\site-packages\telegram\bot.py", line 295, in _post
    return self.request.post(
  File "C:\Users\USERNAME\AppData\Local\Programs\Python\Python310\lib\site-packages\telegram\utils\request.py", line 356, in post
    result = self._request_wrapper(
  File "C:\Users\USERNAME\AppData\Local\Programs\Python\Python310\lib\site-packages\telegram\utils\request.py", line 283, in _request_wrapper
    raise Conflict(message)
telegram.error.Conflict: Conflict: terminated by other getUpdates request; make sure that only one bot instance is running
2023-06-21 23:38:14,745 - telegram.ext.updater - ERROR - Error while getting Updates: Conflict: terminated by other getUpdates request; make sure that only one bot instance is running
2023-06-21 23:38:14,745 - telegram.ext.dispatcher - ERROR - No error handlers are registered, logging exception.
Traceback (most recent call last):
  File "C:\Users\USERNAME\AppData\Local\Programs\Python\Python310\lib\site-packages\telegram\ext\updater.py", line 646, in _network_loop_retry
    if not action_cb():
  File "C:\Users\USERNAME\AppData\Local\Programs\Python\Python310\lib\site-packages\telegram\ext\updater.py", line 597, in polling_action_cb
    updates = self.bot.get_updates(
  File "C:\Users\USERNAME\AppData\Local\Programs\Python\Python310\lib\site-packages\telegram\ext\extbot.py", line 222, in get_updates
    updates = super().get_updates(
  File "C:\Users\USERNAME\AppData\Local\Programs\Python\Python310\lib\site-packages\telegram\bot.py", line 130, in decorator
    result = func(*args, **kwargs)
  File "C:\Users\USERNAME\AppData\Local\Programs\Python\Python310\lib\site-packages\telegram\bot.py", line 2861, in get_updates
    self._post(
  File "C:\Users\USERNAME\AppData\Local\Programs\Python\Python310\lib\site-packages\telegram\bot.py", line 295, in _post
    return self.request.post(
  File "C:\Users\USERNAME\AppData\Local\Programs\Python\Python310\lib\site-packages\telegram\utils\request.py", line 356, in post
    result = self._request_wrapper(
  File "C:\Users\USERNAME\AppData\Local\Programs\Python\Python310\lib\site-packages\telegram\utils\request.py", line 283, in _request_wrapper
    raise Conflict(message)
telegram.error.Conflict: Conflict: terminated by other getUpdates request; make sure that only one bot instance is running
2023-06-21 23:38:18,854 - telegram.ext.updater - ERROR - Error while getting Updates: Conflict: terminated by other getUpdates request; make sure that only one bot instance is running
2023-06-21 23:38:18,855 - telegram.ext.dispatcher - ERROR - No error handlers are registered, logging exception.
Traceback (most recent call last):
  File "C:\Users\USERNAME\AppData\Local\Programs\Python\Python310\lib\site-packages\telegram\ext\updater.py", line 646, in _network_loop_retry
    if not action_cb():
  File "C:\Users\USERNAME\AppData\Local\Programs\Python\Python310\lib\site-packages\telegram\ext\updater.py", line 597, in polling_action_cb
    updates = self.bot.get_updates(
  File "C:\Users\USERNAME\AppData\Local\Programs\Python\Python310\lib\site-packages\telegram\ext\extbot.py", line 222, in get_updates
    updates = super().get_updates(
  File "C:\Users\USERNAME\AppData\Local\Programs\Python\Python310\lib\site-packages\telegram\bot.py", line 130, in decorator
    result = func(*args, **kwargs)
  File "C:\Users\USERNAME\AppData\Local\Programs\Python\Python310\lib\site-packages\telegram\bot.py", line 2861, in get_updates
    self._post(
  File "C:\Users\USERNAME\AppData\Local\Programs\Python\Python310\lib\site-packages\telegram\bot.py", line 295, in _post
    return self.request.post(
  File "C:\Users\USERNAME\AppData\Local\Programs\Python\Python310\lib\site-packages\telegram\utils\request.py", line 356, in post
    result = self._request_wrapper(
  File "C:\Users\USERNAME\AppData\Local\Programs\Python\Python310\lib\site-packages\telegram\utils\request.py", line 283, in _request_wrapper
    raise Conflict(message)
telegram.error.Conflict: Conflict: terminated by other getUpdates request; make sure that only one bot instance is running
2023-06-21 23:38:48,957 - telegram.ext.updater - ERROR - Error while getting Updates: Conflict: terminated by other getUpdates request; make sure that only one bot instance is running
2023-06-21 23:38:48,958 - telegram.ext.dispatcher - ERROR - No error handlers are registered, logging exception.
Traceback (most recent call last):
  File "C:\Users\USERNAME\AppData\Local\Programs\Python\Python310\lib\site-packages\telegram\ext\updater.py", line 646, in _network_loop_retry
    if not action_cb():
  File "C:\Users\USERNAME\AppData\Local\Programs\Python\Python310\lib\site-packages\telegram\ext\updater.py", line 597, in polling_action_cb
    updates = self.bot.get_updates(
  File "C:\Users\USERNAME\AppData\Local\Programs\Python\Python310\lib\site-packages\telegram\ext\extbot.py", line 222, in get_updates
    updates = super().get_updates(
  File "C:\Users\USERNAME\AppData\Local\Programs\Python\Python310\lib\site-packages\telegram\bot.py", line 130, in decorator
    result = func(*args, **kwargs)
  File "C:\Users\USERNAME\AppData\Local\Programs\Python\Python310\lib\site-packages\telegram\bot.py", line 2861, in get_updates
    self._post(
  File "C:\Users\USERNAME\AppData\Local\Programs\Python\Python310\lib\site-packages\telegram\bot.py", line 295, in _post
    return self.request.post(
  File "C:\Users\USERNAME\AppData\Local\Programs\Python\Python310\lib\site-packages\telegram\utils\request.py", line 356, in post
    result = self._request_wrapper(
  File "C:\Users\USERNAME\AppData\Local\Programs\Python\Python310\lib\site-packages\telegram\utils\request.py", line 283, in _request_wrapper
    raise Conflict(message)
telegram.error.Conflict: Conflict: terminated by other getUpdates request; make sure that only one bot instance is running
2023-06-21 23:38:53,053 - telegram.ext.updater - ERROR - Error while getting Updates: Conflict: terminated by other getUpdates request; make sure that only one bot instance is running
2023-06-21 23:38:53,053 - telegram.ext.dispatcher - ERROR - No error handlers are registered, logging exception.
Traceback (most recent call last):
  File "C:\Users\USERNAME\AppData\Local\Programs\Python\Python310\lib\site-packages\telegram\ext\updater.py", line 646, in _network_loop_retry
    if not action_cb():
  File "C:\Users\USERNAME\AppData\Local\Programs\Python\Python310\lib\site-packages\telegram\ext\updater.py", line 597, in polling_action_cb
    updates = self.bot.get_updates(
  File "C:\Users\USERNAME\AppData\Local\Programs\Python\Python310\lib\site-packages\telegram\ext\extbot.py", line 222, in get_updates
    updates = super().get_updates(
  File "C:\Users\USERNAME\AppData\Local\Programs\Python\Python310\lib\site-packages\telegram\bot.py", line 130, in decorator
    result = func(*args, **kwargs)
  File "C:\Users\USERNAME\AppData\Local\Programs\Python\Python310\lib\site-packages\telegram\bot.py", line 2861, in get_updates
    self._post(
  File "C:\Users\USERNAME\AppData\Local\Programs\Python\Python310\lib\site-packages\telegram\bot.py", line 295, in _post
    return self.request.post(
  File "C:\Users\USERNAME\AppData\Local\Programs\Python\Python310\lib\site-packages\telegram\utils\request.py", line 356, in post
    result = self._request_wrapper(
  File "C:\Users\USERNAME\AppData\Local\Programs\Python\Python310\lib\site-packages\telegram\utils\request.py", line 283, in _request_wrapper
    raise Conflict(message)
telegram.error.Conflict: Conflict: terminated by other getUpdates request; make sure that only one bot instance is running
2023-06-21 23:39:23,161 - telegram.ext.updater - ERROR - Error while getting Updates: Conflict: terminated by other getUpdates request; make sure that only one bot instance is running
2023-06-21 23:39:23,162 - telegram.ext.dispatcher - ERROR - No error handlers are registered, logging exception.
Traceback (most recent call last):
  File "C:\Users\USERNAME\AppData\Local\Programs\Python\Python310\lib\site-packages\telegram\ext\updater.py", line 646, in _network_loop_retry
    if not action_cb():
  File "C:\Users\USERNAME\AppData\Local\Programs\Python\Python310\lib\site-packages\telegram\ext\updater.py", line 597, in polling_action_cb
    updates = self.bot.get_updates(
  File "C:\Users\USERNAME\AppData\Local\Programs\Python\Python310\lib\site-packages\telegram\ext\extbot.py", line 222, in get_updates
    updates = super().get_updates(
  File "C:\Users\USERNAME\AppData\Local\Programs\Python\Python310\lib\site-packages\telegram\bot.py", line 130, in decorator
    result = func(*args, **kwargs)
  File "C:\Users\USERNAME\AppData\Local\Programs\Python\Python310\lib\site-packages\telegram\bot.py", line 2861, in get_updates
    self._post(
  File "C:\Users\USERNAME\AppData\Local\Programs\Python\Python310\lib\site-packages\telegram\bot.py", line 295, in _post
    return self.request.post(
  File "C:\Users\USERNAME\AppData\Local\Programs\Python\Python310\lib\site-packages\telegram\utils\request.py", line 356, in post
    result = self._request_wrapper(
  File "C:\Users\USERNAME\AppData\Local\Programs\Python\Python310\lib\site-packages\telegram\utils\request.py", line 283, in _request_wrapper
    raise Conflict(message)
telegram.error.Conflict: Conflict: terminated by other getUpdates request; make sure that only one bot instance is running
2023-06-21 23:39:27,267 - telegram.ext.updater - ERROR - Error while getting Updates: Conflict: terminated by other getUpdates request; make sure that only one bot instance is running
2023-06-21 23:39:27,269 - telegram.ext.dispatcher - ERROR - No error handlers are registered, logging exception.
Traceback (most recent call last):
  File "C:\Users\USERNAME\AppData\Local\Programs\Python\Python310\lib\site-packages\telegram\ext\updater.py", line 646, in _network_loop_retry
    if not action_cb():
  File "C:\Users\USERNAME\AppData\Local\Programs\Python\Python310\lib\site-packages\telegram\ext\updater.py", line 597, in polling_action_cb
    updates = self.bot.get_updates(
  File "C:\Users\USERNAME\AppData\Local\Programs\Python\Python310\lib\site-packages\telegram\ext\extbot.py", line 222, in get_updates
    updates = super().get_updates(
  File "C:\Users\USERNAME\AppData\Local\Programs\Python\Python310\lib\site-packages\telegram\bot.py", line 130, in decorator
    result = func(*args, **kwargs)
  File "C:\Users\USERNAME\AppData\Local\Programs\Python\Python310\lib\site-packages\telegram\bot.py", line 2861, in get_updates
    self._post(
  File "C:\Users\USERNAME\AppData\Local\Programs\Python\Python310\lib\site-packages\telegram\bot.py", line 295, in _post
    return self.request.post(
  File "C:\Users\USERNAME\AppData\Local\Programs\Python\Python310\lib\site-packages\telegram\utils\request.py", line 356, in post
    result = self._request_wrapper(
  File "C:\Users\USERNAME\AppData\Local\Programs\Python\Python310\lib\site-packages\telegram\utils\request.py", line 283, in _request_wrapper
    raise Conflict(message)
telegram.error.Conflict: Conflict: terminated by other getUpdates request; make sure that only one bot instance is running
2023-06-21 23:52:36,044 - apscheduler.scheduler - INFO - Scheduler started
2023-06-21 23:52:37,309 - werkzeug - INFO - [31m[1mWARNING: This is a development server. Do not use it in a production deployment. Use a production WSGI server instead.[0m
 * Running on all addresses (0.0.0.0)
 * Running on http://127.0.0.1:5000
 * Running on http://192.168.0.231:5000
2023-06-21 23:52:37,309 - werkzeug - INFO - [33mPress CTRL+C to quit[0m
2023-06-21 23:52:37,315 - werkzeug - INFO -  * Restarting with stat
2023-06-21 23:52:38,916 - apscheduler.scheduler - INFO - Scheduler started
2023-06-21 23:52:39,348 - werkzeug - WARNING -  * Debugger is active!
2023-06-21 23:52:39,354 - werkzeug - INFO -  * Debugger PIN: 106-333-038
2023-06-21 23:52:39,422 - telegram.ext.updater - ERROR - Error while getting Updates: Conflict: terminated by other getUpdates request; make sure that only one bot instance is running
2023-06-21 23:52:39,422 - telegram.ext.dispatcher - ERROR - No error handlers are registered, logging exception.
Traceback (most recent call last):
  File "C:\Users\USERNAME\AppData\Local\Programs\Python\Python310\lib\site-packages\telegram\ext\updater.py", line 646, in _network_loop_retry
    if not action_cb():
  File "C:\Users\USERNAME\AppData\Local\Programs\Python\Python310\lib\site-packages\telegram\ext\updater.py", line 597, in polling_action_cb
    updates = self.bot.get_updates(
  File "C:\Users\USERNAME\AppData\Local\Programs\Python\Python310\lib\site-packages\telegram\ext\extbot.py", line 222, in get_updates
    updates = super().get_updates(
  File "C:\Users\USERNAME\AppData\Local\Programs\Python\Python310\lib\site-packages\telegram\bot.py", line 130, in decorator
    result = func(*args, **kwargs)
  File "C:\Users\USERNAME\AppData\Local\Programs\Python\Python310\lib\site-packages\telegram\bot.py", line 2861, in get_updates
    self._post(
  File "C:\Users\USERNAME\AppData\Local\Programs\Python\Python310\lib\site-packages\telegram\bot.py", line 295, in _post
    return self.request.post(
  File "C:\Users\USERNAME\AppData\Local\Programs\Python\Python310\lib\site-packages\telegram\utils\request.py", line 356, in post
    result = self._request_wrapper(
  File "C:\Users\USERNAME\AppData\Local\Programs\Python\Python310\lib\site-packages\telegram\utils\request.py", line 283, in _request_wrapper
    raise Conflict(message)
telegram.error.Conflict: Conflict: terminated by other getUpdates request; make sure that only one bot instance is running
2023-06-21 23:52:43,512 - telegram.ext.updater - ERROR - Error while getting Updates: Conflict: terminated by other getUpdates request; make sure that only one bot instance is running
2023-06-21 23:52:43,513 - telegram.ext.dispatcher - ERROR - No error handlers are registered, logging exception.
Traceback (most recent call last):
  File "C:\Users\USERNAME\AppData\Local\Programs\Python\Python310\lib\site-packages\telegram\ext\updater.py", line 646, in _network_loop_retry
    if not action_cb():
  File "C:\Users\USERNAME\AppData\Local\Programs\Python\Python310\lib\site-packages\telegram\ext\updater.py", line 597, in polling_action_cb
    updates = self.bot.get_updates(
  File "C:\Users\USERNAME\AppData\Local\Programs\Python\Python310\lib\site-packages\telegram\ext\extbot.py", line 222, in get_updates
    updates = super().get_updates(
  File "C:\Users\USERNAME\AppData\Local\Programs\Python\Python310\lib\site-packages\telegram\bot.py", line 130, in decorator
    result = func(*args, **kwargs)
  File "C:\Users\USERNAME\AppData\Local\Programs\Python\Python310\lib\site-packages\telegram\bot.py", line 2861, in get_updates
    self._post(
  File "C:\Users\USERNAME\AppData\Local\Programs\Python\Python310\lib\site-packages\telegram\bot.py", line 295, in _post
    return self.request.post(
  File "C:\Users\USERNAME\AppData\Local\Programs\Python\Python310\lib\site-packages\telegram\utils\request.py", line 356, in post
    result = self._request_wrapper(
  File "C:\Users\USERNAME\AppData\Local\Programs\Python\Python310\lib\site-packages\telegram\utils\request.py", line 283, in _request_wrapper
    raise Conflict(message)
telegram.error.Conflict: Conflict: terminated by other getUpdates request; make sure that only one bot instance is running
2023-06-21 23:52:44,611 - telegram.ext.updater - ERROR - Error while getting Updates: Conflict: terminated by other getUpdates request; make sure that only one bot instance is running
2023-06-21 23:52:44,611 - telegram.ext.dispatcher - ERROR - No error handlers are registered, logging exception.
Traceback (most recent call last):
  File "C:\Users\USERNAME\AppData\Local\Programs\Python\Python310\lib\site-packages\telegram\ext\updater.py", line 646, in _network_loop_retry
    if not action_cb():
  File "C:\Users\USERNAME\AppData\Local\Programs\Python\Python310\lib\site-packages\telegram\ext\updater.py", line 597, in polling_action_cb
    updates = self.bot.get_updates(
  File "C:\Users\USERNAME\AppData\Local\Programs\Python\Python310\lib\site-packages\telegram\ext\extbot.py", line 222, in get_updates
    updates = super().get_updates(
  File "C:\Users\USERNAME\AppData\Local\Programs\Python\Python310\lib\site-packages\telegram\bot.py", line 130, in decorator
    result = func(*args, **kwargs)
  File "C:\Users\USERNAME\AppData\Local\Programs\Python\Python310\lib\site-packages\telegram\bot.py", line 2861, in get_updates
    self._post(
  File "C:\Users\USERNAME\AppData\Local\Programs\Python\Python310\lib\site-packages\telegram\bot.py", line 295, in _post
    return self.request.post(
  File "C:\Users\USERNAME\AppData\Local\Programs\Python\Python310\lib\site-packages\telegram\utils\request.py", line 356, in post
    result = self._request_wrapper(
  File "C:\Users\USERNAME\AppData\Local\Programs\Python\Python310\lib\site-packages\telegram\utils\request.py", line 283, in _request_wrapper
    raise Conflict(message)
telegram.error.Conflict: Conflict: terminated by other getUpdates request; make sure that only one bot instance is running
2023-06-21 23:52:48,706 - telegram.ext.updater - ERROR - Error while getting Updates: Conflict: terminated by other getUpdates request; make sure that only one bot instance is running
2023-06-21 23:52:48,707 - telegram.ext.dispatcher - ERROR - No error handlers are registered, logging exception.
Traceback (most recent call last):
  File "C:\Users\USERNAME\AppData\Local\Programs\Python\Python310\lib\site-packages\telegram\ext\updater.py", line 646, in _network_loop_retry
    if not action_cb():
  File "C:\Users\USERNAME\AppData\Local\Programs\Python\Python310\lib\site-packages\telegram\ext\updater.py", line 597, in polling_action_cb
    updates = self.bot.get_updates(
  File "C:\Users\USERNAME\AppData\Local\Programs\Python\Python310\lib\site-packages\telegram\ext\extbot.py", line 222, in get_updates
    updates = super().get_updates(
  File "C:\Users\USERNAME\AppData\Local\Programs\Python\Python310\lib\site-packages\telegram\bot.py", line 130, in decorator
    result = func(*args, **kwargs)
  File "C:\Users\USERNAME\AppData\Local\Programs\Python\Python310\lib\site-packages\telegram\bot.py", line 2861, in get_updates
    self._post(
  File "C:\Users\USERNAME\AppData\Local\Programs\Python\Python310\lib\site-packages\telegram\bot.py", line 295, in _post
    return self.request.post(
  File "C:\Users\USERNAME\AppData\Local\Programs\Python\Python310\lib\site-packages\telegram\utils\request.py", line 356, in post
    result = self._request_wrapper(
  File "C:\Users\USERNAME\AppData\Local\Programs\Python\Python310\lib\site-packages\telegram\utils\request.py", line 283, in _request_wrapper
    raise Conflict(message)
telegram.error.Conflict: Conflict: terminated by other getUpdates request; make sure that only one bot instance is running
2023-06-21 23:52:50,309 - telegram.ext.updater - ERROR - Error while getting Updates: Conflict: terminated by other getUpdates request; make sure that only one bot instance is running
2023-06-21 23:52:50,310 - telegram.ext.dispatcher - ERROR - No error handlers are registered, logging exception.
Traceback (most recent call last):
  File "C:\Users\USERNAME\AppData\Local\Programs\Python\Python310\lib\site-packages\telegram\ext\updater.py", line 646, in _network_loop_retry
    if not action_cb():
  File "C:\Users\USERNAME\AppData\Local\Programs\Python\Python310\lib\site-packages\telegram\ext\updater.py", line 597, in polling_action_cb
    updates = self.bot.get_updates(
  File "C:\Users\USERNAME\AppData\Local\Programs\Python\Python310\lib\site-packages\telegram\ext\extbot.py", line 222, in get_updates
    updates = super().get_updates(
  File "C:\Users\USERNAME\AppData\Local\Programs\Python\Python310\lib\site-packages\telegram\bot.py", line 130, in decorator
    result = func(*args, **kwargs)
  File "C:\Users\USERNAME\AppData\Local\Programs\Python\Python310\lib\site-packages\telegram\bot.py", line 2861, in get_updates
    self._post(
  File "C:\Users\USERNAME\AppData\Local\Programs\Python\Python310\lib\site-packages\telegram\bot.py", line 295, in _post
    return self.request.post(
  File "C:\Users\USERNAME\AppData\Local\Programs\Python\Python310\lib\site-packages\telegram\utils\request.py", line 356, in post
    result = self._request_wrapper(
  File "C:\Users\USERNAME\AppData\Local\Programs\Python\Python310\lib\site-packages\telegram\utils\request.py", line 283, in _request_wrapper
    raise Conflict(message)
telegram.error.Conflict: Conflict: terminated by other getUpdates request; make sure that only one bot instance is running
2023-06-21 23:52:54,910 - telegram.ext.updater - ERROR - Error while getting Updates: Conflict: terminated by other getUpdates request; make sure that only one bot instance is running
2023-06-21 23:52:54,911 - telegram.ext.dispatcher - ERROR - No error handlers are registered, logging exception.
Traceback (most recent call last):
  File "C:\Users\USERNAME\AppData\Local\Programs\Python\Python310\lib\site-packages\telegram\ext\updater.py", line 646, in _network_loop_retry
    if not action_cb():
  File "C:\Users\USERNAME\AppData\Local\Programs\Python\Python310\lib\site-packages\telegram\ext\updater.py", line 597, in polling_action_cb
    updates = self.bot.get_updates(
  File "C:\Users\USERNAME\AppData\Local\Programs\Python\Python310\lib\site-packages\telegram\ext\extbot.py", line 222, in get_updates
    updates = super().get_updates(
  File "C:\Users\USERNAME\AppData\Local\Programs\Python\Python310\lib\site-packages\telegram\bot.py", line 130, in decorator
    result = func(*args, **kwargs)
  File "C:\Users\USERNAME\AppData\Local\Programs\Python\Python310\lib\site-packages\telegram\bot.py", line 2861, in get_updates
    self._post(
  File "C:\Users\USERNAME\AppData\Local\Programs\Python\Python310\lib\site-packages\telegram\bot.py", line 295, in _post
    return self.request.post(
  File "C:\Users\USERNAME\AppData\Local\Programs\Python\Python310\lib\site-packages\telegram\utils\request.py", line 356, in post
    result = self._request_wrapper(
  File "C:\Users\USERNAME\AppData\Local\Programs\Python\Python310\lib\site-packages\telegram\utils\request.py", line 283, in _request_wrapper
    raise Conflict(message)
telegram.error.Conflict: Conflict: terminated by other getUpdates request; make sure that only one bot instance is running
2023-06-21 23:52:57,265 - telegram.ext.updater - ERROR - Error while getting Updates: Conflict: terminated by other getUpdates request; make sure that only one bot instance is running
2023-06-21 23:52:57,266 - telegram.ext.dispatcher - ERROR - No error handlers are registered, logging exception.
Traceback (most recent call last):
  File "C:\Users\USERNAME\AppData\Local\Programs\Python\Python310\lib\site-packages\telegram\ext\updater.py", line 646, in _network_loop_retry
    if not action_cb():
  File "C:\Users\USERNAME\AppData\Local\Programs\Python\Python310\lib\site-packages\telegram\ext\updater.py", line 597, in polling_action_cb
    updates = self.bot.get_updates(
  File "C:\Users\USERNAME\AppData\Local\Programs\Python\Python310\lib\site-packages\telegram\ext\extbot.py", line 222, in get_updates
    updates = super().get_updates(
  File "C:\Users\USERNAME\AppData\Local\Programs\Python\Python310\lib\site-packages\telegram\bot.py", line 130, in decorator
    result = func(*args, **kwargs)
  File "C:\Users\USERNAME\AppData\Local\Programs\Python\Python310\lib\site-packages\telegram\bot.py", line 2861, in get_updates
    self._post(
  File "C:\Users\USERNAME\AppData\Local\Programs\Python\Python310\lib\site-packages\telegram\bot.py", line 295, in _post
    return self.request.post(
  File "C:\Users\USERNAME\AppData\Local\Programs\Python\Python310\lib\site-packages\telegram\utils\request.py", line 356, in post
    result = self._request_wrapper(
  File "C:\Users\USERNAME\AppData\Local\Programs\Python\Python310\lib\site-packages\telegram\utils\request.py", line 283, in _request_wrapper
    raise Conflict(message)
telegram.error.Conflict: Conflict: terminated by other getUpdates request; make sure that only one bot instance is running
2023-06-21 23:53:02,651 - telegram.ext.updater - ERROR - Error while getting Updates: Conflict: terminated by other getUpdates request; make sure that only one bot instance is running
2023-06-21 23:53:02,652 - telegram.ext.dispatcher - ERROR - No error handlers are registered, logging exception.
Traceback (most recent call last):
  File "C:\Users\USERNAME\AppData\Local\Programs\Python\Python310\lib\site-packages\telegram\ext\updater.py", line 646, in _network_loop_retry
    if not action_cb():
  File "C:\Users\USERNAME\AppData\Local\Programs\Python\Python310\lib\site-packages\telegram\ext\updater.py", line 597, in polling_action_cb
    updates = self.bot.get_updates(
  File "C:\Users\USERNAME\AppData\Local\Programs\Python\Python310\lib\site-packages\telegram\ext\extbot.py", line 222, in get_updates
    updates = super().get_updates(
  File "C:\Users\USERNAME\AppData\Local\Programs\Python\Python310\lib\site-packages\telegram\bot.py", line 130, in decorator
    result = func(*args, **kwargs)
  File "C:\Users\USERNAME\AppData\Local\Programs\Python\Python310\lib\site-packages\telegram\bot.py", line 2861, in get_updates
    self._post(
  File "C:\Users\USERNAME\AppData\Local\Programs\Python\Python310\lib\site-packages\telegram\bot.py", line 295, in _post
    return self.request.post(
  File "C:\Users\USERNAME\AppData\Local\Programs\Python\Python310\lib\site-packages\telegram\utils\request.py", line 356, in post
    result = self._request_wrapper(
  File "C:\Users\USERNAME\AppData\Local\Programs\Python\Python310\lib\site-packages\telegram\utils\request.py", line 283, in _request_wrapper
    raise Conflict(message)
telegram.error.Conflict: Conflict: terminated by other getUpdates request; make sure that only one bot instance is running
2023-06-21 23:53:06,122 - telegram.ext.updater - ERROR - Error while getting Updates: Conflict: terminated by other getUpdates request; make sure that only one bot instance is running
2023-06-21 23:53:06,123 - telegram.ext.dispatcher - ERROR - No error handlers are registered, logging exception.
Traceback (most recent call last):
  File "C:\Users\USERNAME\AppData\Local\Programs\Python\Python310\lib\site-packages\telegram\ext\updater.py", line 646, in _network_loop_retry
    if not action_cb():
  File "C:\Users\USERNAME\AppData\Local\Programs\Python\Python310\lib\site-packages\telegram\ext\updater.py", line 597, in polling_action_cb
    updates = self.bot.get_updates(
  File "C:\Users\USERNAME\AppData\Local\Programs\Python\Python310\lib\site-packages\telegram\ext\extbot.py", line 222, in get_updates
    updates = super().get_updates(
  File "C:\Users\USERNAME\AppData\Local\Programs\Python\Python310\lib\site-packages\telegram\bot.py", line 130, in decorator
    result = func(*args, **kwargs)
  File "C:\Users\USERNAME\AppData\Local\Programs\Python\Python310\lib\site-packages\telegram\bot.py", line 2861, in get_updates
    self._post(
  File "C:\Users\USERNAME\AppData\Local\Programs\Python\Python310\lib\site-packages\telegram\bot.py", line 295, in _post
    return self.request.post(
  File "C:\Users\USERNAME\AppData\Local\Programs\Python\Python310\lib\site-packages\telegram\utils\request.py", line 356, in post
    result = self._request_wrapper(
  File "C:\Users\USERNAME\AppData\Local\Programs\Python\Python310\lib\site-packages\telegram\utils\request.py", line 283, in _request_wrapper
    raise Conflict(message)
telegram.error.Conflict: Conflict: terminated by other getUpdates request; make sure that only one bot instance is running
2023-06-21 23:53:09,605 - telegram.ext.updater - ERROR - Error while getting Updates: Conflict: terminated by other getUpdates request; make sure that only one bot instance is running
2023-06-21 23:53:09,606 - telegram.ext.dispatcher - ERROR - No error handlers are registered, logging exception.
Traceback (most recent call last):
  File "C:\Users\USERNAME\AppData\Local\Programs\Python\Python310\lib\site-packages\telegram\ext\updater.py", line 646, in _network_loop_retry
    if not action_cb():
  File "C:\Users\USERNAME\AppData\Local\Programs\Python\Python310\lib\site-packages\telegram\ext\updater.py", line 597, in polling_action_cb
    updates = self.bot.get_updates(
  File "C:\Users\USERNAME\AppData\Local\Programs\Python\Python310\lib\site-packages\telegram\ext\extbot.py", line 222, in get_updates
    updates = super().get_updates(
  File "C:\Users\USERNAME\AppData\Local\Programs\Python\Python310\lib\site-packages\telegram\bot.py", line 130, in decorator
    result = func(*args, **kwargs)
  File "C:\Users\USERNAME\AppData\Local\Programs\Python\Python310\lib\site-packages\telegram\bot.py", line 2861, in get_updates
    self._post(
  File "C:\Users\USERNAME\AppData\Local\Programs\Python\Python310\lib\site-packages\telegram\bot.py", line 295, in _post
    return self.request.post(
  File "C:\Users\USERNAME\AppData\Local\Programs\Python\Python310\lib\site-packages\telegram\utils\request.py", line 356, in post
    result = self._request_wrapper(
  File "C:\Users\USERNAME\AppData\Local\Programs\Python\Python310\lib\site-packages\telegram\utils\request.py", line 283, in _request_wrapper
    raise Conflict(message)
telegram.error.Conflict: Conflict: terminated by other getUpdates request; make sure that only one bot instance is running
2023-06-21 23:53:13,696 - telegram.ext.updater - ERROR - Error while getting Updates: Conflict: terminated by other getUpdates request; make sure that only one bot instance is running
2023-06-21 23:53:13,696 - telegram.ext.dispatcher - ERROR - No error handlers are registered, logging exception.
Traceback (most recent call last):
  File "C:\Users\USERNAME\AppData\Local\Programs\Python\Python310\lib\site-packages\telegram\ext\updater.py", line 646, in _network_loop_retry
    if not action_cb():
  File "C:\Users\USERNAME\AppData\Local\Programs\Python\Python310\lib\site-packages\telegram\ext\updater.py", line 597, in polling_action_cb
    updates = self.bot.get_updates(
  File "C:\Users\USERNAME\AppData\Local\Programs\Python\Python310\lib\site-packages\telegram\ext\extbot.py", line 222, in get_updates
    updates = super().get_updates(
  File "C:\Users\USERNAME\AppData\Local\Programs\Python\Python310\lib\site-packages\telegram\bot.py", line 130, in decorator
    result = func(*args, **kwargs)
  File "C:\Users\USERNAME\AppData\Local\Programs\Python\Python310\lib\site-packages\telegram\bot.py", line 2861, in get_updates
    self._post(
  File "C:\Users\USERNAME\AppData\Local\Programs\Python\Python310\lib\site-packages\telegram\bot.py", line 295, in _post
    return self.request.post(
  File "C:\Users\USERNAME\AppData\Local\Programs\Python\Python310\lib\site-packages\telegram\utils\request.py", line 356, in post
    result = self._request_wrapper(
  File "C:\Users\USERNAME\AppData\Local\Programs\Python\Python310\lib\site-packages\telegram\utils\request.py", line 283, in _request_wrapper
    raise Conflict(message)
telegram.error.Conflict: Conflict: terminated by other getUpdates request; make sure that only one bot instance is running
2023-06-21 23:59:33,687 - apscheduler.scheduler - INFO - Scheduler started
2023-06-21 23:59:35,036 - werkzeug - INFO - [31m[1mWARNING: This is a development server. Do not use it in a production deployment. Use a production WSGI server instead.[0m
 * Running on all addresses (0.0.0.0)
 * Running on http://127.0.0.1:5000
 * Running on http://192.168.0.231:5000
2023-06-21 23:59:35,036 - werkzeug - INFO - [33mPress CTRL+C to quit[0m
2023-06-21 23:59:35,036 - werkzeug - INFO -  * Restarting with stat
2023-06-21 23:59:36,681 - apscheduler.scheduler - INFO - Scheduler started
2023-06-21 23:59:37,074 - werkzeug - WARNING -  * Debugger is active!
2023-06-21 23:59:37,089 - werkzeug - INFO -  * Debugger PIN: 529-428-773
2023-06-21 23:59:37,137 - telegram.ext.updater - ERROR - Error while getting Updates: Conflict: terminated by other getUpdates request; make sure that only one bot instance is running
2023-06-21 23:59:37,137 - telegram.ext.dispatcher - ERROR - No error handlers are registered, logging exception.
Traceback (most recent call last):
  File "C:\Users\USERNAME\AppData\Local\Programs\Python\Python310\lib\site-packages\telegram\ext\updater.py", line 646, in _network_loop_retry
    if not action_cb():
  File "C:\Users\USERNAME\AppData\Local\Programs\Python\Python310\lib\site-packages\telegram\ext\updater.py", line 597, in polling_action_cb
    updates = self.bot.get_updates(
  File "C:\Users\USERNAME\AppData\Local\Programs\Python\Python310\lib\site-packages\telegram\ext\extbot.py", line 222, in get_updates
    updates = super().get_updates(
  File "C:\Users\USERNAME\AppData\Local\Programs\Python\Python310\lib\site-packages\telegram\bot.py", line 130, in decorator
    result = func(*args, **kwargs)
  File "C:\Users\USERNAME\AppData\Local\Programs\Python\Python310\lib\site-packages\telegram\bot.py", line 2861, in get_updates
    self._post(
  File "C:\Users\USERNAME\AppData\Local\Programs\Python\Python310\lib\site-packages\telegram\bot.py", line 295, in _post
    return self.request.post(
  File "C:\Users\USERNAME\AppData\Local\Programs\Python\Python310\lib\site-packages\telegram\utils\request.py", line 356, in post
    result = self._request_wrapper(
  File "C:\Users\USERNAME\AppData\Local\Programs\Python\Python310\lib\site-packages\telegram\utils\request.py", line 283, in _request_wrapper
    raise Conflict(message)
telegram.error.Conflict: Conflict: terminated by other getUpdates request; make sure that only one bot instance is running
2023-06-21 23:59:39,472 - apscheduler.scheduler - INFO - Scheduler has been shut down
2023-06-21 23:59:41,228 - telegram.ext.updater - ERROR - Error while getting Updates: Conflict: terminated by other getUpdates request; make sure that only one bot instance is running
2023-06-21 23:59:42,308 - apscheduler.scheduler - INFO - Scheduler has been shut down
2023-06-24 21:47:33,852 - apscheduler.scheduler - INFO - Scheduler started
2023-06-24 21:47:35,514 - werkzeug - INFO - [31m[1mWARNING: This is a development server. Do not use it in a production deployment. Use a production WSGI server instead.[0m
 * Running on all addresses (0.0.0.0)
 * Running on http://127.0.0.1:5000
 * Running on http://192.168.0.231:5000
2023-06-24 21:47:35,514 - werkzeug - INFO - [33mPress CTRL+C to quit[0m
2023-06-24 21:47:38,441 - telegram.ext.updater - ERROR - Error while getting Updates: Conflict: terminated by other getUpdates request; make sure that only one bot instance is running
2023-06-24 21:47:38,442 - telegram.ext.dispatcher - ERROR - No error handlers are registered, logging exception.
Traceback (most recent call last):
  File "C:\Users\USERNAME\AppData\Local\Programs\Python\Python310\lib\site-packages\telegram\ext\updater.py", line 646, in _network_loop_retry
    if not action_cb():
  File "C:\Users\USERNAME\AppData\Local\Programs\Python\Python310\lib\site-packages\telegram\ext\updater.py", line 597, in polling_action_cb
    updates = self.bot.get_updates(
  File "C:\Users\USERNAME\AppData\Local\Programs\Python\Python310\lib\site-packages\telegram\ext\extbot.py", line 222, in get_updates
    updates = super().get_updates(
  File "C:\Users\USERNAME\AppData\Local\Programs\Python\Python310\lib\site-packages\telegram\bot.py", line 130, in decorator
    result = func(*args, **kwargs)
  File "C:\Users\USERNAME\AppData\Local\Programs\Python\Python310\lib\site-packages\telegram\bot.py", line 2861, in get_updates
    self._post(
  File "C:\Users\USERNAME\AppData\Local\Programs\Python\Python310\lib\site-packages\telegram\bot.py", line 295, in _post
    return self.request.post(
  File "C:\Users\USERNAME\AppData\Local\Programs\Python\Python310\lib\site-packages\telegram\utils\request.py", line 356, in post
    result = self._request_wrapper(
  File "C:\Users\USERNAME\AppData\Local\Programs\Python\Python310\lib\site-packages\telegram\utils\request.py", line 283, in _request_wrapper
    raise Conflict(message)
telegram.error.Conflict: Conflict: terminated by other getUpdates request; make sure that only one bot instance is running
2023-06-24 21:47:44,056 - telegram.ext.updater - ERROR - Error while getting Updates: Conflict: terminated by other getUpdates request; make sure that only one bot instance is running
2023-06-24 21:47:44,057 - telegram.ext.dispatcher - ERROR - No error handlers are registered, logging exception.
Traceback (most recent call last):
  File "C:\Users\USERNAME\AppData\Local\Programs\Python\Python310\lib\site-packages\telegram\ext\updater.py", line 646, in _network_loop_retry
    if not action_cb():
  File "C:\Users\USERNAME\AppData\Local\Programs\Python\Python310\lib\site-packages\telegram\ext\updater.py", line 597, in polling_action_cb
    updates = self.bot.get_updates(
  File "C:\Users\USERNAME\AppData\Local\Programs\Python\Python310\lib\site-packages\telegram\ext\extbot.py", line 222, in get_updates
    updates = super().get_updates(
  File "C:\Users\USERNAME\AppData\Local\Programs\Python\Python310\lib\site-packages\telegram\bot.py", line 130, in decorator
    result = func(*args, **kwargs)
  File "C:\Users\USERNAME\AppData\Local\Programs\Python\Python310\lib\site-packages\telegram\bot.py", line 2861, in get_updates
    self._post(
  File "C:\Users\USERNAME\AppData\Local\Programs\Python\Python310\lib\site-packages\telegram\bot.py", line 295, in _post
    return self.request.post(
  File "C:\Users\USERNAME\AppData\Local\Programs\Python\Python310\lib\site-packages\telegram\utils\request.py", line 356, in post
    result = self._request_wrapper(
  File "C:\Users\USERNAME\AppData\Local\Programs\Python\Python310\lib\site-packages\telegram\utils\request.py", line 283, in _request_wrapper
    raise Conflict(message)
telegram.error.Conflict: Conflict: terminated by other getUpdates request; make sure that only one bot instance is running
2023-06-24 21:47:50,927 - telegram.ext.updater - ERROR - Error while getting Updates: Conflict: terminated by other getUpdates request; make sure that only one bot instance is running
2023-06-24 21:47:50,927 - telegram.ext.dispatcher - ERROR - No error handlers are registered, logging exception.
Traceback (most recent call last):
  File "C:\Users\USERNAME\AppData\Local\Programs\Python\Python310\lib\site-packages\telegram\ext\updater.py", line 646, in _network_loop_retry
    if not action_cb():
  File "C:\Users\USERNAME\AppData\Local\Programs\Python\Python310\lib\site-packages\telegram\ext\updater.py", line 597, in polling_action_cb
    updates = self.bot.get_updates(
  File "C:\Users\USERNAME\AppData\Local\Programs\Python\Python310\lib\site-packages\telegram\ext\extbot.py", line 222, in get_updates
    updates = super().get_updates(
  File "C:\Users\USERNAME\AppData\Local\Programs\Python\Python310\lib\site-packages\telegram\bot.py", line 130, in decorator
    result = func(*args, **kwargs)
  File "C:\Users\USERNAME\AppData\Local\Programs\Python\Python310\lib\site-packages\telegram\bot.py", line 2861, in get_updates
    self._post(
  File "C:\Users\USERNAME\AppData\Local\Programs\Python\Python310\lib\site-packages\telegram\bot.py", line 295, in _post
    return self.request.post(
  File "C:\Users\USERNAME\AppData\Local\Programs\Python\Python310\lib\site-packages\telegram\utils\request.py", line 356, in post
    result = self._request_wrapper(
  File "C:\Users\USERNAME\AppData\Local\Programs\Python\Python310\lib\site-packages\telegram\utils\request.py", line 283, in _request_wrapper
    raise Conflict(message)
telegram.error.Conflict: Conflict: terminated by other getUpdates request; make sure that only one bot instance is running
2023-06-24 21:47:56,665 - telegram.ext.updater - ERROR - Error while getting Updates: Conflict: terminated by other getUpdates request; make sure that only one bot instance is running
2023-06-24 21:47:56,665 - telegram.ext.dispatcher - ERROR - No error handlers are registered, logging exception.
Traceback (most recent call last):
  File "C:\Users\USERNAME\AppData\Local\Programs\Python\Python310\lib\site-packages\telegram\ext\updater.py", line 646, in _network_loop_retry
    if not action_cb():
  File "C:\Users\USERNAME\AppData\Local\Programs\Python\Python310\lib\site-packages\telegram\ext\updater.py", line 597, in polling_action_cb
    updates = self.bot.get_updates(
  File "C:\Users\USERNAME\AppData\Local\Programs\Python\Python310\lib\site-packages\telegram\ext\extbot.py", line 222, in get_updates
    updates = super().get_updates(
  File "C:\Users\USERNAME\AppData\Local\Programs\Python\Python310\lib\site-packages\telegram\bot.py", line 130, in decorator
    result = func(*args, **kwargs)
  File "C:\Users\USERNAME\AppData\Local\Programs\Python\Python310\lib\site-packages\telegram\bot.py", line 2861, in get_updates
    self._post(
  File "C:\Users\USERNAME\AppData\Local\Programs\Python\Python310\lib\site-packages\telegram\bot.py", line 295, in _post
    return self.request.post(
  File "C:\Users\USERNAME\AppData\Local\Programs\Python\Python310\lib\site-packages\telegram\utils\request.py", line 356, in post
    result = self._request_wrapper(
  File "C:\Users\USERNAME\AppData\Local\Programs\Python\Python310\lib\site-packages\telegram\utils\request.py", line 283, in _request_wrapper
    raise Conflict(message)
telegram.error.Conflict: Conflict: terminated by other getUpdates request; make sure that only one bot instance is running
2023-06-24 21:48:05,236 - telegram.ext.updater - ERROR - Error while getting Updates: Conflict: terminated by other getUpdates request; make sure that only one bot instance is running
2023-06-24 21:48:05,236 - telegram.ext.dispatcher - ERROR - No error handlers are registered, logging exception.
Traceback (most recent call last):
  File "C:\Users\USERNAME\AppData\Local\Programs\Python\Python310\lib\site-packages\telegram\ext\updater.py", line 646, in _network_loop_retry
    if not action_cb():
  File "C:\Users\USERNAME\AppData\Local\Programs\Python\Python310\lib\site-packages\telegram\ext\updater.py", line 597, in polling_action_cb
    updates = self.bot.get_updates(
  File "C:\Users\USERNAME\AppData\Local\Programs\Python\Python310\lib\site-packages\telegram\ext\extbot.py", line 222, in get_updates
    updates = super().get_updates(
  File "C:\Users\USERNAME\AppData\Local\Programs\Python\Python310\lib\site-packages\telegram\bot.py", line 130, in decorator
    result = func(*args, **kwargs)
  File "C:\Users\USERNAME\AppData\Local\Programs\Python\Python310\lib\site-packages\telegram\bot.py", line 2861, in get_updates
    self._post(
  File "C:\Users\USERNAME\AppData\Local\Programs\Python\Python310\lib\site-packages\telegram\bot.py", line 295, in _post
    return self.request.post(
  File "C:\Users\USERNAME\AppData\Local\Programs\Python\Python310\lib\site-packages\telegram\utils\request.py", line 356, in post
    result = self._request_wrapper(
  File "C:\Users\USERNAME\AppData\Local\Programs\Python\Python310\lib\site-packages\telegram\utils\request.py", line 283, in _request_wrapper
    raise Conflict(message)
telegram.error.Conflict: Conflict: terminated by other getUpdates request; make sure that only one bot instance is running
2023-06-24 21:48:18,010 - telegram.ext.updater - ERROR - Error while getting Updates: Conflict: terminated by other getUpdates request; make sure that only one bot instance is running
2023-06-24 21:48:18,011 - telegram.ext.dispatcher - ERROR - No error handlers are registered, logging exception.
Traceback (most recent call last):
  File "C:\Users\USERNAME\AppData\Local\Programs\Python\Python310\lib\site-packages\telegram\ext\updater.py", line 646, in _network_loop_retry
    if not action_cb():
  File "C:\Users\USERNAME\AppData\Local\Programs\Python\Python310\lib\site-packages\telegram\ext\updater.py", line 597, in polling_action_cb
    updates = self.bot.get_updates(
  File "C:\Users\USERNAME\AppData\Local\Programs\Python\Python310\lib\site-packages\telegram\ext\extbot.py", line 222, in get_updates
    updates = super().get_updates(
  File "C:\Users\USERNAME\AppData\Local\Programs\Python\Python310\lib\site-packages\telegram\bot.py", line 130, in decorator
    result = func(*args, **kwargs)
  File "C:\Users\USERNAME\AppData\Local\Programs\Python\Python310\lib\site-packages\telegram\bot.py", line 2861, in get_updates
    self._post(
  File "C:\Users\USERNAME\AppData\Local\Programs\Python\Python310\lib\site-packages\telegram\bot.py", line 295, in _post
    return self.request.post(
  File "C:\Users\USERNAME\AppData\Local\Programs\Python\Python310\lib\site-packages\telegram\utils\request.py", line 356, in post
    result = self._request_wrapper(
  File "C:\Users\USERNAME\AppData\Local\Programs\Python\Python310\lib\site-packages\telegram\utils\request.py", line 283, in _request_wrapper
    raise Conflict(message)
telegram.error.Conflict: Conflict: terminated by other getUpdates request; make sure that only one bot instance is running
2023-06-24 21:48:37,125 - telegram.ext.updater - ERROR - Error while getting Updates: Conflict: terminated by other getUpdates request; make sure that only one bot instance is running
2023-06-24 21:48:37,125 - telegram.ext.dispatcher - ERROR - No error handlers are registered, logging exception.
Traceback (most recent call last):
  File "C:\Users\USERNAME\AppData\Local\Programs\Python\Python310\lib\site-packages\telegram\ext\updater.py", line 646, in _network_loop_retry
    if not action_cb():
  File "C:\Users\USERNAME\AppData\Local\Programs\Python\Python310\lib\site-packages\telegram\ext\updater.py", line 597, in polling_action_cb
    updates = self.bot.get_updates(
  File "C:\Users\USERNAME\AppData\Local\Programs\Python\Python310\lib\site-packages\telegram\ext\extbot.py", line 222, in get_updates
    updates = super().get_updates(
  File "C:\Users\USERNAME\AppData\Local\Programs\Python\Python310\lib\site-packages\telegram\bot.py", line 130, in decorator
    result = func(*args, **kwargs)
  File "C:\Users\USERNAME\AppData\Local\Programs\Python\Python310\lib\site-packages\telegram\bot.py", line 2861, in get_updates
    self._post(
  File "C:\Users\USERNAME\AppData\Local\Programs\Python\Python310\lib\site-packages\telegram\bot.py", line 295, in _post
    return self.request.post(
  File "C:\Users\USERNAME\AppData\Local\Programs\Python\Python310\lib\site-packages\telegram\utils\request.py", line 356, in post
    result = self._request_wrapper(
  File "C:\Users\USERNAME\AppData\Local\Programs\Python\Python310\lib\site-packages\telegram\utils\request.py", line 283, in _request_wrapper
    raise Conflict(message)
telegram.error.Conflict: Conflict: terminated by other getUpdates request; make sure that only one bot instance is running
2023-06-24 21:48:56,877 - telegram.ext.dispatcher - ERROR - No error handlers are registered, logging exception.
Traceback (most recent call last):
  File "C:\Users\USERNAME\AppData\Local\Programs\Python\Python310\lib\site-packages\telegram\ext\dispatcher.py", line 555, in process_update
    handler.handle_update(update, self, check, context)
  File "C:\Users\USERNAME\AppData\Local\Programs\Python\Python310\lib\site-packages\telegram\ext\handler.py", line 198, in handle_update
    return self.callback(update, context)
  File "C:\Users\USERNAME\Desktop\AIESEC_CRUSH_BOT\main.py", line 84, in random_gif
    gif_files = os.listdir(GIFS_DIR)
FileNotFoundError: [WinError 3] Системе не удается найти указанный путь: 'gifs'
2023-06-24 21:48:58,328 - telegram.ext.updater - ERROR - Error while getting Updates: Conflict: terminated by other getUpdates request; make sure that only one bot instance is running
2023-06-24 21:48:58,329 - telegram.ext.dispatcher - ERROR - No error handlers are registered, logging exception.
Traceback (most recent call last):
  File "C:\Users\USERNAME\AppData\Local\Programs\Python\Python310\lib\site-packages\telegram\ext\updater.py", line 646, in _network_loop_retry
    if not action_cb():
  File "C:\Users\USERNAME\AppData\Local\Programs\Python\Python310\lib\site-packages\telegram\ext\updater.py", line 597, in polling_action_cb
    updates = self.bot.get_updates(
  File "C:\Users\USERNAME\AppData\Local\Programs\Python\Python310\lib\site-packages\telegram\ext\extbot.py", line 222, in get_updates
    updates = super().get_updates(
  File "C:\Users\USERNAME\AppData\Local\Programs\Python\Python310\lib\site-packages\telegram\bot.py", line 130, in decorator
    result = func(*args, **kwargs)
  File "C:\Users\USERNAME\AppData\Local\Programs\Python\Python310\lib\site-packages\telegram\bot.py", line 2861, in get_updates
    self._post(
  File "C:\Users\USERNAME\AppData\Local\Programs\Python\Python310\lib\site-packages\telegram\bot.py", line 295, in _post
    return self.request.post(
  File "C:\Users\USERNAME\AppData\Local\Programs\Python\Python310\lib\site-packages\telegram\utils\request.py", line 356, in post
    result = self._request_wrapper(
  File "C:\Users\USERNAME\AppData\Local\Programs\Python\Python310\lib\site-packages\telegram\utils\request.py", line 283, in _request_wrapper
    raise Conflict(message)
telegram.error.Conflict: Conflict: terminated by other getUpdates request; make sure that only one bot instance is running
2023-06-24 21:49:28,072 - telegram.ext.updater - ERROR - Error while getting Updates: Conflict: terminated by other getUpdates request; make sure that only one bot instance is running
2023-06-24 21:49:28,072 - telegram.ext.dispatcher - ERROR - No error handlers are registered, logging exception.
Traceback (most recent call last):
  File "C:\Users\USERNAME\AppData\Local\Programs\Python\Python310\lib\site-packages\telegram\ext\updater.py", line 646, in _network_loop_retry
    if not action_cb():
  File "C:\Users\USERNAME\AppData\Local\Programs\Python\Python310\lib\site-packages\telegram\ext\updater.py", line 597, in polling_action_cb
    updates = self.bot.get_updates(
  File "C:\Users\USERNAME\AppData\Local\Programs\Python\Python310\lib\site-packages\telegram\ext\extbot.py", line 222, in get_updates
    updates = super().get_updates(
  File "C:\Users\USERNAME\AppData\Local\Programs\Python\Python310\lib\site-packages\telegram\bot.py", line 130, in decorator
    result = func(*args, **kwargs)
  File "C:\Users\USERNAME\AppData\Local\Programs\Python\Python310\lib\site-packages\telegram\bot.py", line 2861, in get_updates
    self._post(
  File "C:\Users\USERNAME\AppData\Local\Programs\Python\Python310\lib\site-packages\telegram\bot.py", line 295, in _post
    return self.request.post(
  File "C:\Users\USERNAME\AppData\Local\Programs\Python\Python310\lib\site-packages\telegram\utils\request.py", line 356, in post
    result = self._request_wrapper(
  File "C:\Users\USERNAME\AppData\Local\Programs\Python\Python310\lib\site-packages\telegram\utils\request.py", line 283, in _request_wrapper
    raise Conflict(message)
telegram.error.Conflict: Conflict: terminated by other getUpdates request; make sure that only one bot instance is running
2023-06-24 21:49:34,343 - telegram.ext.dispatcher - ERROR - No error handlers are registered, logging exception.
Traceback (most recent call last):
  File "C:\Users\USERNAME\AppData\Local\Programs\Python\Python310\lib\site-packages\telegram\ext\dispatcher.py", line 555, in process_update
    handler.handle_update(update, self, check, context)
  File "C:\Users\USERNAME\AppData\Local\Programs\Python\Python310\lib\site-packages\telegram\ext\handler.py", line 198, in handle_update
    return self.callback(update, context)
  File "C:\Users\USERNAME\Desktop\AIESEC_CRUSH_BOT\main.py", line 84, in random_gif
    gif_files = os.listdir(GIFS_DIR)
FileNotFoundError: [WinError 3] Системе не удается найти указанный путь: 'gifs'
2023-06-24 21:50:10,644 - telegram.ext.updater - ERROR - Error while getting Updates: Conflict: terminated by other getUpdates request; make sure that only one bot instance is running
2023-06-24 21:50:10,644 - telegram.ext.dispatcher - ERROR - No error handlers are registered, logging exception.
Traceback (most recent call last):
  File "C:\Users\USERNAME\AppData\Local\Programs\Python\Python310\lib\site-packages\telegram\ext\updater.py", line 646, in _network_loop_retry
    if not action_cb():
  File "C:\Users\USERNAME\AppData\Local\Programs\Python\Python310\lib\site-packages\telegram\ext\updater.py", line 597, in polling_action_cb
    updates = self.bot.get_updates(
  File "C:\Users\USERNAME\AppData\Local\Programs\Python\Python310\lib\site-packages\telegram\ext\extbot.py", line 222, in get_updates
    updates = super().get_updates(
  File "C:\Users\USERNAME\AppData\Local\Programs\Python\Python310\lib\site-packages\telegram\bot.py", line 130, in decorator
    result = func(*args, **kwargs)
  File "C:\Users\USERNAME\AppData\Local\Programs\Python\Python310\lib\site-packages\telegram\bot.py", line 2861, in get_updates
    self._post(
  File "C:\Users\USERNAME\AppData\Local\Programs\Python\Python310\lib\site-packages\telegram\bot.py", line 295, in _post
    return self.request.post(
  File "C:\Users\USERNAME\AppData\Local\Programs\Python\Python310\lib\site-packages\telegram\utils\request.py", line 356, in post
    result = self._request_wrapper(
  File "C:\Users\USERNAME\AppData\Local\Programs\Python\Python310\lib\site-packages\telegram\utils\request.py", line 283, in _request_wrapper
    raise Conflict(message)
telegram.error.Conflict: Conflict: terminated by other getUpdates request; make sure that only one bot instance is running
2023-06-24 21:50:44,764 - telegram.ext.updater - ERROR - Error while getting Updates: Conflict: terminated by other getUpdates request; make sure that only one bot instance is running
2023-06-24 21:50:44,764 - telegram.ext.dispatcher - ERROR - No error handlers are registered, logging exception.
Traceback (most recent call last):
  File "C:\Users\USERNAME\AppData\Local\Programs\Python\Python310\lib\site-packages\telegram\ext\updater.py", line 646, in _network_loop_retry
    if not action_cb():
  File "C:\Users\USERNAME\AppData\Local\Programs\Python\Python310\lib\site-packages\telegram\ext\updater.py", line 597, in polling_action_cb
    updates = self.bot.get_updates(
  File "C:\Users\USERNAME\AppData\Local\Programs\Python\Python310\lib\site-packages\telegram\ext\extbot.py", line 222, in get_updates
    updates = super().get_updates(
  File "C:\Users\USERNAME\AppData\Local\Programs\Python\Python310\lib\site-packages\telegram\bot.py", line 130, in decorator
    result = func(*args, **kwargs)
  File "C:\Users\USERNAME\AppData\Local\Programs\Python\Python310\lib\site-packages\telegram\bot.py", line 2861, in get_updates
    self._post(
  File "C:\Users\USERNAME\AppData\Local\Programs\Python\Python310\lib\site-packages\telegram\bot.py", line 295, in _post
    return self.request.post(
  File "C:\Users\USERNAME\AppData\Local\Programs\Python\Python310\lib\site-packages\telegram\utils\request.py", line 356, in post
    result = self._request_wrapper(
  File "C:\Users\USERNAME\AppData\Local\Programs\Python\Python310\lib\site-packages\telegram\utils\request.py", line 283, in _request_wrapper
    raise Conflict(message)
telegram.error.Conflict: Conflict: terminated by other getUpdates request; make sure that only one bot instance is running
2023-06-24 21:51:00,644 - telegram.ext.dispatcher - ERROR - No error handlers are registered, logging exception.
Traceback (most recent call last):
  File "C:\Users\USERNAME\AppData\Local\Programs\Python\Python310\lib\site-packages\telegram\ext\dispatcher.py", line 555, in process_update
    handler.handle_update(update, self, check, context)
  File "C:\Users\USERNAME\AppData\Local\Programs\Python\Python310\lib\site-packages\telegram\ext\handler.py", line 198, in handle_update
    return self.callback(update, context)
  File "C:\Users\USERNAME\Desktop\AIESEC_CRUSH_BOT\main.py", line 84, in random_gif
    gif_files = os.listdir(GIFS_DIR)
FileNotFoundError: [WinError 3] Системе не удается найти указанный путь: 'gifs'
2023-06-24 21:51:18,893 - telegram.ext.updater - ERROR - Error while getting Updates: Conflict: terminated by other getUpdates request; make sure that only one bot instance is running
2023-06-24 21:51:18,894 - telegram.ext.dispatcher - ERROR - No error handlers are registered, logging exception.
Traceback (most recent call last):
  File "C:\Users\USERNAME\AppData\Local\Programs\Python\Python310\lib\site-packages\telegram\ext\updater.py", line 646, in _network_loop_retry
    if not action_cb():
  File "C:\Users\USERNAME\AppData\Local\Programs\Python\Python310\lib\site-packages\telegram\ext\updater.py", line 597, in polling_action_cb
    updates = self.bot.get_updates(
  File "C:\Users\USERNAME\AppData\Local\Programs\Python\Python310\lib\site-packages\telegram\ext\extbot.py", line 222, in get_updates
    updates = super().get_updates(
  File "C:\Users\USERNAME\AppData\Local\Programs\Python\Python310\lib\site-packages\telegram\bot.py", line 130, in decorator
    result = func(*args, **kwargs)
  File "C:\Users\USERNAME\AppData\Local\Programs\Python\Python310\lib\site-packages\telegram\bot.py", line 2861, in get_updates
    self._post(
  File "C:\Users\USERNAME\AppData\Local\Programs\Python\Python310\lib\site-packages\telegram\bot.py", line 295, in _post
    return self.request.post(
  File "C:\Users\USERNAME\AppData\Local\Programs\Python\Python310\lib\site-packages\telegram\utils\request.py", line 356, in post
    result = self._request_wrapper(
  File "C:\Users\USERNAME\AppData\Local\Programs\Python\Python310\lib\site-packages\telegram\utils\request.py", line 283, in _request_wrapper
    raise Conflict(message)
telegram.error.Conflict: Conflict: terminated by other getUpdates request; make sure that only one bot instance is running
2023-06-24 21:51:53,015 - telegram.ext.updater - ERROR - Error while getting Updates: Conflict: terminated by other getUpdates request; make sure that only one bot instance is running
2023-06-24 21:51:53,015 - telegram.ext.dispatcher - ERROR - No error handlers are registered, logging exception.
Traceback (most recent call last):
  File "C:\Users\USERNAME\AppData\Local\Programs\Python\Python310\lib\site-packages\telegram\ext\updater.py", line 646, in _network_loop_retry
    if not action_cb():
  File "C:\Users\USERNAME\AppData\Local\Programs\Python\Python310\lib\site-packages\telegram\ext\updater.py", line 597, in polling_action_cb
    updates = self.bot.get_updates(
  File "C:\Users\USERNAME\AppData\Local\Programs\Python\Python310\lib\site-packages\telegram\ext\extbot.py", line 222, in get_updates
    updates = super().get_updates(
  File "C:\Users\USERNAME\AppData\Local\Programs\Python\Python310\lib\site-packages\telegram\bot.py", line 130, in decorator
    result = func(*args, **kwargs)
  File "C:\Users\USERNAME\AppData\Local\Programs\Python\Python310\lib\site-packages\telegram\bot.py", line 2861, in get_updates
    self._post(
  File "C:\Users\USERNAME\AppData\Local\Programs\Python\Python310\lib\site-packages\telegram\bot.py", line 295, in _post
    return self.request.post(
  File "C:\Users\USERNAME\AppData\Local\Programs\Python\Python310\lib\site-packages\telegram\utils\request.py", line 356, in post
    result = self._request_wrapper(
  File "C:\Users\USERNAME\AppData\Local\Programs\Python\Python310\lib\site-packages\telegram\utils\request.py", line 283, in _request_wrapper
    raise Conflict(message)
telegram.error.Conflict: Conflict: terminated by other getUpdates request; make sure that only one bot instance is running
2023-06-24 21:52:27,129 - telegram.ext.updater - ERROR - Error while getting Updates: Conflict: terminated by other getUpdates request; make sure that only one bot instance is running
2023-06-24 21:52:27,129 - telegram.ext.dispatcher - ERROR - No error handlers are registered, logging exception.
Traceback (most recent call last):
  File "C:\Users\USERNAME\AppData\Local\Programs\Python\Python310\lib\site-packages\telegram\ext\updater.py", line 646, in _network_loop_retry
    if not action_cb():
  File "C:\Users\USERNAME\AppData\Local\Programs\Python\Python310\lib\site-packages\telegram\ext\updater.py", line 597, in polling_action_cb
    updates = self.bot.get_updates(
  File "C:\Users\USERNAME\AppData\Local\Programs\Python\Python310\lib\site-packages\telegram\ext\extbot.py", line 222, in get_updates
    updates = super().get_updates(
  File "C:\Users\USERNAME\AppData\Local\Programs\Python\Python310\lib\site-packages\telegram\bot.py", line 130, in decorator
    result = func(*args, **kwargs)
  File "C:\Users\USERNAME\AppData\Local\Programs\Python\Python310\lib\site-packages\telegram\bot.py", line 2861, in get_updates
    self._post(
  File "C:\Users\USERNAME\AppData\Local\Programs\Python\Python310\lib\site-packages\telegram\bot.py", line 295, in _post
    return self.request.post(
  File "C:\Users\USERNAME\AppData\Local\Programs\Python\Python310\lib\site-packages\telegram\utils\request.py", line 356, in post
    result = self._request_wrapper(
  File "C:\Users\USERNAME\AppData\Local\Programs\Python\Python310\lib\site-packages\telegram\utils\request.py", line 283, in _request_wrapper
    raise Conflict(message)
telegram.error.Conflict: Conflict: terminated by other getUpdates request; make sure that only one bot instance is running
2023-06-24 21:52:32,735 - telegram.ext.dispatcher - ERROR - No error handlers are registered, logging exception.
Traceback (most recent call last):
  File "C:\Users\USERNAME\AppData\Local\Programs\Python\Python310\lib\site-packages\telegram\ext\dispatcher.py", line 555, in process_update
    handler.handle_update(update, self, check, context)
  File "C:\Users\USERNAME\AppData\Local\Programs\Python\Python310\lib\site-packages\telegram\ext\handler.py", line 198, in handle_update
    return self.callback(update, context)
  File "C:\Users\USERNAME\Desktop\AIESEC_CRUSH_BOT\main.py", line 84, in random_gif
    gif_files = os.listdir(GIFS_DIR)
FileNotFoundError: [WinError 3] Системе не удается найти указанный путь: 'gifs'
2023-06-24 21:53:17,469 - apscheduler.scheduler - INFO - Scheduler started
2023-06-24 21:53:18,744 - werkzeug - INFO - [31m[1mWARNING: This is a development server. Do not use it in a production deployment. Use a production WSGI server instead.[0m
 * Running on all addresses (0.0.0.0)
 * Running on http://127.0.0.1:5000
 * Running on http://192.168.0.231:5000
2023-06-24 21:53:18,744 - werkzeug - INFO - [33mPress CTRL+C to quit[0m
2023-06-24 21:53:22,011 - telegram.ext.updater - ERROR - Error while getting Updates: Conflict: terminated by other getUpdates request; make sure that only one bot instance is running
2023-06-24 21:53:22,011 - telegram.ext.dispatcher - ERROR - No error handlers are registered, logging exception.
Traceback (most recent call last):
  File "C:\Users\USERNAME\AppData\Local\Programs\Python\Python310\lib\site-packages\telegram\ext\updater.py", line 646, in _network_loop_retry
    if not action_cb():
  File "C:\Users\USERNAME\AppData\Local\Programs\Python\Python310\lib\site-packages\telegram\ext\updater.py", line 597, in polling_action_cb
    updates = self.bot.get_updates(
  File "C:\Users\USERNAME\AppData\Local\Programs\Python\Python310\lib\site-packages\telegram\ext\extbot.py", line 222, in get_updates
    updates = super().get_updates(
  File "C:\Users\USERNAME\AppData\Local\Programs\Python\Python310\lib\site-packages\telegram\bot.py", line 130, in decorator
    result = func(*args, **kwargs)
  File "C:\Users\USERNAME\AppData\Local\Programs\Python\Python310\lib\site-packages\telegram\bot.py", line 2861, in get_updates
    self._post(
  File "C:\Users\USERNAME\AppData\Local\Programs\Python\Python310\lib\site-packages\telegram\bot.py", line 295, in _post
    return self.request.post(
  File "C:\Users\USERNAME\AppData\Local\Programs\Python\Python310\lib\site-packages\telegram\utils\request.py", line 356, in post
    result = self._request_wrapper(
  File "C:\Users\USERNAME\AppData\Local\Programs\Python\Python310\lib\site-packages\telegram\utils\request.py", line 283, in _request_wrapper
    raise Conflict(message)
telegram.error.Conflict: Conflict: terminated by other getUpdates request; make sure that only one bot instance is running
2023-06-24 21:53:27,131 - telegram.ext.updater - ERROR - Error while getting Updates: Conflict: terminated by other getUpdates request; make sure that only one bot instance is running
2023-06-24 21:53:27,131 - telegram.ext.dispatcher - ERROR - No error handlers are registered, logging exception.
Traceback (most recent call last):
  File "C:\Users\USERNAME\AppData\Local\Programs\Python\Python310\lib\site-packages\telegram\ext\updater.py", line 646, in _network_loop_retry
    if not action_cb():
  File "C:\Users\USERNAME\AppData\Local\Programs\Python\Python310\lib\site-packages\telegram\ext\updater.py", line 597, in polling_action_cb
    updates = self.bot.get_updates(
  File "C:\Users\USERNAME\AppData\Local\Programs\Python\Python310\lib\site-packages\telegram\ext\extbot.py", line 222, in get_updates
    updates = super().get_updates(
  File "C:\Users\USERNAME\AppData\Local\Programs\Python\Python310\lib\site-packages\telegram\bot.py", line 130, in decorator
    result = func(*args, **kwargs)
  File "C:\Users\USERNAME\AppData\Local\Programs\Python\Python310\lib\site-packages\telegram\bot.py", line 2861, in get_updates
    self._post(
  File "C:\Users\USERNAME\AppData\Local\Programs\Python\Python310\lib\site-packages\telegram\bot.py", line 295, in _post
    return self.request.post(
  File "C:\Users\USERNAME\AppData\Local\Programs\Python\Python310\lib\site-packages\telegram\utils\request.py", line 356, in post
    result = self._request_wrapper(
  File "C:\Users\USERNAME\AppData\Local\Programs\Python\Python310\lib\site-packages\telegram\utils\request.py", line 283, in _request_wrapper
    raise Conflict(message)
telegram.error.Conflict: Conflict: terminated by other getUpdates request; make sure that only one bot instance is running
2023-06-24 21:53:33,245 - telegram.ext.updater - ERROR - Error while getting Updates: Conflict: terminated by other getUpdates request; make sure that only one bot instance is running
2023-06-24 21:53:33,245 - telegram.ext.dispatcher - ERROR - No error handlers are registered, logging exception.
Traceback (most recent call last):
  File "C:\Users\USERNAME\AppData\Local\Programs\Python\Python310\lib\site-packages\telegram\ext\updater.py", line 646, in _network_loop_retry
    if not action_cb():
  File "C:\Users\USERNAME\AppData\Local\Programs\Python\Python310\lib\site-packages\telegram\ext\updater.py", line 597, in polling_action_cb
    updates = self.bot.get_updates(
  File "C:\Users\USERNAME\AppData\Local\Programs\Python\Python310\lib\site-packages\telegram\ext\extbot.py", line 222, in get_updates
    updates = super().get_updates(
  File "C:\Users\USERNAME\AppData\Local\Programs\Python\Python310\lib\site-packages\telegram\bot.py", line 130, in decorator
    result = func(*args, **kwargs)
  File "C:\Users\USERNAME\AppData\Local\Programs\Python\Python310\lib\site-packages\telegram\bot.py", line 2861, in get_updates
    self._post(
  File "C:\Users\USERNAME\AppData\Local\Programs\Python\Python310\lib\site-packages\telegram\bot.py", line 295, in _post
    return self.request.post(
  File "C:\Users\USERNAME\AppData\Local\Programs\Python\Python310\lib\site-packages\telegram\utils\request.py", line 356, in post
    result = self._request_wrapper(
  File "C:\Users\USERNAME\AppData\Local\Programs\Python\Python310\lib\site-packages\telegram\utils\request.py", line 283, in _request_wrapper
    raise Conflict(message)
telegram.error.Conflict: Conflict: terminated by other getUpdates request; make sure that only one bot instance is running
2023-06-24 21:53:40,867 - telegram.ext.updater - ERROR - Error while getting Updates: Conflict: terminated by other getUpdates request; make sure that only one bot instance is running
2023-06-24 21:53:40,867 - telegram.ext.dispatcher - ERROR - No error handlers are registered, logging exception.
Traceback (most recent call last):
  File "C:\Users\USERNAME\AppData\Local\Programs\Python\Python310\lib\site-packages\telegram\ext\updater.py", line 646, in _network_loop_retry
    if not action_cb():
  File "C:\Users\USERNAME\AppData\Local\Programs\Python\Python310\lib\site-packages\telegram\ext\updater.py", line 597, in polling_action_cb
    updates = self.bot.get_updates(
  File "C:\Users\USERNAME\AppData\Local\Programs\Python\Python310\lib\site-packages\telegram\ext\extbot.py", line 222, in get_updates
    updates = super().get_updates(
  File "C:\Users\USERNAME\AppData\Local\Programs\Python\Python310\lib\site-packages\telegram\bot.py", line 130, in decorator
    result = func(*args, **kwargs)
  File "C:\Users\USERNAME\AppData\Local\Programs\Python\Python310\lib\site-packages\telegram\bot.py", line 2861, in get_updates
    self._post(
  File "C:\Users\USERNAME\AppData\Local\Programs\Python\Python310\lib\site-packages\telegram\bot.py", line 295, in _post
    return self.request.post(
  File "C:\Users\USERNAME\AppData\Local\Programs\Python\Python310\lib\site-packages\telegram\utils\request.py", line 356, in post
    result = self._request_wrapper(
  File "C:\Users\USERNAME\AppData\Local\Programs\Python\Python310\lib\site-packages\telegram\utils\request.py", line 283, in _request_wrapper
    raise Conflict(message)
telegram.error.Conflict: Conflict: terminated by other getUpdates request; make sure that only one bot instance is running
2023-06-24 21:53:48,364 - telegram.ext.updater - ERROR - Error while getting Updates: Conflict: terminated by other getUpdates request; make sure that only one bot instance is running
2023-06-24 21:53:48,364 - telegram.ext.dispatcher - ERROR - No error handlers are registered, logging exception.
Traceback (most recent call last):
  File "C:\Users\USERNAME\AppData\Local\Programs\Python\Python310\lib\site-packages\telegram\ext\updater.py", line 646, in _network_loop_retry
    if not action_cb():
  File "C:\Users\USERNAME\AppData\Local\Programs\Python\Python310\lib\site-packages\telegram\ext\updater.py", line 597, in polling_action_cb
    updates = self.bot.get_updates(
  File "C:\Users\USERNAME\AppData\Local\Programs\Python\Python310\lib\site-packages\telegram\ext\extbot.py", line 222, in get_updates
    updates = super().get_updates(
  File "C:\Users\USERNAME\AppData\Local\Programs\Python\Python310\lib\site-packages\telegram\bot.py", line 130, in decorator
    result = func(*args, **kwargs)
  File "C:\Users\USERNAME\AppData\Local\Programs\Python\Python310\lib\site-packages\telegram\bot.py", line 2861, in get_updates
    self._post(
  File "C:\Users\USERNAME\AppData\Local\Programs\Python\Python310\lib\site-packages\telegram\bot.py", line 295, in _post
    return self.request.post(
  File "C:\Users\USERNAME\AppData\Local\Programs\Python\Python310\lib\site-packages\telegram\utils\request.py", line 356, in post
    result = self._request_wrapper(
  File "C:\Users\USERNAME\AppData\Local\Programs\Python\Python310\lib\site-packages\telegram\utils\request.py", line 283, in _request_wrapper
    raise Conflict(message)
telegram.error.Conflict: Conflict: terminated by other getUpdates request; make sure that only one bot instance is running
2023-06-24 21:53:53,099 - apscheduler.scheduler - INFO - Scheduler has been shut down
2023-06-24 21:54:12,443 - apscheduler.scheduler - INFO - Scheduler started
2023-06-24 21:54:13,759 - werkzeug - INFO - [31m[1mWARNING: This is a development server. Do not use it in a production deployment. Use a production WSGI server instead.[0m
 * Running on all addresses (0.0.0.0)
 * Running on http://127.0.0.1:5000
 * Running on http://192.168.0.231:5000
2023-06-24 21:54:13,759 - werkzeug - INFO - [33mPress CTRL+C to quit[0m
2023-06-24 21:54:16,989 - telegram.ext.updater - ERROR - Error while getting Updates: Conflict: terminated by other getUpdates request; make sure that only one bot instance is running
2023-06-24 21:54:17,004 - telegram.ext.dispatcher - ERROR - No error handlers are registered, logging exception.
Traceback (most recent call last):
  File "C:\Users\USERNAME\AppData\Local\Programs\Python\Python310\lib\site-packages\telegram\ext\updater.py", line 646, in _network_loop_retry
    if not action_cb():
  File "C:\Users\USERNAME\AppData\Local\Programs\Python\Python310\lib\site-packages\telegram\ext\updater.py", line 597, in polling_action_cb
    updates = self.bot.get_updates(
  File "C:\Users\USERNAME\AppData\Local\Programs\Python\Python310\lib\site-packages\telegram\ext\extbot.py", line 222, in get_updates
    updates = super().get_updates(
  File "C:\Users\USERNAME\AppData\Local\Programs\Python\Python310\lib\site-packages\telegram\bot.py", line 130, in decorator
    result = func(*args, **kwargs)
  File "C:\Users\USERNAME\AppData\Local\Programs\Python\Python310\lib\site-packages\telegram\bot.py", line 2861, in get_updates
    self._post(
  File "C:\Users\USERNAME\AppData\Local\Programs\Python\Python310\lib\site-packages\telegram\bot.py", line 295, in _post
    return self.request.post(
  File "C:\Users\USERNAME\AppData\Local\Programs\Python\Python310\lib\site-packages\telegram\utils\request.py", line 356, in post
    result = self._request_wrapper(
  File "C:\Users\USERNAME\AppData\Local\Programs\Python\Python310\lib\site-packages\telegram\utils\request.py", line 283, in _request_wrapper
    raise Conflict(message)
telegram.error.Conflict: Conflict: terminated by other getUpdates request; make sure that only one bot instance is running
2023-06-24 21:54:22,625 - telegram.ext.updater - ERROR - Error while getting Updates: Conflict: terminated by other getUpdates request; make sure that only one bot instance is running
2023-06-24 21:54:22,625 - telegram.ext.dispatcher - ERROR - No error handlers are registered, logging exception.
Traceback (most recent call last):
  File "C:\Users\USERNAME\AppData\Local\Programs\Python\Python310\lib\site-packages\telegram\ext\updater.py", line 646, in _network_loop_retry
    if not action_cb():
  File "C:\Users\USERNAME\AppData\Local\Programs\Python\Python310\lib\site-packages\telegram\ext\updater.py", line 597, in polling_action_cb
    updates = self.bot.get_updates(
  File "C:\Users\USERNAME\AppData\Local\Programs\Python\Python310\lib\site-packages\telegram\ext\extbot.py", line 222, in get_updates
    updates = super().get_updates(
  File "C:\Users\USERNAME\AppData\Local\Programs\Python\Python310\lib\site-packages\telegram\bot.py", line 130, in decorator
    result = func(*args, **kwargs)
  File "C:\Users\USERNAME\AppData\Local\Programs\Python\Python310\lib\site-packages\telegram\bot.py", line 2861, in get_updates
    self._post(
  File "C:\Users\USERNAME\AppData\Local\Programs\Python\Python310\lib\site-packages\telegram\bot.py", line 295, in _post
    return self.request.post(
  File "C:\Users\USERNAME\AppData\Local\Programs\Python\Python310\lib\site-packages\telegram\utils\request.py", line 356, in post
    result = self._request_wrapper(
  File "C:\Users\USERNAME\AppData\Local\Programs\Python\Python310\lib\site-packages\telegram\utils\request.py", line 283, in _request_wrapper
    raise Conflict(message)
telegram.error.Conflict: Conflict: terminated by other getUpdates request; make sure that only one bot instance is running
2023-06-24 21:54:28,232 - telegram.ext.updater - ERROR - Error while getting Updates: Conflict: terminated by other getUpdates request; make sure that only one bot instance is running
2023-06-24 21:54:28,232 - telegram.ext.dispatcher - ERROR - No error handlers are registered, logging exception.
Traceback (most recent call last):
  File "C:\Users\USERNAME\AppData\Local\Programs\Python\Python310\lib\site-packages\telegram\ext\updater.py", line 646, in _network_loop_retry
    if not action_cb():
  File "C:\Users\USERNAME\AppData\Local\Programs\Python\Python310\lib\site-packages\telegram\ext\updater.py", line 597, in polling_action_cb
    updates = self.bot.get_updates(
  File "C:\Users\USERNAME\AppData\Local\Programs\Python\Python310\lib\site-packages\telegram\ext\extbot.py", line 222, in get_updates
    updates = super().get_updates(
  File "C:\Users\USERNAME\AppData\Local\Programs\Python\Python310\lib\site-packages\telegram\bot.py", line 130, in decorator
    result = func(*args, **kwargs)
  File "C:\Users\USERNAME\AppData\Local\Programs\Python\Python310\lib\site-packages\telegram\bot.py", line 2861, in get_updates
    self._post(
  File "C:\Users\USERNAME\AppData\Local\Programs\Python\Python310\lib\site-packages\telegram\bot.py", line 295, in _post
    return self.request.post(
  File "C:\Users\USERNAME\AppData\Local\Programs\Python\Python310\lib\site-packages\telegram\utils\request.py", line 356, in post
    result = self._request_wrapper(
  File "C:\Users\USERNAME\AppData\Local\Programs\Python\Python310\lib\site-packages\telegram\utils\request.py", line 283, in _request_wrapper
    raise Conflict(message)
telegram.error.Conflict: Conflict: terminated by other getUpdates request; make sure that only one bot instance is running
2023-06-24 21:54:33,851 - telegram.ext.updater - ERROR - Error while getting Updates: Conflict: terminated by other getUpdates request; make sure that only one bot instance is running
2023-06-24 21:54:33,851 - telegram.ext.dispatcher - ERROR - No error handlers are registered, logging exception.
Traceback (most recent call last):
  File "C:\Users\USERNAME\AppData\Local\Programs\Python\Python310\lib\site-packages\telegram\ext\updater.py", line 646, in _network_loop_retry
    if not action_cb():
  File "C:\Users\USERNAME\AppData\Local\Programs\Python\Python310\lib\site-packages\telegram\ext\updater.py", line 597, in polling_action_cb
    updates = self.bot.get_updates(
  File "C:\Users\USERNAME\AppData\Local\Programs\Python\Python310\lib\site-packages\telegram\ext\extbot.py", line 222, in get_updates
    updates = super().get_updates(
  File "C:\Users\USERNAME\AppData\Local\Programs\Python\Python310\lib\site-packages\telegram\bot.py", line 130, in decorator
    result = func(*args, **kwargs)
  File "C:\Users\USERNAME\AppData\Local\Programs\Python\Python310\lib\site-packages\telegram\bot.py", line 2861, in get_updates
    self._post(
  File "C:\Users\USERNAME\AppData\Local\Programs\Python\Python310\lib\site-packages\telegram\bot.py", line 295, in _post
    return self.request.post(
  File "C:\Users\USERNAME\AppData\Local\Programs\Python\Python310\lib\site-packages\telegram\utils\request.py", line 356, in post
    result = self._request_wrapper(
  File "C:\Users\USERNAME\AppData\Local\Programs\Python\Python310\lib\site-packages\telegram\utils\request.py", line 283, in _request_wrapper
    raise Conflict(message)
telegram.error.Conflict: Conflict: terminated by other getUpdates request; make sure that only one bot instance is running
2023-06-24 21:54:39,458 - telegram.ext.updater - ERROR - Error while getting Updates: Conflict: terminated by other getUpdates request; make sure that only one bot instance is running
2023-06-24 21:54:39,458 - telegram.ext.dispatcher - ERROR - No error handlers are registered, logging exception.
Traceback (most recent call last):
  File "C:\Users\USERNAME\AppData\Local\Programs\Python\Python310\lib\site-packages\telegram\ext\updater.py", line 646, in _network_loop_retry
    if not action_cb():
  File "C:\Users\USERNAME\AppData\Local\Programs\Python\Python310\lib\site-packages\telegram\ext\updater.py", line 597, in polling_action_cb
    updates = self.bot.get_updates(
  File "C:\Users\USERNAME\AppData\Local\Programs\Python\Python310\lib\site-packages\telegram\ext\extbot.py", line 222, in get_updates
    updates = super().get_updates(
  File "C:\Users\USERNAME\AppData\Local\Programs\Python\Python310\lib\site-packages\telegram\bot.py", line 130, in decorator
    result = func(*args, **kwargs)
  File "C:\Users\USERNAME\AppData\Local\Programs\Python\Python310\lib\site-packages\telegram\bot.py", line 2861, in get_updates
    self._post(
  File "C:\Users\USERNAME\AppData\Local\Programs\Python\Python310\lib\site-packages\telegram\bot.py", line 295, in _post
    return self.request.post(
  File "C:\Users\USERNAME\AppData\Local\Programs\Python\Python310\lib\site-packages\telegram\utils\request.py", line 356, in post
    result = self._request_wrapper(
  File "C:\Users\USERNAME\AppData\Local\Programs\Python\Python310\lib\site-packages\telegram\utils\request.py", line 283, in _request_wrapper
    raise Conflict(message)
telegram.error.Conflict: Conflict: terminated by other getUpdates request; make sure that only one bot instance is running
2023-06-24 21:54:46,314 - telegram.ext.updater - ERROR - Error while getting Updates: Conflict: terminated by other getUpdates request; make sure that only one bot instance is running
2023-06-24 21:54:46,314 - telegram.ext.dispatcher - ERROR - No error handlers are registered, logging exception.
Traceback (most recent call last):
  File "C:\Users\USERNAME\AppData\Local\Programs\Python\Python310\lib\site-packages\telegram\ext\updater.py", line 646, in _network_loop_retry
    if not action_cb():
  File "C:\Users\USERNAME\AppData\Local\Programs\Python\Python310\lib\site-packages\telegram\ext\updater.py", line 597, in polling_action_cb
    updates = self.bot.get_updates(
  File "C:\Users\USERNAME\AppData\Local\Programs\Python\Python310\lib\site-packages\telegram\ext\extbot.py", line 222, in get_updates
    updates = super().get_updates(
  File "C:\Users\USERNAME\AppData\Local\Programs\Python\Python310\lib\site-packages\telegram\bot.py", line 130, in decorator
    result = func(*args, **kwargs)
  File "C:\Users\USERNAME\AppData\Local\Programs\Python\Python310\lib\site-packages\telegram\bot.py", line 2861, in get_updates
    self._post(
  File "C:\Users\USERNAME\AppData\Local\Programs\Python\Python310\lib\site-packages\telegram\bot.py", line 295, in _post
    return self.request.post(
  File "C:\Users\USERNAME\AppData\Local\Programs\Python\Python310\lib\site-packages\telegram\utils\request.py", line 356, in post
    result = self._request_wrapper(
  File "C:\Users\USERNAME\AppData\Local\Programs\Python\Python310\lib\site-packages\telegram\utils\request.py", line 283, in _request_wrapper
    raise Conflict(message)
telegram.error.Conflict: Conflict: terminated by other getUpdates request; make sure that only one bot instance is running
2023-06-24 21:54:55,065 - telegram.ext.updater - ERROR - Error while getting Updates: Conflict: terminated by other getUpdates request; make sure that only one bot instance is running
2023-06-24 21:54:55,065 - telegram.ext.dispatcher - ERROR - No error handlers are registered, logging exception.
Traceback (most recent call last):
  File "C:\Users\USERNAME\AppData\Local\Programs\Python\Python310\lib\site-packages\telegram\ext\updater.py", line 646, in _network_loop_retry
    if not action_cb():
  File "C:\Users\USERNAME\AppData\Local\Programs\Python\Python310\lib\site-packages\telegram\ext\updater.py", line 597, in polling_action_cb
    updates = self.bot.get_updates(
  File "C:\Users\USERNAME\AppData\Local\Programs\Python\Python310\lib\site-packages\telegram\ext\extbot.py", line 222, in get_updates
    updates = super().get_updates(
  File "C:\Users\USERNAME\AppData\Local\Programs\Python\Python310\lib\site-packages\telegram\bot.py", line 130, in decorator
    result = func(*args, **kwargs)
  File "C:\Users\USERNAME\AppData\Local\Programs\Python\Python310\lib\site-packages\telegram\bot.py", line 2861, in get_updates
    self._post(
  File "C:\Users\USERNAME\AppData\Local\Programs\Python\Python310\lib\site-packages\telegram\bot.py", line 295, in _post
    return self.request.post(
  File "C:\Users\USERNAME\AppData\Local\Programs\Python\Python310\lib\site-packages\telegram\utils\request.py", line 356, in post
    result = self._request_wrapper(
  File "C:\Users\USERNAME\AppData\Local\Programs\Python\Python310\lib\site-packages\telegram\utils\request.py", line 283, in _request_wrapper
    raise Conflict(message)
telegram.error.Conflict: Conflict: terminated by other getUpdates request; make sure that only one bot instance is running
2023-06-24 21:55:01,424 - apscheduler.scheduler - INFO - Scheduler has been shut down
2023-06-24 21:55:03,619 - telegram.ext.updater - ERROR - Error while getting Updates: Conflict: terminated by other getUpdates request; make sure that only one bot instance is running
2023-06-24 21:55:20,131 - apscheduler.scheduler - INFO - Scheduler started
2023-06-24 21:55:24,658 - telegram.ext.updater - ERROR - Error while getting Updates: Conflict: terminated by other getUpdates request; make sure that only one bot instance is running
2023-06-24 21:55:24,659 - telegram.ext.dispatcher - ERROR - No error handlers are registered, logging exception.
Traceback (most recent call last):
  File "C:\Users\USERNAME\AppData\Local\Programs\Python\Python310\lib\site-packages\telegram\ext\updater.py", line 646, in _network_loop_retry
    if not action_cb():
  File "C:\Users\USERNAME\AppData\Local\Programs\Python\Python310\lib\site-packages\telegram\ext\updater.py", line 597, in polling_action_cb
    updates = self.bot.get_updates(
  File "C:\Users\USERNAME\AppData\Local\Programs\Python\Python310\lib\site-packages\telegram\ext\extbot.py", line 222, in get_updates
    updates = super().get_updates(
  File "C:\Users\USERNAME\AppData\Local\Programs\Python\Python310\lib\site-packages\telegram\bot.py", line 130, in decorator
    result = func(*args, **kwargs)
  File "C:\Users\USERNAME\AppData\Local\Programs\Python\Python310\lib\site-packages\telegram\bot.py", line 2861, in get_updates
    self._post(
  File "C:\Users\USERNAME\AppData\Local\Programs\Python\Python310\lib\site-packages\telegram\bot.py", line 295, in _post
    return self.request.post(
  File "C:\Users\USERNAME\AppData\Local\Programs\Python\Python310\lib\site-packages\telegram\utils\request.py", line 356, in post
    result = self._request_wrapper(
  File "C:\Users\USERNAME\AppData\Local\Programs\Python\Python310\lib\site-packages\telegram\utils\request.py", line 283, in _request_wrapper
    raise Conflict(message)
telegram.error.Conflict: Conflict: terminated by other getUpdates request; make sure that only one bot instance is running
2023-06-24 21:55:30,269 - telegram.ext.updater - ERROR - Error while getting Updates: Conflict: terminated by other getUpdates request; make sure that only one bot instance is running
2023-06-24 21:55:30,270 - telegram.ext.dispatcher - ERROR - No error handlers are registered, logging exception.
Traceback (most recent call last):
  File "C:\Users\USERNAME\AppData\Local\Programs\Python\Python310\lib\site-packages\telegram\ext\updater.py", line 646, in _network_loop_retry
    if not action_cb():
  File "C:\Users\USERNAME\AppData\Local\Programs\Python\Python310\lib\site-packages\telegram\ext\updater.py", line 597, in polling_action_cb
    updates = self.bot.get_updates(
  File "C:\Users\USERNAME\AppData\Local\Programs\Python\Python310\lib\site-packages\telegram\ext\extbot.py", line 222, in get_updates
    updates = super().get_updates(
  File "C:\Users\USERNAME\AppData\Local\Programs\Python\Python310\lib\site-packages\telegram\bot.py", line 130, in decorator
    result = func(*args, **kwargs)
  File "C:\Users\USERNAME\AppData\Local\Programs\Python\Python310\lib\site-packages\telegram\bot.py", line 2861, in get_updates
    self._post(
  File "C:\Users\USERNAME\AppData\Local\Programs\Python\Python310\lib\site-packages\telegram\bot.py", line 295, in _post
    return self.request.post(
  File "C:\Users\USERNAME\AppData\Local\Programs\Python\Python310\lib\site-packages\telegram\utils\request.py", line 356, in post
    result = self._request_wrapper(
  File "C:\Users\USERNAME\AppData\Local\Programs\Python\Python310\lib\site-packages\telegram\utils\request.py", line 283, in _request_wrapper
    raise Conflict(message)
telegram.error.Conflict: Conflict: terminated by other getUpdates request; make sure that only one bot instance is running
2023-06-24 21:55:37,148 - telegram.ext.updater - ERROR - Error while getting Updates: Conflict: terminated by other getUpdates request; make sure that only one bot instance is running
2023-06-24 21:55:37,149 - telegram.ext.dispatcher - ERROR - No error handlers are registered, logging exception.
Traceback (most recent call last):
  File "C:\Users\USERNAME\AppData\Local\Programs\Python\Python310\lib\site-packages\telegram\ext\updater.py", line 646, in _network_loop_retry
    if not action_cb():
  File "C:\Users\USERNAME\AppData\Local\Programs\Python\Python310\lib\site-packages\telegram\ext\updater.py", line 597, in polling_action_cb
    updates = self.bot.get_updates(
  File "C:\Users\USERNAME\AppData\Local\Programs\Python\Python310\lib\site-packages\telegram\ext\extbot.py", line 222, in get_updates
    updates = super().get_updates(
  File "C:\Users\USERNAME\AppData\Local\Programs\Python\Python310\lib\site-packages\telegram\bot.py", line 130, in decorator
    result = func(*args, **kwargs)
  File "C:\Users\USERNAME\AppData\Local\Programs\Python\Python310\lib\site-packages\telegram\bot.py", line 2861, in get_updates
    self._post(
  File "C:\Users\USERNAME\AppData\Local\Programs\Python\Python310\lib\site-packages\telegram\bot.py", line 295, in _post
    return self.request.post(
  File "C:\Users\USERNAME\AppData\Local\Programs\Python\Python310\lib\site-packages\telegram\utils\request.py", line 356, in post
    result = self._request_wrapper(
  File "C:\Users\USERNAME\AppData\Local\Programs\Python\Python310\lib\site-packages\telegram\utils\request.py", line 283, in _request_wrapper
    raise Conflict(message)
telegram.error.Conflict: Conflict: terminated by other getUpdates request; make sure that only one bot instance is running
2023-06-24 21:55:42,891 - telegram.ext.updater - ERROR - Error while getting Updates: Conflict: terminated by other getUpdates request; make sure that only one bot instance is running
2023-06-24 21:55:42,891 - telegram.ext.dispatcher - ERROR - No error handlers are registered, logging exception.
Traceback (most recent call last):
  File "C:\Users\USERNAME\AppData\Local\Programs\Python\Python310\lib\site-packages\telegram\ext\updater.py", line 646, in _network_loop_retry
    if not action_cb():
  File "C:\Users\USERNAME\AppData\Local\Programs\Python\Python310\lib\site-packages\telegram\ext\updater.py", line 597, in polling_action_cb
    updates = self.bot.get_updates(
  File "C:\Users\USERNAME\AppData\Local\Programs\Python\Python310\lib\site-packages\telegram\ext\extbot.py", line 222, in get_updates
    updates = super().get_updates(
  File "C:\Users\USERNAME\AppData\Local\Programs\Python\Python310\lib\site-packages\telegram\bot.py", line 130, in decorator
    result = func(*args, **kwargs)
  File "C:\Users\USERNAME\AppData\Local\Programs\Python\Python310\lib\site-packages\telegram\bot.py", line 2861, in get_updates
    self._post(
  File "C:\Users\USERNAME\AppData\Local\Programs\Python\Python310\lib\site-packages\telegram\bot.py", line 295, in _post
    return self.request.post(
  File "C:\Users\USERNAME\AppData\Local\Programs\Python\Python310\lib\site-packages\telegram\utils\request.py", line 356, in post
    result = self._request_wrapper(
  File "C:\Users\USERNAME\AppData\Local\Programs\Python\Python310\lib\site-packages\telegram\utils\request.py", line 283, in _request_wrapper
    raise Conflict(message)
telegram.error.Conflict: Conflict: terminated by other getUpdates request; make sure that only one bot instance is running
2023-06-24 21:55:51,467 - telegram.ext.updater - ERROR - Error while getting Updates: Conflict: terminated by other getUpdates request; make sure that only one bot instance is running
2023-06-24 21:55:51,467 - telegram.ext.dispatcher - ERROR - No error handlers are registered, logging exception.
Traceback (most recent call last):
  File "C:\Users\USERNAME\AppData\Local\Programs\Python\Python310\lib\site-packages\telegram\ext\updater.py", line 646, in _network_loop_retry
    if not action_cb():
  File "C:\Users\USERNAME\AppData\Local\Programs\Python\Python310\lib\site-packages\telegram\ext\updater.py", line 597, in polling_action_cb
    updates = self.bot.get_updates(
  File "C:\Users\USERNAME\AppData\Local\Programs\Python\Python310\lib\site-packages\telegram\ext\extbot.py", line 222, in get_updates
    updates = super().get_updates(
  File "C:\Users\USERNAME\AppData\Local\Programs\Python\Python310\lib\site-packages\telegram\bot.py", line 130, in decorator
    result = func(*args, **kwargs)
  File "C:\Users\USERNAME\AppData\Local\Programs\Python\Python310\lib\site-packages\telegram\bot.py", line 2861, in get_updates
    self._post(
  File "C:\Users\USERNAME\AppData\Local\Programs\Python\Python310\lib\site-packages\telegram\bot.py", line 295, in _post
    return self.request.post(
  File "C:\Users\USERNAME\AppData\Local\Programs\Python\Python310\lib\site-packages\telegram\utils\request.py", line 356, in post
    result = self._request_wrapper(
  File "C:\Users\USERNAME\AppData\Local\Programs\Python\Python310\lib\site-packages\telegram\utils\request.py", line 283, in _request_wrapper
    raise Conflict(message)
telegram.error.Conflict: Conflict: terminated by other getUpdates request; make sure that only one bot instance is running
2023-06-24 21:56:04,231 - telegram.ext.updater - ERROR - Error while getting Updates: Conflict: terminated by other getUpdates request; make sure that only one bot instance is running
2023-06-24 21:56:04,231 - telegram.ext.dispatcher - ERROR - No error handlers are registered, logging exception.
Traceback (most recent call last):
  File "C:\Users\USERNAME\AppData\Local\Programs\Python\Python310\lib\site-packages\telegram\ext\updater.py", line 646, in _network_loop_retry
    if not action_cb():
  File "C:\Users\USERNAME\AppData\Local\Programs\Python\Python310\lib\site-packages\telegram\ext\updater.py", line 597, in polling_action_cb
    updates = self.bot.get_updates(
  File "C:\Users\USERNAME\AppData\Local\Programs\Python\Python310\lib\site-packages\telegram\ext\extbot.py", line 222, in get_updates
    updates = super().get_updates(
  File "C:\Users\USERNAME\AppData\Local\Programs\Python\Python310\lib\site-packages\telegram\bot.py", line 130, in decorator
    result = func(*args, **kwargs)
  File "C:\Users\USERNAME\AppData\Local\Programs\Python\Python310\lib\site-packages\telegram\bot.py", line 2861, in get_updates
    self._post(
  File "C:\Users\USERNAME\AppData\Local\Programs\Python\Python310\lib\site-packages\telegram\bot.py", line 295, in _post
    return self.request.post(
  File "C:\Users\USERNAME\AppData\Local\Programs\Python\Python310\lib\site-packages\telegram\utils\request.py", line 356, in post
    result = self._request_wrapper(
  File "C:\Users\USERNAME\AppData\Local\Programs\Python\Python310\lib\site-packages\telegram\utils\request.py", line 283, in _request_wrapper
    raise Conflict(message)
telegram.error.Conflict: Conflict: terminated by other getUpdates request; make sure that only one bot instance is running
2023-06-24 21:56:23,345 - telegram.ext.updater - ERROR - Error while getting Updates: Conflict: terminated by other getUpdates request; make sure that only one bot instance is running
2023-06-24 21:56:23,345 - telegram.ext.dispatcher - ERROR - No error handlers are registered, logging exception.
Traceback (most recent call last):
  File "C:\Users\USERNAME\AppData\Local\Programs\Python\Python310\lib\site-packages\telegram\ext\updater.py", line 646, in _network_loop_retry
    if not action_cb():
  File "C:\Users\USERNAME\AppData\Local\Programs\Python\Python310\lib\site-packages\telegram\ext\updater.py", line 597, in polling_action_cb
    updates = self.bot.get_updates(
  File "C:\Users\USERNAME\AppData\Local\Programs\Python\Python310\lib\site-packages\telegram\ext\extbot.py", line 222, in get_updates
    updates = super().get_updates(
  File "C:\Users\USERNAME\AppData\Local\Programs\Python\Python310\lib\site-packages\telegram\bot.py", line 130, in decorator
    result = func(*args, **kwargs)
  File "C:\Users\USERNAME\AppData\Local\Programs\Python\Python310\lib\site-packages\telegram\bot.py", line 2861, in get_updates
    self._post(
  File "C:\Users\USERNAME\AppData\Local\Programs\Python\Python310\lib\site-packages\telegram\bot.py", line 295, in _post
    return self.request.post(
  File "C:\Users\USERNAME\AppData\Local\Programs\Python\Python310\lib\site-packages\telegram\utils\request.py", line 356, in post
    result = self._request_wrapper(
  File "C:\Users\USERNAME\AppData\Local\Programs\Python\Python310\lib\site-packages\telegram\utils\request.py", line 283, in _request_wrapper
    raise Conflict(message)
telegram.error.Conflict: Conflict: terminated by other getUpdates request; make sure that only one bot instance is running
2023-06-24 21:56:48,948 - apscheduler.scheduler - INFO - Scheduler started
2023-06-24 21:56:50,190 - werkzeug - INFO - [31m[1mWARNING: This is a development server. Do not use it in a production deployment. Use a production WSGI server instead.[0m
 * Running on all addresses (0.0.0.0)
 * Running on http://127.0.0.1:5000
 * Running on http://192.168.0.231:5000
2023-06-24 21:56:50,190 - werkzeug - INFO - [33mPress CTRL+C to quit[0m
2023-06-24 21:57:01,586 - root - INFO - /in called, chat_id=1250739576 user_id=1250739576
2023-06-24 21:57:01,587 - telegram.ext.dispatcher - ERROR - No error handlers are registered, logging exception.
Traceback (most recent call last):
  File "C:\Users\USERNAME\AppData\Local\Programs\Python\Python310\lib\site-packages\telegram\ext\dispatcher.py", line 555, in process_update
    handler.handle_update(update, self, check, context)
  File "C:\Users\USERNAME\AppData\Local\Programs\Python\Python310\lib\site-packages\telegram\ext\handler.py", line 198, in handle_update
    return self.callback(update, context)
  File "C:\Users\USERNAME\Desktop\AIESEC_CRUSH_BOT\main.py", line 96, in in_command
    BotDatabase.add_user(user.id, user_name)
TypeError: BotDatabase.add_user() missing 1 required positional argument: 'username'
2023-06-24 21:57:07,596 - telegram.ext.dispatcher - ERROR - No error handlers are registered, logging exception.
Traceback (most recent call last):
  File "C:\Users\USERNAME\AppData\Local\Programs\Python\Python310\lib\site-packages\telegram\ext\dispatcher.py", line 555, in process_update
    handler.handle_update(update, self, check, context)
  File "C:\Users\USERNAME\AppData\Local\Programs\Python\Python310\lib\site-packages\telegram\ext\handler.py", line 198, in handle_update
    return self.callback(update, context)
  File "C:\Users\USERNAME\Desktop\AIESEC_CRUSH_BOT\main.py", line 106, in out_command
    BotDatabase.delete_user_from_chat(chat_id, user.id)
TypeError: BotDatabase.delete_user_from_chat() missing 1 required positional argument: 'user_id'
2023-06-24 21:57:10,269 - telegram.ext.updater - ERROR - Error while getting Updates: Conflict: terminated by other getUpdates request; make sure that only one bot instance is running
2023-06-24 21:57:10,270 - telegram.ext.dispatcher - ERROR - No error handlers are registered, logging exception.
Traceback (most recent call last):
  File "C:\Users\USERNAME\AppData\Local\Programs\Python\Python310\lib\site-packages\telegram\ext\updater.py", line 646, in _network_loop_retry
    if not action_cb():
  File "C:\Users\USERNAME\AppData\Local\Programs\Python\Python310\lib\site-packages\telegram\ext\updater.py", line 597, in polling_action_cb
    updates = self.bot.get_updates(
  File "C:\Users\USERNAME\AppData\Local\Programs\Python\Python310\lib\site-packages\telegram\ext\extbot.py", line 222, in get_updates
    updates = super().get_updates(
  File "C:\Users\USERNAME\AppData\Local\Programs\Python\Python310\lib\site-packages\telegram\bot.py", line 130, in decorator
    result = func(*args, **kwargs)
  File "C:\Users\USERNAME\AppData\Local\Programs\Python\Python310\lib\site-packages\telegram\bot.py", line 2861, in get_updates
    self._post(
  File "C:\Users\USERNAME\AppData\Local\Programs\Python\Python310\lib\site-packages\telegram\bot.py", line 295, in _post
    return self.request.post(
  File "C:\Users\USERNAME\AppData\Local\Programs\Python\Python310\lib\site-packages\telegram\utils\request.py", line 356, in post
    result = self._request_wrapper(
  File "C:\Users\USERNAME\AppData\Local\Programs\Python\Python310\lib\site-packages\telegram\utils\request.py", line 283, in _request_wrapper
    raise Conflict(message)
telegram.error.Conflict: Conflict: terminated by other getUpdates request; make sure that only one bot instance is running
2023-06-24 21:57:15,374 - telegram.ext.updater - ERROR - Error while getting Updates: Conflict: terminated by other getUpdates request; make sure that only one bot instance is running
2023-06-24 21:57:15,374 - telegram.ext.dispatcher - ERROR - No error handlers are registered, logging exception.
Traceback (most recent call last):
  File "C:\Users\USERNAME\AppData\Local\Programs\Python\Python310\lib\site-packages\telegram\ext\updater.py", line 646, in _network_loop_retry
    if not action_cb():
  File "C:\Users\USERNAME\AppData\Local\Programs\Python\Python310\lib\site-packages\telegram\ext\updater.py", line 597, in polling_action_cb
    updates = self.bot.get_updates(
  File "C:\Users\USERNAME\AppData\Local\Programs\Python\Python310\lib\site-packages\telegram\ext\extbot.py", line 222, in get_updates
    updates = super().get_updates(
  File "C:\Users\USERNAME\AppData\Local\Programs\Python\Python310\lib\site-packages\telegram\bot.py", line 130, in decorator
    result = func(*args, **kwargs)
  File "C:\Users\USERNAME\AppData\Local\Programs\Python\Python310\lib\site-packages\telegram\bot.py", line 2861, in get_updates
    self._post(
  File "C:\Users\USERNAME\AppData\Local\Programs\Python\Python310\lib\site-packages\telegram\bot.py", line 295, in _post
    return self.request.post(
  File "C:\Users\USERNAME\AppData\Local\Programs\Python\Python310\lib\site-packages\telegram\utils\request.py", line 356, in post
    result = self._request_wrapper(
  File "C:\Users\USERNAME\AppData\Local\Programs\Python\Python310\lib\site-packages\telegram\utils\request.py", line 283, in _request_wrapper
    raise Conflict(message)
telegram.error.Conflict: Conflict: terminated by other getUpdates request; make sure that only one bot instance is running
2023-06-24 21:57:20,987 - telegram.ext.updater - ERROR - Error while getting Updates: Conflict: terminated by other getUpdates request; make sure that only one bot instance is running
2023-06-24 21:57:20,988 - telegram.ext.dispatcher - ERROR - No error handlers are registered, logging exception.
Traceback (most recent call last):
  File "C:\Users\USERNAME\AppData\Local\Programs\Python\Python310\lib\site-packages\telegram\ext\updater.py", line 646, in _network_loop_retry
    if not action_cb():
  File "C:\Users\USERNAME\AppData\Local\Programs\Python\Python310\lib\site-packages\telegram\ext\updater.py", line 597, in polling_action_cb
    updates = self.bot.get_updates(
  File "C:\Users\USERNAME\AppData\Local\Programs\Python\Python310\lib\site-packages\telegram\ext\extbot.py", line 222, in get_updates
    updates = super().get_updates(
  File "C:\Users\USERNAME\AppData\Local\Programs\Python\Python310\lib\site-packages\telegram\bot.py", line 130, in decorator
    result = func(*args, **kwargs)
  File "C:\Users\USERNAME\AppData\Local\Programs\Python\Python310\lib\site-packages\telegram\bot.py", line 2861, in get_updates
    self._post(
  File "C:\Users\USERNAME\AppData\Local\Programs\Python\Python310\lib\site-packages\telegram\bot.py", line 295, in _post
    return self.request.post(
  File "C:\Users\USERNAME\AppData\Local\Programs\Python\Python310\lib\site-packages\telegram\utils\request.py", line 356, in post
    result = self._request_wrapper(
  File "C:\Users\USERNAME\AppData\Local\Programs\Python\Python310\lib\site-packages\telegram\utils\request.py", line 283, in _request_wrapper
    raise Conflict(message)
telegram.error.Conflict: Conflict: terminated by other getUpdates request; make sure that only one bot instance is running
2023-06-24 21:57:27,947 - telegram.ext.updater - ERROR - Error while getting Updates: Conflict: terminated by other getUpdates request; make sure that only one bot instance is running
2023-06-24 21:57:27,947 - telegram.ext.dispatcher - ERROR - No error handlers are registered, logging exception.
Traceback (most recent call last):
  File "C:\Users\USERNAME\AppData\Local\Programs\Python\Python310\lib\site-packages\telegram\ext\updater.py", line 646, in _network_loop_retry
    if not action_cb():
  File "C:\Users\USERNAME\AppData\Local\Programs\Python\Python310\lib\site-packages\telegram\ext\updater.py", line 597, in polling_action_cb
    updates = self.bot.get_updates(
  File "C:\Users\USERNAME\AppData\Local\Programs\Python\Python310\lib\site-packages\telegram\ext\extbot.py", line 222, in get_updates
    updates = super().get_updates(
  File "C:\Users\USERNAME\AppData\Local\Programs\Python\Python310\lib\site-packages\telegram\bot.py", line 130, in decorator
    result = func(*args, **kwargs)
  File "C:\Users\USERNAME\AppData\Local\Programs\Python\Python310\lib\site-packages\telegram\bot.py", line 2861, in get_updates
    self._post(
  File "C:\Users\USERNAME\AppData\Local\Programs\Python\Python310\lib\site-packages\telegram\bot.py", line 295, in _post
    return self.request.post(
  File "C:\Users\USERNAME\AppData\Local\Programs\Python\Python310\lib\site-packages\telegram\utils\request.py", line 356, in post
    result = self._request_wrapper(
  File "C:\Users\USERNAME\AppData\Local\Programs\Python\Python310\lib\site-packages\telegram\utils\request.py", line 283, in _request_wrapper
    raise Conflict(message)
telegram.error.Conflict: Conflict: terminated by other getUpdates request; make sure that only one bot instance is running
2023-06-24 21:57:36,694 - telegram.ext.updater - ERROR - Error while getting Updates: Conflict: terminated by other getUpdates request; make sure that only one bot instance is running
2023-06-24 21:57:36,694 - telegram.ext.dispatcher - ERROR - No error handlers are registered, logging exception.
Traceback (most recent call last):
  File "C:\Users\USERNAME\AppData\Local\Programs\Python\Python310\lib\site-packages\telegram\ext\updater.py", line 646, in _network_loop_retry
    if not action_cb():
  File "C:\Users\USERNAME\AppData\Local\Programs\Python\Python310\lib\site-packages\telegram\ext\updater.py", line 597, in polling_action_cb
    updates = self.bot.get_updates(
  File "C:\Users\USERNAME\AppData\Local\Programs\Python\Python310\lib\site-packages\telegram\ext\extbot.py", line 222, in get_updates
    updates = super().get_updates(
  File "C:\Users\USERNAME\AppData\Local\Programs\Python\Python310\lib\site-packages\telegram\bot.py", line 130, in decorator
    result = func(*args, **kwargs)
  File "C:\Users\USERNAME\AppData\Local\Programs\Python\Python310\lib\site-packages\telegram\bot.py", line 2861, in get_updates
    self._post(
  File "C:\Users\USERNAME\AppData\Local\Programs\Python\Python310\lib\site-packages\telegram\bot.py", line 295, in _post
    return self.request.post(
  File "C:\Users\USERNAME\AppData\Local\Programs\Python\Python310\lib\site-packages\telegram\utils\request.py", line 356, in post
    result = self._request_wrapper(
  File "C:\Users\USERNAME\AppData\Local\Programs\Python\Python310\lib\site-packages\telegram\utils\request.py", line 283, in _request_wrapper
    raise Conflict(message)
telegram.error.Conflict: Conflict: terminated by other getUpdates request; make sure that only one bot instance is running
2023-06-24 21:57:45,243 - telegram.ext.updater - ERROR - Error while getting Updates: Conflict: terminated by other getUpdates request; make sure that only one bot instance is running
2023-06-24 21:57:45,243 - telegram.ext.dispatcher - ERROR - No error handlers are registered, logging exception.
Traceback (most recent call last):
  File "C:\Users\USERNAME\AppData\Local\Programs\Python\Python310\lib\site-packages\telegram\ext\updater.py", line 646, in _network_loop_retry
    if not action_cb():
  File "C:\Users\USERNAME\AppData\Local\Programs\Python\Python310\lib\site-packages\telegram\ext\updater.py", line 597, in polling_action_cb
    updates = self.bot.get_updates(
  File "C:\Users\USERNAME\AppData\Local\Programs\Python\Python310\lib\site-packages\telegram\ext\extbot.py", line 222, in get_updates
    updates = super().get_updates(
  File "C:\Users\USERNAME\AppData\Local\Programs\Python\Python310\lib\site-packages\telegram\bot.py", line 130, in decorator
    result = func(*args, **kwargs)
  File "C:\Users\USERNAME\AppData\Local\Programs\Python\Python310\lib\site-packages\telegram\bot.py", line 2861, in get_updates
    self._post(
  File "C:\Users\USERNAME\AppData\Local\Programs\Python\Python310\lib\site-packages\telegram\bot.py", line 295, in _post
    return self.request.post(
  File "C:\Users\USERNAME\AppData\Local\Programs\Python\Python310\lib\site-packages\telegram\utils\request.py", line 356, in post
    result = self._request_wrapper(
  File "C:\Users\USERNAME\AppData\Local\Programs\Python\Python310\lib\site-packages\telegram\utils\request.py", line 283, in _request_wrapper
    raise Conflict(message)
telegram.error.Conflict: Conflict: terminated by other getUpdates request; make sure that only one bot instance is running
2023-06-24 21:57:58,017 - telegram.ext.updater - ERROR - Error while getting Updates: Conflict: terminated by other getUpdates request; make sure that only one bot instance is running
2023-06-24 21:57:58,017 - telegram.ext.dispatcher - ERROR - No error handlers are registered, logging exception.
Traceback (most recent call last):
  File "C:\Users\USERNAME\AppData\Local\Programs\Python\Python310\lib\site-packages\telegram\ext\updater.py", line 646, in _network_loop_retry
    if not action_cb():
  File "C:\Users\USERNAME\AppData\Local\Programs\Python\Python310\lib\site-packages\telegram\ext\updater.py", line 597, in polling_action_cb
    updates = self.bot.get_updates(
  File "C:\Users\USERNAME\AppData\Local\Programs\Python\Python310\lib\site-packages\telegram\ext\extbot.py", line 222, in get_updates
    updates = super().get_updates(
  File "C:\Users\USERNAME\AppData\Local\Programs\Python\Python310\lib\site-packages\telegram\bot.py", line 130, in decorator
    result = func(*args, **kwargs)
  File "C:\Users\USERNAME\AppData\Local\Programs\Python\Python310\lib\site-packages\telegram\bot.py", line 2861, in get_updates
    self._post(
  File "C:\Users\USERNAME\AppData\Local\Programs\Python\Python310\lib\site-packages\telegram\bot.py", line 295, in _post
    return self.request.post(
  File "C:\Users\USERNAME\AppData\Local\Programs\Python\Python310\lib\site-packages\telegram\utils\request.py", line 356, in post
    result = self._request_wrapper(
  File "C:\Users\USERNAME\AppData\Local\Programs\Python\Python310\lib\site-packages\telegram\utils\request.py", line 283, in _request_wrapper
    raise Conflict(message)
telegram.error.Conflict: Conflict: terminated by other getUpdates request; make sure that only one bot instance is running
2023-06-24 21:58:17,106 - telegram.ext.updater - ERROR - Error while getting Updates: Conflict: terminated by other getUpdates request; make sure that only one bot instance is running
2023-06-24 21:58:17,106 - telegram.ext.dispatcher - ERROR - No error handlers are registered, logging exception.
Traceback (most recent call last):
  File "C:\Users\USERNAME\AppData\Local\Programs\Python\Python310\lib\site-packages\telegram\ext\updater.py", line 646, in _network_loop_retry
    if not action_cb():
  File "C:\Users\USERNAME\AppData\Local\Programs\Python\Python310\lib\site-packages\telegram\ext\updater.py", line 597, in polling_action_cb
    updates = self.bot.get_updates(
  File "C:\Users\USERNAME\AppData\Local\Programs\Python\Python310\lib\site-packages\telegram\ext\extbot.py", line 222, in get_updates
    updates = super().get_updates(
  File "C:\Users\USERNAME\AppData\Local\Programs\Python\Python310\lib\site-packages\telegram\bot.py", line 130, in decorator
    result = func(*args, **kwargs)
  File "C:\Users\USERNAME\AppData\Local\Programs\Python\Python310\lib\site-packages\telegram\bot.py", line 2861, in get_updates
    self._post(
  File "C:\Users\USERNAME\AppData\Local\Programs\Python\Python310\lib\site-packages\telegram\bot.py", line 295, in _post
    return self.request.post(
  File "C:\Users\USERNAME\AppData\Local\Programs\Python\Python310\lib\site-packages\telegram\utils\request.py", line 356, in post
    result = self._request_wrapper(
  File "C:\Users\USERNAME\AppData\Local\Programs\Python\Python310\lib\site-packages\telegram\utils\request.py", line 283, in _request_wrapper
    raise Conflict(message)
telegram.error.Conflict: Conflict: terminated by other getUpdates request; make sure that only one bot instance is running
2023-06-24 21:58:24,329 - apscheduler.scheduler - INFO - Scheduler started
2023-06-24 21:58:38,311 - telegram.ext.updater - ERROR - Error while getting Updates: Conflict: terminated by other getUpdates request; make sure that only one bot instance is running
2023-06-24 21:58:38,312 - telegram.ext.dispatcher - ERROR - No error handlers are registered, logging exception.
Traceback (most recent call last):
  File "C:\Users\USERNAME\AppData\Local\Programs\Python\Python310\lib\site-packages\telegram\ext\updater.py", line 646, in _network_loop_retry
    if not action_cb():
  File "C:\Users\USERNAME\AppData\Local\Programs\Python\Python310\lib\site-packages\telegram\ext\updater.py", line 597, in polling_action_cb
    updates = self.bot.get_updates(
  File "C:\Users\USERNAME\AppData\Local\Programs\Python\Python310\lib\site-packages\telegram\ext\extbot.py", line 222, in get_updates
    updates = super().get_updates(
  File "C:\Users\USERNAME\AppData\Local\Programs\Python\Python310\lib\site-packages\telegram\bot.py", line 130, in decorator
    result = func(*args, **kwargs)
  File "C:\Users\USERNAME\AppData\Local\Programs\Python\Python310\lib\site-packages\telegram\bot.py", line 2861, in get_updates
    self._post(
  File "C:\Users\USERNAME\AppData\Local\Programs\Python\Python310\lib\site-packages\telegram\bot.py", line 295, in _post
    return self.request.post(
  File "C:\Users\USERNAME\AppData\Local\Programs\Python\Python310\lib\site-packages\telegram\utils\request.py", line 356, in post
    result = self._request_wrapper(
  File "C:\Users\USERNAME\AppData\Local\Programs\Python\Python310\lib\site-packages\telegram\utils\request.py", line 283, in _request_wrapper
    raise Conflict(message)
telegram.error.Conflict: Conflict: terminated by other getUpdates request; make sure that only one bot instance is running
2023-06-24 21:58:40,138 - root - INFO - /in called, chat_id=1250739576 user_id=1250739576
2023-06-24 21:58:40,138 - telegram.ext.dispatcher - ERROR - No error handlers are registered, logging exception.
Traceback (most recent call last):
  File "C:\Users\USERNAME\AppData\Local\Programs\Python\Python310\lib\site-packages\telegram\ext\dispatcher.py", line 555, in process_update
    handler.handle_update(update, self, check, context)
  File "C:\Users\USERNAME\AppData\Local\Programs\Python\Python310\lib\site-packages\telegram\ext\handler.py", line 198, in handle_update
    return self.callback(update, context)
  File "C:\Users\USERNAME\Desktop\AIESEC_CRUSH_BOT\main.py", line 95, in in_command
    BotDatabase.add_user(user.id, user_name)
TypeError: BotDatabase.add_user() missing 1 required positional argument: 'username'
2023-06-24 21:58:50,157 - root - INFO - /in called, chat_id=1250739576 user_id=1250739576
2023-06-24 21:58:50,157 - telegram.ext.dispatcher - ERROR - No error handlers are registered, logging exception.
Traceback (most recent call last):
  File "C:\Users\USERNAME\AppData\Local\Programs\Python\Python310\lib\site-packages\telegram\ext\dispatcher.py", line 555, in process_update
    handler.handle_update(update, self, check, context)
  File "C:\Users\USERNAME\AppData\Local\Programs\Python\Python310\lib\site-packages\telegram\ext\handler.py", line 198, in handle_update
    return self.callback(update, context)
  File "C:\Users\USERNAME\Desktop\AIESEC_CRUSH_BOT\main.py", line 95, in in_command
    BotDatabase.add_user(user.id, user_name)
TypeError: BotDatabase.add_user() missing 1 required positional argument: 'username'
2023-06-24 21:59:08,039 - telegram.ext.updater - ERROR - Error while getting Updates: Conflict: terminated by other getUpdates request; make sure that only one bot instance is running
2023-06-24 21:59:08,054 - telegram.ext.dispatcher - ERROR - No error handlers are registered, logging exception.
Traceback (most recent call last):
  File "C:\Users\USERNAME\AppData\Local\Programs\Python\Python310\lib\site-packages\telegram\ext\updater.py", line 646, in _network_loop_retry
    if not action_cb():
  File "C:\Users\USERNAME\AppData\Local\Programs\Python\Python310\lib\site-packages\telegram\ext\updater.py", line 597, in polling_action_cb
    updates = self.bot.get_updates(
  File "C:\Users\USERNAME\AppData\Local\Programs\Python\Python310\lib\site-packages\telegram\ext\extbot.py", line 222, in get_updates
    updates = super().get_updates(
  File "C:\Users\USERNAME\AppData\Local\Programs\Python\Python310\lib\site-packages\telegram\bot.py", line 130, in decorator
    result = func(*args, **kwargs)
  File "C:\Users\USERNAME\AppData\Local\Programs\Python\Python310\lib\site-packages\telegram\bot.py", line 2861, in get_updates
    self._post(
  File "C:\Users\USERNAME\AppData\Local\Programs\Python\Python310\lib\site-packages\telegram\bot.py", line 295, in _post
    return self.request.post(
  File "C:\Users\USERNAME\AppData\Local\Programs\Python\Python310\lib\site-packages\telegram\utils\request.py", line 356, in post
    result = self._request_wrapper(
  File "C:\Users\USERNAME\AppData\Local\Programs\Python\Python310\lib\site-packages\telegram\utils\request.py", line 283, in _request_wrapper
    raise Conflict(message)
telegram.error.Conflict: Conflict: terminated by other getUpdates request; make sure that only one bot instance is running
2023-06-24 21:59:50,611 - telegram.ext.updater - ERROR - Error while getting Updates: Conflict: terminated by other getUpdates request; make sure that only one bot instance is running
2023-06-24 21:59:50,612 - telegram.ext.dispatcher - ERROR - No error handlers are registered, logging exception.
Traceback (most recent call last):
  File "C:\Users\USERNAME\AppData\Local\Programs\Python\Python310\lib\site-packages\telegram\ext\updater.py", line 646, in _network_loop_retry
    if not action_cb():
  File "C:\Users\USERNAME\AppData\Local\Programs\Python\Python310\lib\site-packages\telegram\ext\updater.py", line 597, in polling_action_cb
    updates = self.bot.get_updates(
  File "C:\Users\USERNAME\AppData\Local\Programs\Python\Python310\lib\site-packages\telegram\ext\extbot.py", line 222, in get_updates
    updates = super().get_updates(
  File "C:\Users\USERNAME\AppData\Local\Programs\Python\Python310\lib\site-packages\telegram\bot.py", line 130, in decorator
    result = func(*args, **kwargs)
  File "C:\Users\USERNAME\AppData\Local\Programs\Python\Python310\lib\site-packages\telegram\bot.py", line 2861, in get_updates
    self._post(
  File "C:\Users\USERNAME\AppData\Local\Programs\Python\Python310\lib\site-packages\telegram\bot.py", line 295, in _post
    return self.request.post(
  File "C:\Users\USERNAME\AppData\Local\Programs\Python\Python310\lib\site-packages\telegram\utils\request.py", line 356, in post
    result = self._request_wrapper(
  File "C:\Users\USERNAME\AppData\Local\Programs\Python\Python310\lib\site-packages\telegram\utils\request.py", line 283, in _request_wrapper
    raise Conflict(message)
telegram.error.Conflict: Conflict: terminated by other getUpdates request; make sure that only one bot instance is running
2023-06-24 22:00:24,724 - telegram.ext.updater - ERROR - Error while getting Updates: Conflict: terminated by other getUpdates request; make sure that only one bot instance is running
2023-06-24 22:00:24,724 - telegram.ext.dispatcher - ERROR - No error handlers are registered, logging exception.
Traceback (most recent call last):
  File "C:\Users\USERNAME\AppData\Local\Programs\Python\Python310\lib\site-packages\telegram\ext\updater.py", line 646, in _network_loop_retry
    if not action_cb():
  File "C:\Users\USERNAME\AppData\Local\Programs\Python\Python310\lib\site-packages\telegram\ext\updater.py", line 597, in polling_action_cb
    updates = self.bot.get_updates(
  File "C:\Users\USERNAME\AppData\Local\Programs\Python\Python310\lib\site-packages\telegram\ext\extbot.py", line 222, in get_updates
    updates = super().get_updates(
  File "C:\Users\USERNAME\AppData\Local\Programs\Python\Python310\lib\site-packages\telegram\bot.py", line 130, in decorator
    result = func(*args, **kwargs)
  File "C:\Users\USERNAME\AppData\Local\Programs\Python\Python310\lib\site-packages\telegram\bot.py", line 2861, in get_updates
    self._post(
  File "C:\Users\USERNAME\AppData\Local\Programs\Python\Python310\lib\site-packages\telegram\bot.py", line 295, in _post
    return self.request.post(
  File "C:\Users\USERNAME\AppData\Local\Programs\Python\Python310\lib\site-packages\telegram\utils\request.py", line 356, in post
    result = self._request_wrapper(
  File "C:\Users\USERNAME\AppData\Local\Programs\Python\Python310\lib\site-packages\telegram\utils\request.py", line 283, in _request_wrapper
    raise Conflict(message)
telegram.error.Conflict: Conflict: terminated by other getUpdates request; make sure that only one bot instance is running
2023-06-24 22:00:58,851 - telegram.ext.updater - ERROR - Error while getting Updates: Conflict: terminated by other getUpdates request; make sure that only one bot instance is running
2023-06-24 22:00:58,852 - telegram.ext.dispatcher - ERROR - No error handlers are registered, logging exception.
Traceback (most recent call last):
  File "C:\Users\USERNAME\AppData\Local\Programs\Python\Python310\lib\site-packages\telegram\ext\updater.py", line 646, in _network_loop_retry
    if not action_cb():
  File "C:\Users\USERNAME\AppData\Local\Programs\Python\Python310\lib\site-packages\telegram\ext\updater.py", line 597, in polling_action_cb
    updates = self.bot.get_updates(
  File "C:\Users\USERNAME\AppData\Local\Programs\Python\Python310\lib\site-packages\telegram\ext\extbot.py", line 222, in get_updates
    updates = super().get_updates(
  File "C:\Users\USERNAME\AppData\Local\Programs\Python\Python310\lib\site-packages\telegram\bot.py", line 130, in decorator
    result = func(*args, **kwargs)
  File "C:\Users\USERNAME\AppData\Local\Programs\Python\Python310\lib\site-packages\telegram\bot.py", line 2861, in get_updates
    self._post(
  File "C:\Users\USERNAME\AppData\Local\Programs\Python\Python310\lib\site-packages\telegram\bot.py", line 295, in _post
    return self.request.post(
  File "C:\Users\USERNAME\AppData\Local\Programs\Python\Python310\lib\site-packages\telegram\utils\request.py", line 356, in post
    result = self._request_wrapper(
  File "C:\Users\USERNAME\AppData\Local\Programs\Python\Python310\lib\site-packages\telegram\utils\request.py", line 283, in _request_wrapper
    raise Conflict(message)
telegram.error.Conflict: Conflict: terminated by other getUpdates request; make sure that only one bot instance is running
2023-06-24 22:01:24,397 - root - INFO - /in called, chat_id=1250739576 user_id=1250739576
2023-06-24 22:01:24,397 - telegram.ext.dispatcher - ERROR - No error handlers are registered, logging exception.
Traceback (most recent call last):
  File "C:\Users\USERNAME\AppData\Local\Programs\Python\Python310\lib\site-packages\telegram\ext\dispatcher.py", line 555, in process_update
    handler.handle_update(update, self, check, context)
  File "C:\Users\USERNAME\AppData\Local\Programs\Python\Python310\lib\site-packages\telegram\ext\handler.py", line 198, in handle_update
    return self.callback(update, context)
  File "C:\Users\USERNAME\Desktop\AIESEC_CRUSH_BOT\main.py", line 95, in in_command
    BotDatabase.add_user(user.id, user_name)
TypeError: BotDatabase.add_user() missing 1 required positional argument: 'username'
2023-06-24 22:01:32,966 - telegram.ext.updater - ERROR - Error while getting Updates: Conflict: terminated by other getUpdates request; make sure that only one bot instance is running
2023-06-24 22:01:32,966 - telegram.ext.dispatcher - ERROR - No error handlers are registered, logging exception.
Traceback (most recent call last):
  File "C:\Users\USERNAME\AppData\Local\Programs\Python\Python310\lib\site-packages\telegram\ext\updater.py", line 646, in _network_loop_retry
    if not action_cb():
  File "C:\Users\USERNAME\AppData\Local\Programs\Python\Python310\lib\site-packages\telegram\ext\updater.py", line 597, in polling_action_cb
    updates = self.bot.get_updates(
  File "C:\Users\USERNAME\AppData\Local\Programs\Python\Python310\lib\site-packages\telegram\ext\extbot.py", line 222, in get_updates
    updates = super().get_updates(
  File "C:\Users\USERNAME\AppData\Local\Programs\Python\Python310\lib\site-packages\telegram\bot.py", line 130, in decorator
    result = func(*args, **kwargs)
  File "C:\Users\USERNAME\AppData\Local\Programs\Python\Python310\lib\site-packages\telegram\bot.py", line 2861, in get_updates
    self._post(
  File "C:\Users\USERNAME\AppData\Local\Programs\Python\Python310\lib\site-packages\telegram\bot.py", line 295, in _post
    return self.request.post(
  File "C:\Users\USERNAME\AppData\Local\Programs\Python\Python310\lib\site-packages\telegram\utils\request.py", line 356, in post
    result = self._request_wrapper(
  File "C:\Users\USERNAME\AppData\Local\Programs\Python\Python310\lib\site-packages\telegram\utils\request.py", line 283, in _request_wrapper
    raise Conflict(message)
telegram.error.Conflict: Conflict: terminated by other getUpdates request; make sure that only one bot instance is running
2023-06-24 22:02:07,086 - telegram.ext.updater - ERROR - Error while getting Updates: Conflict: terminated by other getUpdates request; make sure that only one bot instance is running
2023-06-24 22:02:07,087 - telegram.ext.dispatcher - ERROR - No error handlers are registered, logging exception.
Traceback (most recent call last):
  File "C:\Users\USERNAME\AppData\Local\Programs\Python\Python310\lib\site-packages\telegram\ext\updater.py", line 646, in _network_loop_retry
    if not action_cb():
  File "C:\Users\USERNAME\AppData\Local\Programs\Python\Python310\lib\site-packages\telegram\ext\updater.py", line 597, in polling_action_cb
    updates = self.bot.get_updates(
  File "C:\Users\USERNAME\AppData\Local\Programs\Python\Python310\lib\site-packages\telegram\ext\extbot.py", line 222, in get_updates
    updates = super().get_updates(
  File "C:\Users\USERNAME\AppData\Local\Programs\Python\Python310\lib\site-packages\telegram\bot.py", line 130, in decorator
    result = func(*args, **kwargs)
  File "C:\Users\USERNAME\AppData\Local\Programs\Python\Python310\lib\site-packages\telegram\bot.py", line 2861, in get_updates
    self._post(
  File "C:\Users\USERNAME\AppData\Local\Programs\Python\Python310\lib\site-packages\telegram\bot.py", line 295, in _post
    return self.request.post(
  File "C:\Users\USERNAME\AppData\Local\Programs\Python\Python310\lib\site-packages\telegram\utils\request.py", line 356, in post
    result = self._request_wrapper(
  File "C:\Users\USERNAME\AppData\Local\Programs\Python\Python310\lib\site-packages\telegram\utils\request.py", line 283, in _request_wrapper
    raise Conflict(message)
telegram.error.Conflict: Conflict: terminated by other getUpdates request; make sure that only one bot instance is running
2023-06-24 22:02:40,257 - apscheduler.scheduler - INFO - Scheduler started
2023-06-24 22:02:50,699 - root - INFO - /in called, chat_id=1250739576 user_id=1250739576
2023-06-24 22:02:50,700 - telegram.ext.dispatcher - ERROR - No error handlers are registered, logging exception.
Traceback (most recent call last):
  File "C:\Users\USERNAME\AppData\Local\Programs\Python\Python310\lib\site-packages\telegram\ext\dispatcher.py", line 555, in process_update
    handler.handle_update(update, self, check, context)
  File "C:\Users\USERNAME\AppData\Local\Programs\Python\Python310\lib\site-packages\telegram\ext\handler.py", line 198, in handle_update
    return self.callback(update, context)
  File "C:\Users\USERNAME\Desktop\AIESEC_CRUSH_BOT\main.py", line 95, in in_command
    BotDatabase.add_user(user.id, user_name)
TypeError: BotDatabase.add_user() missing 1 required positional argument: 'username'
2023-06-24 22:03:50,856 - root - INFO - /in called, chat_id=-1001719730820 user_id=1250739576
2023-06-24 22:03:50,856 - telegram.ext.dispatcher - ERROR - No error handlers are registered, logging exception.
Traceback (most recent call last):
  File "C:\Users\USERNAME\AppData\Local\Programs\Python\Python310\lib\site-packages\telegram\ext\dispatcher.py", line 555, in process_update
    handler.handle_update(update, self, check, context)
  File "C:\Users\USERNAME\AppData\Local\Programs\Python\Python310\lib\site-packages\telegram\ext\handler.py", line 198, in handle_update
    return self.callback(update, context)
  File "C:\Users\USERNAME\Desktop\AIESEC_CRUSH_BOT\main.py", line 95, in in_command
    BotDatabase.add_user(user.id, user_name)
TypeError: BotDatabase.add_user() missing 1 required positional argument: 'username'
2023-06-24 22:04:07,954 - root - INFO - /in called, chat_id=-1001719730820 user_id=1250739576
2023-06-24 22:04:07,954 - telegram.ext.dispatcher - ERROR - No error handlers are registered, logging exception.
Traceback (most recent call last):
  File "C:\Users\USERNAME\AppData\Local\Programs\Python\Python310\lib\site-packages\telegram\ext\dispatcher.py", line 555, in process_update
    handler.handle_update(update, self, check, context)
  File "C:\Users\USERNAME\AppData\Local\Programs\Python\Python310\lib\site-packages\telegram\ext\handler.py", line 198, in handle_update
    return self.callback(update, context)
  File "C:\Users\USERNAME\Desktop\AIESEC_CRUSH_BOT\main.py", line 95, in in_command
    BotDatabase.add_user(user.id, user_name)
TypeError: BotDatabase.add_user() missing 1 required positional argument: 'username'
2023-06-24 22:04:32,070 - telegram.ext.dispatcher - ERROR - No error handlers are registered, logging exception.
Traceback (most recent call last):
  File "C:\Users\USERNAME\AppData\Local\Programs\Python\Python310\lib\site-packages\telegram\ext\dispatcher.py", line 555, in process_update
    handler.handle_update(update, self, check, context)
  File "C:\Users\USERNAME\AppData\Local\Programs\Python\Python310\lib\site-packages\telegram\ext\handler.py", line 198, in handle_update
    return self.callback(update, context)
  File "C:\Users\USERNAME\Desktop\AIESEC_CRUSH_BOT\main.py", line 105, in out_command
    BotDatabase.delete_user_from_chat(chat_id, user.id)
TypeError: BotDatabase.delete_user_from_chat() missing 1 required positional argument: 'user_id'
2023-06-24 22:58:26,724 - apscheduler.scheduler - INFO - Scheduler started
2023-06-24 22:58:30,807 - werkzeug - INFO - [31m[1mWARNING: This is a development server. Do not use it in a production deployment. Use a production WSGI server instead.[0m
 * Running on all addresses (0.0.0.0)
 * Running on http://127.0.0.1:5000
 * Running on http://192.168.0.231:5000
2023-06-24 22:58:30,808 - werkzeug - INFO - [33mPress CTRL+C to quit[0m
2023-06-24 22:59:20,575 - root - INFO - /in called, chat_id=1250739576 user_id=1250739576
2023-06-24 22:59:20,576 - telegram.ext.dispatcher - ERROR - No error handlers are registered, logging exception.
Traceback (most recent call last):
  File "C:\Users\USERNAME\AppData\Local\Programs\Python\Python310\lib\site-packages\telegram\ext\dispatcher.py", line 555, in process_update
    handler.handle_update(update, self, check, context)
  File "C:\Users\USERNAME\AppData\Local\Programs\Python\Python310\lib\site-packages\telegram\ext\handler.py", line 198, in handle_update
    return self.callback(update, context)
  File "C:\Users\USERNAME\Desktop\AIESEC_CRUSH_BOT\main.py", line 96, in in_command
    BotDatabase.add_user(user.id, user_name)
TypeError: BotDatabase.add_user() missing 1 required positional argument: 'username'
2023-06-24 22:59:27,038 - apscheduler.scheduler - INFO - Scheduler has been shut down
2023-06-25 14:02:53,641 - werkzeug - INFO - [31m[1mWARNING: This is a development server. Do not use it in a production deployment. Use a production WSGI server instead.[0m
 * Running on all addresses (0.0.0.0)
 * Running on http://127.0.0.1:5000
 * Running on http://192.168.0.231:5000
2023-06-25 14:02:53,641 - werkzeug - INFO - [33mPress CTRL+C to quit[0m
