2023-06-21 20:43:46,270 - apscheduler.scheduler - INFO - Scheduler started
2023-06-21 20:44:11,223 - apscheduler.scheduler - INFO - Scheduler started
2023-06-21 21:04:21,082 - root - INFO - /in called, chat_id=1250739576 user_id=1250739576
2023-06-21 21:11:14,941 - root - INFO - /all called, chat_id=-1001719730820 user_count=2
2023-06-21 21:32:46,431 - apscheduler.scheduler - INFO - Scheduler started
2023-06-21 21:32:47,592 - root - INFO - /all called, chat_id=-1001719730820 user_count=2
2023-06-21 21:32:55,005 - root - INFO - /all called, chat_id=-1001719730820 user_count=2
2023-06-21 22:18:23,788 - apscheduler.scheduler - INFO - Scheduler started
2023-06-21 22:20:14,693 - apscheduler.scheduler - INFO - Scheduler started
2023-06-21 22:29:35,163 - apscheduler.scheduler - INFO - Scheduler started
2023-06-21 22:36:34,315 - apscheduler.scheduler - INFO - Scheduler started
2023-06-21 23:35:04,861 - apscheduler.scheduler - INFO - Scheduler started
2023-06-21 23:35:06,599 - werkzeug - INFO - [31m[1mWARNING: This is a development server. Do not use it in a production deployment. Use a production WSGI server instead.[0m
 * Running on all addresses (0.0.0.0)
 * Running on http://127.0.0.1:5000
 * Running on http://192.168.0.231:5000
2023-06-21 23:35:06,599 - werkzeug - INFO - [33mPress CTRL+C to quit[0m
2023-06-21 23:35:06,608 - werkzeug - INFO -  * Restarting with stat
2023-06-21 23:35:08,197 - apscheduler.scheduler - INFO - Scheduler started
2023-06-21 23:35:08,626 - werkzeug - WARNING -  * Debugger is active!
2023-06-21 23:35:08,636 - werkzeug - INFO -  * Debugger PIN: 106-333-038
2023-06-21 23:35:08,716 - telegram.ext.updater - ERROR - Error while getting Updates: Conflict: terminated by other getUpdates request; make sure that only one bot instance is running
2023-06-21 23:35:08,716 - telegram.ext.dispatcher - ERROR - No error handlers are registered, logging exception.
Traceback (most recent call last):
  File "C:\Users\USERNAME\AppData\Local\Programs\Python\Python310\lib\site-packages\telegram\ext\updater.py", line 646, in _network_loop_retry
    if not action_cb():
  File "C:\Users\USERNAME\AppData\Local\Programs\Python\Python310\lib\site-packages\telegram\ext\updater.py", line 597, in polling_action_cb
    updates = self.bot.get_updates(
  File "C:\Users\USERNAME\AppData\Local\Programs\Python\Python310\lib\site-packages\telegram\ext\extbot.py", line 222, in get_updates
    updates = super().get_updates(
  File "C:\Users\USERNAME\AppData\Local\Programs\Python\Python310\lib\site-packages\telegram\bot.py", line 130, in decorator
    result = func(*args, **kwargs)
  File "C:\Users\USERNAME\AppData\Local\Programs\Python\Python310\lib\site-packages\telegram\bot.py", line 2861, in get_updates
    self._post(
  File "C:\Users\USERNAME\AppData\Local\Programs\Python\Python310\lib\site-packages\telegram\bot.py", line 295, in _post
    return self.request.post(
  File "C:\Users\USERNAME\AppData\Local\Programs\Python\Python310\lib\site-packages\telegram\utils\request.py", line 356, in post
    result = self._request_wrapper(
  File "C:\Users\USERNAME\AppData\Local\Programs\Python\Python310\lib\site-packages\telegram\utils\request.py", line 283, in _request_wrapper
    raise Conflict(message)
telegram.error.Conflict: Conflict: terminated by other getUpdates request; make sure that only one bot instance is running
2023-06-21 23:35:12,825 - telegram.ext.updater - ERROR - Error while getting Updates: Conflict: terminated by other getUpdates request; make sure that only one bot instance is running
2023-06-21 23:35:12,825 - telegram.ext.dispatcher - ERROR - No error handlers are registered, logging exception.
Traceback (most recent call last):
  File "C:\Users\USERNAME\AppData\Local\Programs\Python\Python310\lib\site-packages\telegram\ext\updater.py", line 646, in _network_loop_retry
    if not action_cb():
  File "C:\Users\USERNAME\AppData\Local\Programs\Python\Python310\lib\site-packages\telegram\ext\updater.py", line 597, in polling_action_cb
    updates = self.bot.get_updates(
  File "C:\Users\USERNAME\AppData\Local\Programs\Python\Python310\lib\site-packages\telegram\ext\extbot.py", line 222, in get_updates
    updates = super().get_updates(
  File "C:\Users\USERNAME\AppData\Local\Programs\Python\Python310\lib\site-packages\telegram\bot.py", line 130, in decorator
    result = func(*args, **kwargs)
  File "C:\Users\USERNAME\AppData\Local\Programs\Python\Python310\lib\site-packages\telegram\bot.py", line 2861, in get_updates
    self._post(
  File "C:\Users\USERNAME\AppData\Local\Programs\Python\Python310\lib\site-packages\telegram\bot.py", line 295, in _post
    return self.request.post(
  File "C:\Users\USERNAME\AppData\Local\Programs\Python\Python310\lib\site-packages\telegram\utils\request.py", line 356, in post
    result = self._request_wrapper(
  File "C:\Users\USERNAME\AppData\Local\Programs\Python\Python310\lib\site-packages\telegram\utils\request.py", line 283, in _request_wrapper
    raise Conflict(message)
telegram.error.Conflict: Conflict: terminated by other getUpdates request; make sure that only one bot instance is running
2023-06-21 23:35:13,927 - telegram.ext.updater - ERROR - Error while getting Updates: Conflict: terminated by other getUpdates request; make sure that only one bot instance is running
2023-06-21 23:35:13,927 - telegram.ext.dispatcher - ERROR - No error handlers are registered, logging exception.
Traceback (most recent call last):
  File "C:\Users\USERNAME\AppData\Local\Programs\Python\Python310\lib\site-packages\telegram\ext\updater.py", line 646, in _network_loop_retry
    if not action_cb():
  File "C:\Users\USERNAME\AppData\Local\Programs\Python\Python310\lib\site-packages\telegram\ext\updater.py", line 597, in polling_action_cb
    updates = self.bot.get_updates(
  File "C:\Users\USERNAME\AppData\Local\Programs\Python\Python310\lib\site-packages\telegram\ext\extbot.py", line 222, in get_updates
    updates = super().get_updates(
  File "C:\Users\USERNAME\AppData\Local\Programs\Python\Python310\lib\site-packages\telegram\bot.py", line 130, in decorator
    result = func(*args, **kwargs)
  File "C:\Users\USERNAME\AppData\Local\Programs\Python\Python310\lib\site-packages\telegram\bot.py", line 2861, in get_updates
    self._post(
  File "C:\Users\USERNAME\AppData\Local\Programs\Python\Python310\lib\site-packages\telegram\bot.py", line 295, in _post
    return self.request.post(
  File "C:\Users\USERNAME\AppData\Local\Programs\Python\Python310\lib\site-packages\telegram\utils\request.py", line 356, in post
    result = self._request_wrapper(
  File "C:\Users\USERNAME\AppData\Local\Programs\Python\Python310\lib\site-packages\telegram\utils\request.py", line 283, in _request_wrapper
    raise Conflict(message)
telegram.error.Conflict: Conflict: terminated by other getUpdates request; make sure that only one bot instance is running
2023-06-21 23:35:18,525 - telegram.ext.updater - ERROR - Error while getting Updates: Conflict: terminated by other getUpdates request; make sure that only one bot instance is running
2023-06-21 23:35:18,525 - telegram.ext.dispatcher - ERROR - No error handlers are registered, logging exception.
Traceback (most recent call last):
  File "C:\Users\USERNAME\AppData\Local\Programs\Python\Python310\lib\site-packages\telegram\ext\updater.py", line 646, in _network_loop_retry
    if not action_cb():
  File "C:\Users\USERNAME\AppData\Local\Programs\Python\Python310\lib\site-packages\telegram\ext\updater.py", line 597, in polling_action_cb
    updates = self.bot.get_updates(
  File "C:\Users\USERNAME\AppData\Local\Programs\Python\Python310\lib\site-packages\telegram\ext\extbot.py", line 222, in get_updates
    updates = super().get_updates(
  File "C:\Users\USERNAME\AppData\Local\Programs\Python\Python310\lib\site-packages\telegram\bot.py", line 130, in decorator
    result = func(*args, **kwargs)
  File "C:\Users\USERNAME\AppData\Local\Programs\Python\Python310\lib\site-packages\telegram\bot.py", line 2861, in get_updates
    self._post(
  File "C:\Users\USERNAME\AppData\Local\Programs\Python\Python310\lib\site-packages\telegram\bot.py", line 295, in _post
    return self.request.post(
  File "C:\Users\USERNAME\AppData\Local\Programs\Python\Python310\lib\site-packages\telegram\utils\request.py", line 356, in post
    result = self._request_wrapper(
  File "C:\Users\USERNAME\AppData\Local\Programs\Python\Python310\lib\site-packages\telegram\utils\request.py", line 283, in _request_wrapper
    raise Conflict(message)
telegram.error.Conflict: Conflict: terminated by other getUpdates request; make sure that only one bot instance is running
2023-06-21 23:35:19,636 - telegram.ext.updater - ERROR - Error while getting Updates: Conflict: terminated by other getUpdates request; make sure that only one bot instance is running
2023-06-21 23:35:19,636 - telegram.ext.dispatcher - ERROR - No error handlers are registered, logging exception.
Traceback (most recent call last):
  File "C:\Users\USERNAME\AppData\Local\Programs\Python\Python310\lib\site-packages\telegram\ext\updater.py", line 646, in _network_loop_retry
    if not action_cb():
  File "C:\Users\USERNAME\AppData\Local\Programs\Python\Python310\lib\site-packages\telegram\ext\updater.py", line 597, in polling_action_cb
    updates = self.bot.get_updates(
  File "C:\Users\USERNAME\AppData\Local\Programs\Python\Python310\lib\site-packages\telegram\ext\extbot.py", line 222, in get_updates
    updates = super().get_updates(
  File "C:\Users\USERNAME\AppData\Local\Programs\Python\Python310\lib\site-packages\telegram\bot.py", line 130, in decorator
    result = func(*args, **kwargs)
  File "C:\Users\USERNAME\AppData\Local\Programs\Python\Python310\lib\site-packages\telegram\bot.py", line 2861, in get_updates
    self._post(
  File "C:\Users\USERNAME\AppData\Local\Programs\Python\Python310\lib\site-packages\telegram\bot.py", line 295, in _post
    return self.request.post(
  File "C:\Users\USERNAME\AppData\Local\Programs\Python\Python310\lib\site-packages\telegram\utils\request.py", line 356, in post
    result = self._request_wrapper(
  File "C:\Users\USERNAME\AppData\Local\Programs\Python\Python310\lib\site-packages\telegram\utils\request.py", line 283, in _request_wrapper
    raise Conflict(message)
telegram.error.Conflict: Conflict: terminated by other getUpdates request; make sure that only one bot instance is running
2023-06-21 23:35:24,994 - telegram.ext.updater - ERROR - Error while getting Updates: Conflict: terminated by other getUpdates request; make sure that only one bot instance is running
2023-06-21 23:35:24,995 - telegram.ext.dispatcher - ERROR - No error handlers are registered, logging exception.
Traceback (most recent call last):
  File "C:\Users\USERNAME\AppData\Local\Programs\Python\Python310\lib\site-packages\telegram\ext\updater.py", line 646, in _network_loop_retry
    if not action_cb():
  File "C:\Users\USERNAME\AppData\Local\Programs\Python\Python310\lib\site-packages\telegram\ext\updater.py", line 597, in polling_action_cb
    updates = self.bot.get_updates(
  File "C:\Users\USERNAME\AppData\Local\Programs\Python\Python310\lib\site-packages\telegram\ext\extbot.py", line 222, in get_updates
    updates = super().get_updates(
  File "C:\Users\USERNAME\AppData\Local\Programs\Python\Python310\lib\site-packages\telegram\bot.py", line 130, in decorator
    result = func(*args, **kwargs)
  File "C:\Users\USERNAME\AppData\Local\Programs\Python\Python310\lib\site-packages\telegram\bot.py", line 2861, in get_updates
    self._post(
  File "C:\Users\USERNAME\AppData\Local\Programs\Python\Python310\lib\site-packages\telegram\bot.py", line 295, in _post
    return self.request.post(
  File "C:\Users\USERNAME\AppData\Local\Programs\Python\Python310\lib\site-packages\telegram\utils\request.py", line 356, in post
    result = self._request_wrapper(
  File "C:\Users\USERNAME\AppData\Local\Programs\Python\Python310\lib\site-packages\telegram\utils\request.py", line 283, in _request_wrapper
    raise Conflict(message)
telegram.error.Conflict: Conflict: terminated by other getUpdates request; make sure that only one bot instance is running
2023-06-21 23:35:26,095 - telegram.ext.updater - ERROR - Error while getting Updates: Conflict: terminated by other getUpdates request; make sure that only one bot instance is running
2023-06-21 23:35:26,096 - telegram.ext.dispatcher - ERROR - No error handlers are registered, logging exception.
Traceback (most recent call last):
  File "C:\Users\USERNAME\AppData\Local\Programs\Python\Python310\lib\site-packages\telegram\ext\updater.py", line 646, in _network_loop_retry
    if not action_cb():
  File "C:\Users\USERNAME\AppData\Local\Programs\Python\Python310\lib\site-packages\telegram\ext\updater.py", line 597, in polling_action_cb
    updates = self.bot.get_updates(
  File "C:\Users\USERNAME\AppData\Local\Programs\Python\Python310\lib\site-packages\telegram\ext\extbot.py", line 222, in get_updates
    updates = super().get_updates(
  File "C:\Users\USERNAME\AppData\Local\Programs\Python\Python310\lib\site-packages\telegram\bot.py", line 130, in decorator
    result = func(*args, **kwargs)
  File "C:\Users\USERNAME\AppData\Local\Programs\Python\Python310\lib\site-packages\telegram\bot.py", line 2861, in get_updates
    self._post(
  File "C:\Users\USERNAME\AppData\Local\Programs\Python\Python310\lib\site-packages\telegram\bot.py", line 295, in _post
    return self.request.post(
  File "C:\Users\USERNAME\AppData\Local\Programs\Python\Python310\lib\site-packages\telegram\utils\request.py", line 356, in post
    result = self._request_wrapper(
  File "C:\Users\USERNAME\AppData\Local\Programs\Python\Python310\lib\site-packages\telegram\utils\request.py", line 283, in _request_wrapper
    raise Conflict(message)
telegram.error.Conflict: Conflict: terminated by other getUpdates request; make sure that only one bot instance is running
2023-06-21 23:35:26,780 - telegram.ext.dispatcher - ERROR - No error handlers are registered, logging exception.
Traceback (most recent call last):
  File "C:\Users\USERNAME\AppData\Local\Programs\Python\Python310\lib\site-packages\telegram\ext\dispatcher.py", line 555, in process_update
    handler.handle_update(update, self, check, context)
  File "C:\Users\USERNAME\AppData\Local\Programs\Python\Python310\lib\site-packages\telegram\ext\handler.py", line 198, in handle_update
    return self.callback(update, context)
  File "C:\Users\USERNAME\Desktop\AIESEC_CRUSH_BOT\main2.py", line 64, in random_gif
    gif_files = os.listdir(GIFS_DIR)
FileNotFoundError: [WinError 3] Системе не удается найти указанный путь: 'gifs'
2023-06-21 23:35:29,574 - telegram.ext.updater - ERROR - Error while getting Updates: Conflict: terminated by other getUpdates request; make sure that only one bot instance is running
2023-06-21 23:35:29,574 - telegram.ext.dispatcher - ERROR - No error handlers are registered, logging exception.
Traceback (most recent call last):
  File "C:\Users\USERNAME\AppData\Local\Programs\Python\Python310\lib\site-packages\telegram\ext\updater.py", line 646, in _network_loop_retry
    if not action_cb():
  File "C:\Users\USERNAME\AppData\Local\Programs\Python\Python310\lib\site-packages\telegram\ext\updater.py", line 597, in polling_action_cb
    updates = self.bot.get_updates(
  File "C:\Users\USERNAME\AppData\Local\Programs\Python\Python310\lib\site-packages\telegram\ext\extbot.py", line 222, in get_updates
    updates = super().get_updates(
  File "C:\Users\USERNAME\AppData\Local\Programs\Python\Python310\lib\site-packages\telegram\bot.py", line 130, in decorator
    result = func(*args, **kwargs)
  File "C:\Users\USERNAME\AppData\Local\Programs\Python\Python310\lib\site-packages\telegram\bot.py", line 2861, in get_updates
    self._post(
  File "C:\Users\USERNAME\AppData\Local\Programs\Python\Python310\lib\site-packages\telegram\bot.py", line 295, in _post
    return self.request.post(
  File "C:\Users\USERNAME\AppData\Local\Programs\Python\Python310\lib\site-packages\telegram\utils\request.py", line 356, in post
    result = self._request_wrapper(
  File "C:\Users\USERNAME\AppData\Local\Programs\Python\Python310\lib\site-packages\telegram\utils\request.py", line 283, in _request_wrapper
    raise Conflict(message)
telegram.error.Conflict: Conflict: terminated by other getUpdates request; make sure that only one bot instance is running
2023-06-21 23:35:33,687 - telegram.ext.updater - ERROR - Error while getting Updates: Conflict: terminated by other getUpdates request; make sure that only one bot instance is running
2023-06-21 23:35:33,688 - telegram.ext.dispatcher - ERROR - No error handlers are registered, logging exception.
Traceback (most recent call last):
  File "C:\Users\USERNAME\AppData\Local\Programs\Python\Python310\lib\site-packages\telegram\ext\updater.py", line 646, in _network_loop_retry
    if not action_cb():
  File "C:\Users\USERNAME\AppData\Local\Programs\Python\Python310\lib\site-packages\telegram\ext\updater.py", line 597, in polling_action_cb
    updates = self.bot.get_updates(
  File "C:\Users\USERNAME\AppData\Local\Programs\Python\Python310\lib\site-packages\telegram\ext\extbot.py", line 222, in get_updates
    updates = super().get_updates(
  File "C:\Users\USERNAME\AppData\Local\Programs\Python\Python310\lib\site-packages\telegram\bot.py", line 130, in decorator
    result = func(*args, **kwargs)
  File "C:\Users\USERNAME\AppData\Local\Programs\Python\Python310\lib\site-packages\telegram\bot.py", line 2861, in get_updates
    self._post(
  File "C:\Users\USERNAME\AppData\Local\Programs\Python\Python310\lib\site-packages\telegram\bot.py", line 295, in _post
    return self.request.post(
  File "C:\Users\USERNAME\AppData\Local\Programs\Python\Python310\lib\site-packages\telegram\utils\request.py", line 356, in post
    result = self._request_wrapper(
  File "C:\Users\USERNAME\AppData\Local\Programs\Python\Python310\lib\site-packages\telegram\utils\request.py", line 283, in _request_wrapper
    raise Conflict(message)
telegram.error.Conflict: Conflict: terminated by other getUpdates request; make sure that only one bot instance is running
2023-06-21 23:35:38,848 - telegram.ext.updater - ERROR - Error while getting Updates: Conflict: terminated by other getUpdates request; make sure that only one bot instance is running
2023-06-21 23:35:38,848 - telegram.ext.dispatcher - ERROR - No error handlers are registered, logging exception.
Traceback (most recent call last):
  File "C:\Users\USERNAME\AppData\Local\Programs\Python\Python310\lib\site-packages\telegram\ext\updater.py", line 646, in _network_loop_retry
    if not action_cb():
  File "C:\Users\USERNAME\AppData\Local\Programs\Python\Python310\lib\site-packages\telegram\ext\updater.py", line 597, in polling_action_cb
    updates = self.bot.get_updates(
  File "C:\Users\USERNAME\AppData\Local\Programs\Python\Python310\lib\site-packages\telegram\ext\extbot.py", line 222, in get_updates
    updates = super().get_updates(
  File "C:\Users\USERNAME\AppData\Local\Programs\Python\Python310\lib\site-packages\telegram\bot.py", line 130, in decorator
    result = func(*args, **kwargs)
  File "C:\Users\USERNAME\AppData\Local\Programs\Python\Python310\lib\site-packages\telegram\bot.py", line 2861, in get_updates
    self._post(
  File "C:\Users\USERNAME\AppData\Local\Programs\Python\Python310\lib\site-packages\telegram\bot.py", line 295, in _post
    return self.request.post(
  File "C:\Users\USERNAME\AppData\Local\Programs\Python\Python310\lib\site-packages\telegram\utils\request.py", line 356, in post
    result = self._request_wrapper(
  File "C:\Users\USERNAME\AppData\Local\Programs\Python\Python310\lib\site-packages\telegram\utils\request.py", line 283, in _request_wrapper
    raise Conflict(message)
telegram.error.Conflict: Conflict: terminated by other getUpdates request; make sure that only one bot instance is running
2023-06-21 23:35:43,460 - telegram.ext.updater - ERROR - Error while getting Updates: Conflict: terminated by other getUpdates request; make sure that only one bot instance is running
2023-06-21 23:35:43,460 - telegram.ext.dispatcher - ERROR - No error handlers are registered, logging exception.
Traceback (most recent call last):
  File "C:\Users\USERNAME\AppData\Local\Programs\Python\Python310\lib\site-packages\telegram\ext\updater.py", line 646, in _network_loop_retry
    if not action_cb():
  File "C:\Users\USERNAME\AppData\Local\Programs\Python\Python310\lib\site-packages\telegram\ext\updater.py", line 597, in polling_action_cb
    updates = self.bot.get_updates(
  File "C:\Users\USERNAME\AppData\Local\Programs\Python\Python310\lib\site-packages\telegram\ext\extbot.py", line 222, in get_updates
    updates = super().get_updates(
  File "C:\Users\USERNAME\AppData\Local\Programs\Python\Python310\lib\site-packages\telegram\bot.py", line 130, in decorator
    result = func(*args, **kwargs)
  File "C:\Users\USERNAME\AppData\Local\Programs\Python\Python310\lib\site-packages\telegram\bot.py", line 2861, in get_updates
    self._post(
  File "C:\Users\USERNAME\AppData\Local\Programs\Python\Python310\lib\site-packages\telegram\bot.py", line 295, in _post
    return self.request.post(
  File "C:\Users\USERNAME\AppData\Local\Programs\Python\Python310\lib\site-packages\telegram\utils\request.py", line 356, in post
    result = self._request_wrapper(
  File "C:\Users\USERNAME\AppData\Local\Programs\Python\Python310\lib\site-packages\telegram\utils\request.py", line 283, in _request_wrapper
    raise Conflict(message)
telegram.error.Conflict: Conflict: terminated by other getUpdates request; make sure that only one bot instance is running
2023-06-21 23:35:51,156 - telegram.ext.updater - ERROR - Error while getting Updates: Conflict: terminated by other getUpdates request; make sure that only one bot instance is running
2023-06-21 23:35:51,156 - telegram.ext.dispatcher - ERROR - No error handlers are registered, logging exception.
Traceback (most recent call last):
  File "C:\Users\USERNAME\AppData\Local\Programs\Python\Python310\lib\site-packages\telegram\ext\updater.py", line 646, in _network_loop_retry
    if not action_cb():
  File "C:\Users\USERNAME\AppData\Local\Programs\Python\Python310\lib\site-packages\telegram\ext\updater.py", line 597, in polling_action_cb
    updates = self.bot.get_updates(
  File "C:\Users\USERNAME\AppData\Local\Programs\Python\Python310\lib\site-packages\telegram\ext\extbot.py", line 222, in get_updates
    updates = super().get_updates(
  File "C:\Users\USERNAME\AppData\Local\Programs\Python\Python310\lib\site-packages\telegram\bot.py", line 130, in decorator
    result = func(*args, **kwargs)
  File "C:\Users\USERNAME\AppData\Local\Programs\Python\Python310\lib\site-packages\telegram\bot.py", line 2861, in get_updates
    self._post(
  File "C:\Users\USERNAME\AppData\Local\Programs\Python\Python310\lib\site-packages\telegram\bot.py", line 295, in _post
    return self.request.post(
  File "C:\Users\USERNAME\AppData\Local\Programs\Python\Python310\lib\site-packages\telegram\utils\request.py", line 356, in post
    result = self._request_wrapper(
  File "C:\Users\USERNAME\AppData\Local\Programs\Python\Python310\lib\site-packages\telegram\utils\request.py", line 283, in _request_wrapper
    raise Conflict(message)
telegram.error.Conflict: Conflict: terminated by other getUpdates request; make sure that only one bot instance is running
2023-06-21 23:35:55,252 - telegram.ext.updater - ERROR - Error while getting Updates: Conflict: terminated by other getUpdates request; make sure that only one bot instance is running
2023-06-21 23:35:55,252 - telegram.ext.dispatcher - ERROR - No error handlers are registered, logging exception.
Traceback (most recent call last):
  File "C:\Users\USERNAME\AppData\Local\Programs\Python\Python310\lib\site-packages\telegram\ext\updater.py", line 646, in _network_loop_retry
    if not action_cb():
  File "C:\Users\USERNAME\AppData\Local\Programs\Python\Python310\lib\site-packages\telegram\ext\updater.py", line 597, in polling_action_cb
    updates = self.bot.get_updates(
  File "C:\Users\USERNAME\AppData\Local\Programs\Python\Python310\lib\site-packages\telegram\ext\extbot.py", line 222, in get_updates
    updates = super().get_updates(
  File "C:\Users\USERNAME\AppData\Local\Programs\Python\Python310\lib\site-packages\telegram\bot.py", line 130, in decorator
    result = func(*args, **kwargs)
  File "C:\Users\USERNAME\AppData\Local\Programs\Python\Python310\lib\site-packages\telegram\bot.py", line 2861, in get_updates
    self._post(
  File "C:\Users\USERNAME\AppData\Local\Programs\Python\Python310\lib\site-packages\telegram\bot.py", line 295, in _post
    return self.request.post(
  File "C:\Users\USERNAME\AppData\Local\Programs\Python\Python310\lib\site-packages\telegram\utils\request.py", line 356, in post
    result = self._request_wrapper(
  File "C:\Users\USERNAME\AppData\Local\Programs\Python\Python310\lib\site-packages\telegram\utils\request.py", line 283, in _request_wrapper
    raise Conflict(message)
telegram.error.Conflict: Conflict: terminated by other getUpdates request; make sure that only one bot instance is running
2023-06-21 23:36:06,743 - telegram.ext.updater - ERROR - Error while getting Updates: Conflict: terminated by other getUpdates request; make sure that only one bot instance is running
2023-06-21 23:36:06,743 - telegram.ext.dispatcher - ERROR - No error handlers are registered, logging exception.
Traceback (most recent call last):
  File "C:\Users\USERNAME\AppData\Local\Programs\Python\Python310\lib\site-packages\telegram\ext\updater.py", line 646, in _network_loop_retry
    if not action_cb():
  File "C:\Users\USERNAME\AppData\Local\Programs\Python\Python310\lib\site-packages\telegram\ext\updater.py", line 597, in polling_action_cb
    updates = self.bot.get_updates(
  File "C:\Users\USERNAME\AppData\Local\Programs\Python\Python310\lib\site-packages\telegram\ext\extbot.py", line 222, in get_updates
    updates = super().get_updates(
  File "C:\Users\USERNAME\AppData\Local\Programs\Python\Python310\lib\site-packages\telegram\bot.py", line 130, in decorator
    result = func(*args, **kwargs)
  File "C:\Users\USERNAME\AppData\Local\Programs\Python\Python310\lib\site-packages\telegram\bot.py", line 2861, in get_updates
    self._post(
  File "C:\Users\USERNAME\AppData\Local\Programs\Python\Python310\lib\site-packages\telegram\bot.py", line 295, in _post
    return self.request.post(
  File "C:\Users\USERNAME\AppData\Local\Programs\Python\Python310\lib\site-packages\telegram\utils\request.py", line 356, in post
    result = self._request_wrapper(
  File "C:\Users\USERNAME\AppData\Local\Programs\Python\Python310\lib\site-packages\telegram\utils\request.py", line 283, in _request_wrapper
    raise Conflict(message)
telegram.error.Conflict: Conflict: terminated by other getUpdates request; make sure that only one bot instance is running
2023-06-21 23:36:10,854 - telegram.ext.updater - ERROR - Error while getting Updates: Conflict: terminated by other getUpdates request; make sure that only one bot instance is running
2023-06-21 23:36:10,854 - telegram.ext.dispatcher - ERROR - No error handlers are registered, logging exception.
Traceback (most recent call last):
  File "C:\Users\USERNAME\AppData\Local\Programs\Python\Python310\lib\site-packages\telegram\ext\updater.py", line 646, in _network_loop_retry
    if not action_cb():
  File "C:\Users\USERNAME\AppData\Local\Programs\Python\Python310\lib\site-packages\telegram\ext\updater.py", line 597, in polling_action_cb
    updates = self.bot.get_updates(
  File "C:\Users\USERNAME\AppData\Local\Programs\Python\Python310\lib\site-packages\telegram\ext\extbot.py", line 222, in get_updates
    updates = super().get_updates(
  File "C:\Users\USERNAME\AppData\Local\Programs\Python\Python310\lib\site-packages\telegram\bot.py", line 130, in decorator
    result = func(*args, **kwargs)
  File "C:\Users\USERNAME\AppData\Local\Programs\Python\Python310\lib\site-packages\telegram\bot.py", line 2861, in get_updates
    self._post(
  File "C:\Users\USERNAME\AppData\Local\Programs\Python\Python310\lib\site-packages\telegram\bot.py", line 295, in _post
    return self.request.post(
  File "C:\Users\USERNAME\AppData\Local\Programs\Python\Python310\lib\site-packages\telegram\utils\request.py", line 356, in post
    result = self._request_wrapper(
  File "C:\Users\USERNAME\AppData\Local\Programs\Python\Python310\lib\site-packages\telegram\utils\request.py", line 283, in _request_wrapper
    raise Conflict(message)
telegram.error.Conflict: Conflict: terminated by other getUpdates request; make sure that only one bot instance is running
2023-06-21 23:36:28,046 - telegram.ext.updater - ERROR - Error while getting Updates: Conflict: terminated by other getUpdates request; make sure that only one bot instance is running
2023-06-21 23:36:28,046 - telegram.ext.dispatcher - ERROR - No error handlers are registered, logging exception.
Traceback (most recent call last):
  File "C:\Users\USERNAME\AppData\Local\Programs\Python\Python310\lib\site-packages\telegram\ext\updater.py", line 646, in _network_loop_retry
    if not action_cb():
  File "C:\Users\USERNAME\AppData\Local\Programs\Python\Python310\lib\site-packages\telegram\ext\updater.py", line 597, in polling_action_cb
    updates = self.bot.get_updates(
  File "C:\Users\USERNAME\AppData\Local\Programs\Python\Python310\lib\site-packages\telegram\ext\extbot.py", line 222, in get_updates
    updates = super().get_updates(
  File "C:\Users\USERNAME\AppData\Local\Programs\Python\Python310\lib\site-packages\telegram\bot.py", line 130, in decorator
    result = func(*args, **kwargs)
  File "C:\Users\USERNAME\AppData\Local\Programs\Python\Python310\lib\site-packages\telegram\bot.py", line 2861, in get_updates
    self._post(
  File "C:\Users\USERNAME\AppData\Local\Programs\Python\Python310\lib\site-packages\telegram\bot.py", line 295, in _post
    return self.request.post(
  File "C:\Users\USERNAME\AppData\Local\Programs\Python\Python310\lib\site-packages\telegram\utils\request.py", line 356, in post
    result = self._request_wrapper(
  File "C:\Users\USERNAME\AppData\Local\Programs\Python\Python310\lib\site-packages\telegram\utils\request.py", line 283, in _request_wrapper
    raise Conflict(message)
telegram.error.Conflict: Conflict: terminated by other getUpdates request; make sure that only one bot instance is running
2023-06-21 23:36:32,144 - telegram.ext.updater - ERROR - Error while getting Updates: Conflict: terminated by other getUpdates request; make sure that only one bot instance is running
2023-06-21 23:36:32,145 - telegram.ext.dispatcher - ERROR - No error handlers are registered, logging exception.
Traceback (most recent call last):
  File "C:\Users\USERNAME\AppData\Local\Programs\Python\Python310\lib\site-packages\telegram\ext\updater.py", line 646, in _network_loop_retry
    if not action_cb():
  File "C:\Users\USERNAME\AppData\Local\Programs\Python\Python310\lib\site-packages\telegram\ext\updater.py", line 597, in polling_action_cb
    updates = self.bot.get_updates(
  File "C:\Users\USERNAME\AppData\Local\Programs\Python\Python310\lib\site-packages\telegram\ext\extbot.py", line 222, in get_updates
    updates = super().get_updates(
  File "C:\Users\USERNAME\AppData\Local\Programs\Python\Python310\lib\site-packages\telegram\bot.py", line 130, in decorator
    result = func(*args, **kwargs)
  File "C:\Users\USERNAME\AppData\Local\Programs\Python\Python310\lib\site-packages\telegram\bot.py", line 2861, in get_updates
    self._post(
  File "C:\Users\USERNAME\AppData\Local\Programs\Python\Python310\lib\site-packages\telegram\bot.py", line 295, in _post
    return self.request.post(
  File "C:\Users\USERNAME\AppData\Local\Programs\Python\Python310\lib\site-packages\telegram\utils\request.py", line 356, in post
    result = self._request_wrapper(
  File "C:\Users\USERNAME\AppData\Local\Programs\Python\Python310\lib\site-packages\telegram\utils\request.py", line 283, in _request_wrapper
    raise Conflict(message)
telegram.error.Conflict: Conflict: terminated by other getUpdates request; make sure that only one bot instance is running
2023-06-21 23:36:57,869 - telegram.ext.updater - ERROR - Error while getting Updates: Conflict: terminated by other getUpdates request; make sure that only one bot instance is running
2023-06-21 23:36:57,870 - telegram.ext.dispatcher - ERROR - No error handlers are registered, logging exception.
Traceback (most recent call last):
  File "C:\Users\USERNAME\AppData\Local\Programs\Python\Python310\lib\site-packages\telegram\ext\updater.py", line 646, in _network_loop_retry
    if not action_cb():
  File "C:\Users\USERNAME\AppData\Local\Programs\Python\Python310\lib\site-packages\telegram\ext\updater.py", line 597, in polling_action_cb
    updates = self.bot.get_updates(
  File "C:\Users\USERNAME\AppData\Local\Programs\Python\Python310\lib\site-packages\telegram\ext\extbot.py", line 222, in get_updates
    updates = super().get_updates(
  File "C:\Users\USERNAME\AppData\Local\Programs\Python\Python310\lib\site-packages\telegram\bot.py", line 130, in decorator
    result = func(*args, **kwargs)
  File "C:\Users\USERNAME\AppData\Local\Programs\Python\Python310\lib\site-packages\telegram\bot.py", line 2861, in get_updates
    self._post(
  File "C:\Users\USERNAME\AppData\Local\Programs\Python\Python310\lib\site-packages\telegram\bot.py", line 295, in _post
    return self.request.post(
  File "C:\Users\USERNAME\AppData\Local\Programs\Python\Python310\lib\site-packages\telegram\utils\request.py", line 356, in post
    result = self._request_wrapper(
  File "C:\Users\USERNAME\AppData\Local\Programs\Python\Python310\lib\site-packages\telegram\utils\request.py", line 283, in _request_wrapper
    raise Conflict(message)
telegram.error.Conflict: Conflict: terminated by other getUpdates request; make sure that only one bot instance is running
2023-06-21 23:37:01,986 - telegram.ext.updater - ERROR - Error while getting Updates: Conflict: terminated by other getUpdates request; make sure that only one bot instance is running
2023-06-21 23:37:01,987 - telegram.ext.dispatcher - ERROR - No error handlers are registered, logging exception.
Traceback (most recent call last):
  File "C:\Users\USERNAME\AppData\Local\Programs\Python\Python310\lib\site-packages\telegram\ext\updater.py", line 646, in _network_loop_retry
    if not action_cb():
  File "C:\Users\USERNAME\AppData\Local\Programs\Python\Python310\lib\site-packages\telegram\ext\updater.py", line 597, in polling_action_cb
    updates = self.bot.get_updates(
  File "C:\Users\USERNAME\AppData\Local\Programs\Python\Python310\lib\site-packages\telegram\ext\extbot.py", line 222, in get_updates
    updates = super().get_updates(
  File "C:\Users\USERNAME\AppData\Local\Programs\Python\Python310\lib\site-packages\telegram\bot.py", line 130, in decorator
    result = func(*args, **kwargs)
  File "C:\Users\USERNAME\AppData\Local\Programs\Python\Python310\lib\site-packages\telegram\bot.py", line 2861, in get_updates
    self._post(
  File "C:\Users\USERNAME\AppData\Local\Programs\Python\Python310\lib\site-packages\telegram\bot.py", line 295, in _post
    return self.request.post(
  File "C:\Users\USERNAME\AppData\Local\Programs\Python\Python310\lib\site-packages\telegram\utils\request.py", line 356, in post
    result = self._request_wrapper(
  File "C:\Users\USERNAME\AppData\Local\Programs\Python\Python310\lib\site-packages\telegram\utils\request.py", line 283, in _request_wrapper
    raise Conflict(message)
telegram.error.Conflict: Conflict: terminated by other getUpdates request; make sure that only one bot instance is running
2023-06-21 23:37:40,535 - telegram.ext.updater - ERROR - Error while getting Updates: Conflict: terminated by other getUpdates request; make sure that only one bot instance is running
2023-06-21 23:37:40,536 - telegram.ext.dispatcher - ERROR - No error handlers are registered, logging exception.
Traceback (most recent call last):
  File "C:\Users\USERNAME\AppData\Local\Programs\Python\Python310\lib\site-packages\telegram\ext\updater.py", line 646, in _network_loop_retry
    if not action_cb():
  File "C:\Users\USERNAME\AppData\Local\Programs\Python\Python310\lib\site-packages\telegram\ext\updater.py", line 597, in polling_action_cb
    updates = self.bot.get_updates(
  File "C:\Users\USERNAME\AppData\Local\Programs\Python\Python310\lib\site-packages\telegram\ext\extbot.py", line 222, in get_updates
    updates = super().get_updates(
  File "C:\Users\USERNAME\AppData\Local\Programs\Python\Python310\lib\site-packages\telegram\bot.py", line 130, in decorator
    result = func(*args, **kwargs)
  File "C:\Users\USERNAME\AppData\Local\Programs\Python\Python310\lib\site-packages\telegram\bot.py", line 2861, in get_updates
    self._post(
  File "C:\Users\USERNAME\AppData\Local\Programs\Python\Python310\lib\site-packages\telegram\bot.py", line 295, in _post
    return self.request.post(
  File "C:\Users\USERNAME\AppData\Local\Programs\Python\Python310\lib\site-packages\telegram\utils\request.py", line 356, in post
    result = self._request_wrapper(
  File "C:\Users\USERNAME\AppData\Local\Programs\Python\Python310\lib\site-packages\telegram\utils\request.py", line 283, in _request_wrapper
    raise Conflict(message)
telegram.error.Conflict: Conflict: terminated by other getUpdates request; make sure that only one bot instance is running
2023-06-21 23:37:44,648 - telegram.ext.updater - ERROR - Error while getting Updates: Conflict: terminated by other getUpdates request; make sure that only one bot instance is running
2023-06-21 23:37:44,648 - telegram.ext.dispatcher - ERROR - No error handlers are registered, logging exception.
Traceback (most recent call last):
  File "C:\Users\USERNAME\AppData\Local\Programs\Python\Python310\lib\site-packages\telegram\ext\updater.py", line 646, in _network_loop_retry
    if not action_cb():
  File "C:\Users\USERNAME\AppData\Local\Programs\Python\Python310\lib\site-packages\telegram\ext\updater.py", line 597, in polling_action_cb
    updates = self.bot.get_updates(
  File "C:\Users\USERNAME\AppData\Local\Programs\Python\Python310\lib\site-packages\telegram\ext\extbot.py", line 222, in get_updates
    updates = super().get_updates(
  File "C:\Users\USERNAME\AppData\Local\Programs\Python\Python310\lib\site-packages\telegram\bot.py", line 130, in decorator
    result = func(*args, **kwargs)
  File "C:\Users\USERNAME\AppData\Local\Programs\Python\Python310\lib\site-packages\telegram\bot.py", line 2861, in get_updates
    self._post(
  File "C:\Users\USERNAME\AppData\Local\Programs\Python\Python310\lib\site-packages\telegram\bot.py", line 295, in _post
    return self.request.post(
  File "C:\Users\USERNAME\AppData\Local\Programs\Python\Python310\lib\site-packages\telegram\utils\request.py", line 356, in post
    result = self._request_wrapper(
  File "C:\Users\USERNAME\AppData\Local\Programs\Python\Python310\lib\site-packages\telegram\utils\request.py", line 283, in _request_wrapper
    raise Conflict(message)
telegram.error.Conflict: Conflict: terminated by other getUpdates request; make sure that only one bot instance is running
2023-06-21 23:38:14,745 - telegram.ext.updater - ERROR - Error while getting Updates: Conflict: terminated by other getUpdates request; make sure that only one bot instance is running
2023-06-21 23:38:14,745 - telegram.ext.dispatcher - ERROR - No error handlers are registered, logging exception.
Traceback (most recent call last):
  File "C:\Users\USERNAME\AppData\Local\Programs\Python\Python310\lib\site-packages\telegram\ext\updater.py", line 646, in _network_loop_retry
    if not action_cb():
  File "C:\Users\USERNAME\AppData\Local\Programs\Python\Python310\lib\site-packages\telegram\ext\updater.py", line 597, in polling_action_cb
    updates = self.bot.get_updates(
  File "C:\Users\USERNAME\AppData\Local\Programs\Python\Python310\lib\site-packages\telegram\ext\extbot.py", line 222, in get_updates
    updates = super().get_updates(
  File "C:\Users\USERNAME\AppData\Local\Programs\Python\Python310\lib\site-packages\telegram\bot.py", line 130, in decorator
    result = func(*args, **kwargs)
  File "C:\Users\USERNAME\AppData\Local\Programs\Python\Python310\lib\site-packages\telegram\bot.py", line 2861, in get_updates
    self._post(
  File "C:\Users\USERNAME\AppData\Local\Programs\Python\Python310\lib\site-packages\telegram\bot.py", line 295, in _post
    return self.request.post(
  File "C:\Users\USERNAME\AppData\Local\Programs\Python\Python310\lib\site-packages\telegram\utils\request.py", line 356, in post
    result = self._request_wrapper(
  File "C:\Users\USERNAME\AppData\Local\Programs\Python\Python310\lib\site-packages\telegram\utils\request.py", line 283, in _request_wrapper
    raise Conflict(message)
telegram.error.Conflict: Conflict: terminated by other getUpdates request; make sure that only one bot instance is running
2023-06-21 23:38:18,854 - telegram.ext.updater - ERROR - Error while getting Updates: Conflict: terminated by other getUpdates request; make sure that only one bot instance is running
2023-06-21 23:38:18,855 - telegram.ext.dispatcher - ERROR - No error handlers are registered, logging exception.
Traceback (most recent call last):
  File "C:\Users\USERNAME\AppData\Local\Programs\Python\Python310\lib\site-packages\telegram\ext\updater.py", line 646, in _network_loop_retry
    if not action_cb():
  File "C:\Users\USERNAME\AppData\Local\Programs\Python\Python310\lib\site-packages\telegram\ext\updater.py", line 597, in polling_action_cb
    updates = self.bot.get_updates(
  File "C:\Users\USERNAME\AppData\Local\Programs\Python\Python310\lib\site-packages\telegram\ext\extbot.py", line 222, in get_updates
    updates = super().get_updates(
  File "C:\Users\USERNAME\AppData\Local\Programs\Python\Python310\lib\site-packages\telegram\bot.py", line 130, in decorator
    result = func(*args, **kwargs)
  File "C:\Users\USERNAME\AppData\Local\Programs\Python\Python310\lib\site-packages\telegram\bot.py", line 2861, in get_updates
    self._post(
  File "C:\Users\USERNAME\AppData\Local\Programs\Python\Python310\lib\site-packages\telegram\bot.py", line 295, in _post
    return self.request.post(
  File "C:\Users\USERNAME\AppData\Local\Programs\Python\Python310\lib\site-packages\telegram\utils\request.py", line 356, in post
    result = self._request_wrapper(
  File "C:\Users\USERNAME\AppData\Local\Programs\Python\Python310\lib\site-packages\telegram\utils\request.py", line 283, in _request_wrapper
    raise Conflict(message)
telegram.error.Conflict: Conflict: terminated by other getUpdates request; make sure that only one bot instance is running
2023-06-21 23:38:48,957 - telegram.ext.updater - ERROR - Error while getting Updates: Conflict: terminated by other getUpdates request; make sure that only one bot instance is running
2023-06-21 23:38:48,958 - telegram.ext.dispatcher - ERROR - No error handlers are registered, logging exception.
Traceback (most recent call last):
  File "C:\Users\USERNAME\AppData\Local\Programs\Python\Python310\lib\site-packages\telegram\ext\updater.py", line 646, in _network_loop_retry
    if not action_cb():
  File "C:\Users\USERNAME\AppData\Local\Programs\Python\Python310\lib\site-packages\telegram\ext\updater.py", line 597, in polling_action_cb
    updates = self.bot.get_updates(
  File "C:\Users\USERNAME\AppData\Local\Programs\Python\Python310\lib\site-packages\telegram\ext\extbot.py", line 222, in get_updates
    updates = super().get_updates(
  File "C:\Users\USERNAME\AppData\Local\Programs\Python\Python310\lib\site-packages\telegram\bot.py", line 130, in decorator
    result = func(*args, **kwargs)
  File "C:\Users\USERNAME\AppData\Local\Programs\Python\Python310\lib\site-packages\telegram\bot.py", line 2861, in get_updates
    self._post(
  File "C:\Users\USERNAME\AppData\Local\Programs\Python\Python310\lib\site-packages\telegram\bot.py", line 295, in _post
    return self.request.post(
  File "C:\Users\USERNAME\AppData\Local\Programs\Python\Python310\lib\site-packages\telegram\utils\request.py", line 356, in post
    result = self._request_wrapper(
  File "C:\Users\USERNAME\AppData\Local\Programs\Python\Python310\lib\site-packages\telegram\utils\request.py", line 283, in _request_wrapper
    raise Conflict(message)
telegram.error.Conflict: Conflict: terminated by other getUpdates request; make sure that only one bot instance is running
2023-06-21 23:38:53,053 - telegram.ext.updater - ERROR - Error while getting Updates: Conflict: terminated by other getUpdates request; make sure that only one bot instance is running
2023-06-21 23:38:53,053 - telegram.ext.dispatcher - ERROR - No error handlers are registered, logging exception.
Traceback (most recent call last):
  File "C:\Users\USERNAME\AppData\Local\Programs\Python\Python310\lib\site-packages\telegram\ext\updater.py", line 646, in _network_loop_retry
    if not action_cb():
  File "C:\Users\USERNAME\AppData\Local\Programs\Python\Python310\lib\site-packages\telegram\ext\updater.py", line 597, in polling_action_cb
    updates = self.bot.get_updates(
  File "C:\Users\USERNAME\AppData\Local\Programs\Python\Python310\lib\site-packages\telegram\ext\extbot.py", line 222, in get_updates
    updates = super().get_updates(
  File "C:\Users\USERNAME\AppData\Local\Programs\Python\Python310\lib\site-packages\telegram\bot.py", line 130, in decorator
    result = func(*args, **kwargs)
  File "C:\Users\USERNAME\AppData\Local\Programs\Python\Python310\lib\site-packages\telegram\bot.py", line 2861, in get_updates
    self._post(
  File "C:\Users\USERNAME\AppData\Local\Programs\Python\Python310\lib\site-packages\telegram\bot.py", line 295, in _post
    return self.request.post(
  File "C:\Users\USERNAME\AppData\Local\Programs\Python\Python310\lib\site-packages\telegram\utils\request.py", line 356, in post
    result = self._request_wrapper(
  File "C:\Users\USERNAME\AppData\Local\Programs\Python\Python310\lib\site-packages\telegram\utils\request.py", line 283, in _request_wrapper
    raise Conflict(message)
telegram.error.Conflict: Conflict: terminated by other getUpdates request; make sure that only one bot instance is running
2023-06-21 23:39:23,161 - telegram.ext.updater - ERROR - Error while getting Updates: Conflict: terminated by other getUpdates request; make sure that only one bot instance is running
2023-06-21 23:39:23,162 - telegram.ext.dispatcher - ERROR - No error handlers are registered, logging exception.
Traceback (most recent call last):
  File "C:\Users\USERNAME\AppData\Local\Programs\Python\Python310\lib\site-packages\telegram\ext\updater.py", line 646, in _network_loop_retry
    if not action_cb():
  File "C:\Users\USERNAME\AppData\Local\Programs\Python\Python310\lib\site-packages\telegram\ext\updater.py", line 597, in polling_action_cb
    updates = self.bot.get_updates(
  File "C:\Users\USERNAME\AppData\Local\Programs\Python\Python310\lib\site-packages\telegram\ext\extbot.py", line 222, in get_updates
    updates = super().get_updates(
  File "C:\Users\USERNAME\AppData\Local\Programs\Python\Python310\lib\site-packages\telegram\bot.py", line 130, in decorator
    result = func(*args, **kwargs)
  File "C:\Users\USERNAME\AppData\Local\Programs\Python\Python310\lib\site-packages\telegram\bot.py", line 2861, in get_updates
    self._post(
  File "C:\Users\USERNAME\AppData\Local\Programs\Python\Python310\lib\site-packages\telegram\bot.py", line 295, in _post
    return self.request.post(
  File "C:\Users\USERNAME\AppData\Local\Programs\Python\Python310\lib\site-packages\telegram\utils\request.py", line 356, in post
    result = self._request_wrapper(
  File "C:\Users\USERNAME\AppData\Local\Programs\Python\Python310\lib\site-packages\telegram\utils\request.py", line 283, in _request_wrapper
    raise Conflict(message)
telegram.error.Conflict: Conflict: terminated by other getUpdates request; make sure that only one bot instance is running
2023-06-21 23:39:27,267 - telegram.ext.updater - ERROR - Error while getting Updates: Conflict: terminated by other getUpdates request; make sure that only one bot instance is running
2023-06-21 23:39:27,269 - telegram.ext.dispatcher - ERROR - No error handlers are registered, logging exception.
Traceback (most recent call last):
  File "C:\Users\USERNAME\AppData\Local\Programs\Python\Python310\lib\site-packages\telegram\ext\updater.py", line 646, in _network_loop_retry
    if not action_cb():
  File "C:\Users\USERNAME\AppData\Local\Programs\Python\Python310\lib\site-packages\telegram\ext\updater.py", line 597, in polling_action_cb
    updates = self.bot.get_updates(
  File "C:\Users\USERNAME\AppData\Local\Programs\Python\Python310\lib\site-packages\telegram\ext\extbot.py", line 222, in get_updates
    updates = super().get_updates(
  File "C:\Users\USERNAME\AppData\Local\Programs\Python\Python310\lib\site-packages\telegram\bot.py", line 130, in decorator
    result = func(*args, **kwargs)
  File "C:\Users\USERNAME\AppData\Local\Programs\Python\Python310\lib\site-packages\telegram\bot.py", line 2861, in get_updates
    self._post(
  File "C:\Users\USERNAME\AppData\Local\Programs\Python\Python310\lib\site-packages\telegram\bot.py", line 295, in _post
    return self.request.post(
  File "C:\Users\USERNAME\AppData\Local\Programs\Python\Python310\lib\site-packages\telegram\utils\request.py", line 356, in post
    result = self._request_wrapper(
  File "C:\Users\USERNAME\AppData\Local\Programs\Python\Python310\lib\site-packages\telegram\utils\request.py", line 283, in _request_wrapper
    raise Conflict(message)
telegram.error.Conflict: Conflict: terminated by other getUpdates request; make sure that only one bot instance is running
